2024-03-06 17:27:41,453 INFO    MainThread:67432 [internal.py:wandb_internal():90] W&B internal server running at pid: 67432, started at: 2024-03-06 17:27:41.452295
2024-03-06 17:27:41,454 INFO    WriterThread:67432 [datastore.py:open_for_write():75] open: .\wandb\run-20240306_172740-sugepeky\run-sugepeky.wandb
2024-03-06 17:27:41,457 DEBUG   SenderThread:67432 [sender.py:send():235] send: header
2024-03-06 17:27:41,458 DEBUG   SenderThread:67432 [sender.py:send():235] send: run
2024-03-06 17:27:41,459 INFO    SenderThread:67432 [sender.py:_maybe_setup_resume():492] checking resume status for None/UNet-DAS/sugepeky
2024-03-06 17:27:44,180 DEBUG   HandlerThread:67432 [handler.py:handle_request():141] handle_request: check_version
2024-03-06 17:27:44,189 INFO    SenderThread:67432 [dir_watcher.py:__init__():205] watching files in: .\wandb\run-20240306_172740-sugepeky\files
2024-03-06 17:27:44,189 INFO    SenderThread:67432 [sender.py:_start_run_threads():812] run started: sugepeky with start time 1709717260
2024-03-06 17:27:44,189 DEBUG   SenderThread:67432 [sender.py:send():235] send: summary
2024-03-06 17:27:44,190 INFO    SenderThread:67432 [sender.py:_save_file():949] saving file wandb-summary.json with policy end
2024-03-06 17:27:44,191 DEBUG   SenderThread:67432 [sender.py:send_request():249] send_request: check_version
2024-03-06 17:27:44,982 DEBUG   HandlerThread:67432 [handler.py:handle_request():141] handle_request: run_start
2024-03-06 17:27:45,018 DEBUG   HandlerThread:67432 [meta.py:__init__():35] meta init
2024-03-06 17:27:45,018 DEBUG   HandlerThread:67432 [meta.py:__init__():49] meta init done
2024-03-06 17:27:45,018 DEBUG   HandlerThread:67432 [meta.py:probe():209] probe
2024-03-06 17:27:45,040 DEBUG   HandlerThread:67432 [meta.py:_setup_git():199] setup git
2024-03-06 17:27:45,190 INFO    Thread-11 :67432 [dir_watcher.py:_on_file_created():256] file/dir created: .\wandb\run-20240306_172740-sugepeky\files\wandb-summary.json
2024-03-06 17:27:45,195 DEBUG   HandlerThread:67432 [meta.py:_setup_git():206] setup git done
2024-03-06 17:27:45,195 DEBUG   HandlerThread:67432 [meta.py:_save_pip():53] save pip
2024-03-06 17:27:45,196 DEBUG   HandlerThread:67432 [meta.py:_save_pip():67] save pip done
2024-03-06 17:27:45,196 DEBUG   HandlerThread:67432 [meta.py:_save_conda():74] save conda
2024-03-06 17:27:46,198 INFO    Thread-11 :67432 [dir_watcher.py:_on_file_created():256] file/dir created: .\wandb\run-20240306_172740-sugepeky\files\conda-environment.yaml
2024-03-06 17:27:46,198 INFO    Thread-11 :67432 [dir_watcher.py:_on_file_created():256] file/dir created: .\wandb\run-20240306_172740-sugepeky\files\requirements.txt
2024-03-06 17:27:48,524 DEBUG   HandlerThread:67432 [meta.py:_save_conda():84] save conda done
2024-03-06 17:27:48,525 DEBUG   HandlerThread:67432 [meta.py:probe():247] probe done
2024-03-06 17:27:48,605 DEBUG   HandlerThread:67432 [handler.py:handle_request():141] handle_request: stop_status
2024-03-06 17:27:48,605 DEBUG   SenderThread:67432 [sender.py:send():235] send: files
2024-03-06 17:27:48,605 INFO    SenderThread:67432 [sender.py:_save_file():949] saving file wandb-metadata.json with policy now
2024-03-06 17:27:48,607 DEBUG   SenderThread:67432 [sender.py:send_request():249] send_request: stop_status
2024-03-06 17:27:49,223 INFO    Thread-11 :67432 [dir_watcher.py:_on_file_modified():269] file/dir modified: .\wandb\run-20240306_172740-sugepeky\files\conda-environment.yaml
2024-03-06 17:27:49,223 INFO    Thread-11 :67432 [dir_watcher.py:_on_file_created():256] file/dir created: .\wandb\run-20240306_172740-sugepeky\files\wandb-metadata.json
2024-03-06 17:27:49,224 INFO    Thread-11 :67432 [dir_watcher.py:_on_file_created():256] file/dir created: .\wandb\run-20240306_172740-sugepeky\files\output.log
2024-03-06 17:27:50,037 DEBUG   SenderThread:67432 [sender.py:send():235] send: telemetry
2024-03-06 17:27:50,037 DEBUG   SenderThread:67432 [sender.py:send():235] send: metric
2024-03-06 17:27:50,037 DEBUG   SenderThread:67432 [sender.py:send():235] send: telemetry
2024-03-06 17:27:50,037 DEBUG   SenderThread:67432 [sender.py:send():235] send: metric
2024-03-06 17:27:50,037 WARNING SenderThread:67432 [sender.py:send_metric():905] Seen metric with glob (shouldn't happen)
2024-03-06 17:27:50,038 DEBUG   SenderThread:67432 [sender.py:send():235] send: config
2024-03-06 17:27:50,468 ERROR   Thread-17 :67432 [internal_api.py:upload_file():1640] upload_file exception https://storage.googleapis.com/wandb-production.appspot.com/shahwaiz/UNet-DAS/sugepeky/wandb-metadata.json?Expires=1709803670&GoogleAccessId=gorilla-files-url-signer-man%40wandb-production.iam.gserviceaccount.com&Signature=Wo1jcnokk6nK0GU9yVQMT5zw%2Fqmx4MUAuOGoFnob3P708ZcMhJt6wFhruWOoQJ49WoYIkjpYyjwUC4ccX8rTXYXyjDkUZMhHvyDgsomctoRd7vgfJJDFnq7pEUKwbW8zAA8XG7yLDJR7sp4kj5UfbFo%2BQ5coJIp6lLPtjR4J8CbWvBF0e3DMuK15jJonEQPwMqUnDs2er6o8snMi3oBaXy54F9i6jKZgI5kAnfZSZaIOlybJqre15hSYqx%2BMePV6XdTqKD5PAWo0ib99gX60ForkJXpvx%2FwWytOCq3sASFLRGqkG%2F1WVRWEOjkUzzz0V5%2BBw1hpJEBC5whLpbrCzxg%3D%3D: ('Connection aborted.', ConnectionResetError(10054, '远程主机强迫关闭了一个现有的连接。', None, 10054, None))
2024-03-06 17:27:50,468 ERROR   Thread-17 :67432 [internal_api.py:upload_file():1642] upload_file request headers: {'User-Agent': 'python-requests/2.31.0', 'Accept-Encoding': 'gzip, deflate', 'Accept': '*/*', 'Connection': 'keep-alive', 'Content-Length': '967'}
2024-03-06 17:27:50,468 ERROR   Thread-17 :67432 [internal_api.py:upload_file():1644] upload_file response body: 
2024-03-06 17:27:51,232 INFO    Thread-11 :67432 [dir_watcher.py:_on_file_modified():269] file/dir modified: .\wandb\run-20240306_172740-sugepeky\files\output.log
2024-03-06 17:27:52,232 ERROR   Thread-17 :67432 [internal_api.py:upload_file():1640] upload_file exception https://storage.googleapis.com/wandb-production.appspot.com/shahwaiz/UNet-DAS/sugepeky/wandb-metadata.json?Expires=1709803670&GoogleAccessId=gorilla-files-url-signer-man%40wandb-production.iam.gserviceaccount.com&Signature=Wo1jcnokk6nK0GU9yVQMT5zw%2Fqmx4MUAuOGoFnob3P708ZcMhJt6wFhruWOoQJ49WoYIkjpYyjwUC4ccX8rTXYXyjDkUZMhHvyDgsomctoRd7vgfJJDFnq7pEUKwbW8zAA8XG7yLDJR7sp4kj5UfbFo%2BQ5coJIp6lLPtjR4J8CbWvBF0e3DMuK15jJonEQPwMqUnDs2er6o8snMi3oBaXy54F9i6jKZgI5kAnfZSZaIOlybJqre15hSYqx%2BMePV6XdTqKD5PAWo0ib99gX60ForkJXpvx%2FwWytOCq3sASFLRGqkG%2F1WVRWEOjkUzzz0V5%2BBw1hpJEBC5whLpbrCzxg%3D%3D: ('Connection aborted.', ConnectionResetError(10054, '远程主机强迫关闭了一个现有的连接。', None, 10054, None))
2024-03-06 17:27:52,232 ERROR   Thread-17 :67432 [internal_api.py:upload_file():1642] upload_file request headers: {'User-Agent': 'python-requests/2.31.0', 'Accept-Encoding': 'gzip, deflate', 'Accept': '*/*', 'Connection': 'keep-alive', 'Content-Length': '967'}
2024-03-06 17:27:52,232 ERROR   Thread-17 :67432 [internal_api.py:upload_file():1644] upload_file response body: 
2024-03-06 17:27:54,897 ERROR   Thread-17 :67432 [internal_api.py:upload_file():1640] upload_file exception https://storage.googleapis.com/wandb-production.appspot.com/shahwaiz/UNet-DAS/sugepeky/wandb-metadata.json?Expires=1709803670&GoogleAccessId=gorilla-files-url-signer-man%40wandb-production.iam.gserviceaccount.com&Signature=Wo1jcnokk6nK0GU9yVQMT5zw%2Fqmx4MUAuOGoFnob3P708ZcMhJt6wFhruWOoQJ49WoYIkjpYyjwUC4ccX8rTXYXyjDkUZMhHvyDgsomctoRd7vgfJJDFnq7pEUKwbW8zAA8XG7yLDJR7sp4kj5UfbFo%2BQ5coJIp6lLPtjR4J8CbWvBF0e3DMuK15jJonEQPwMqUnDs2er6o8snMi3oBaXy54F9i6jKZgI5kAnfZSZaIOlybJqre15hSYqx%2BMePV6XdTqKD5PAWo0ib99gX60ForkJXpvx%2FwWytOCq3sASFLRGqkG%2F1WVRWEOjkUzzz0V5%2BBw1hpJEBC5whLpbrCzxg%3D%3D: ('Connection aborted.', ConnectionResetError(10054, '远程主机强迫关闭了一个现有的连接。', None, 10054, None))
2024-03-06 17:27:54,897 ERROR   Thread-17 :67432 [internal_api.py:upload_file():1642] upload_file request headers: {'User-Agent': 'python-requests/2.31.0', 'Accept-Encoding': 'gzip, deflate', 'Accept': '*/*', 'Connection': 'keep-alive', 'Content-Length': '967'}
2024-03-06 17:27:54,897 ERROR   Thread-17 :67432 [internal_api.py:upload_file():1644] upload_file response body: 
2024-03-06 17:27:54,897 ERROR   Thread-17 :67432 [retry.py:__call__():126] Retry attempt failed:
Traceback (most recent call last):
  File "E:\Anaconda\envs\unet\lib\site-packages\urllib3\connectionpool.py", line 793, in urlopen
    response = self._make_request(
  File "E:\Anaconda\envs\unet\lib\site-packages\urllib3\connectionpool.py", line 491, in _make_request
    raise new_e
  File "E:\Anaconda\envs\unet\lib\site-packages\urllib3\connectionpool.py", line 467, in _make_request
    self._validate_conn(conn)
  File "E:\Anaconda\envs\unet\lib\site-packages\urllib3\connectionpool.py", line 1099, in _validate_conn
    conn.connect()
  File "E:\Anaconda\envs\unet\lib\site-packages\urllib3\connection.py", line 653, in connect
    sock_and_verified = _ssl_wrap_socket_and_match_hostname(
  File "E:\Anaconda\envs\unet\lib\site-packages\urllib3\connection.py", line 806, in _ssl_wrap_socket_and_match_hostname
    ssl_sock = ssl_wrap_socket(
  File "E:\Anaconda\envs\unet\lib\site-packages\urllib3\util\ssl_.py", line 465, in ssl_wrap_socket
    ssl_sock = _ssl_wrap_socket_impl(sock, context, tls_in_tls, server_hostname)
  File "E:\Anaconda\envs\unet\lib\site-packages\urllib3\util\ssl_.py", line 509, in _ssl_wrap_socket_impl
    return ssl_context.wrap_socket(sock, server_hostname=server_hostname)
  File "E:\Anaconda\envs\unet\lib\ssl.py", line 500, in wrap_socket
    return self.sslsocket_class._create(
  File "E:\Anaconda\envs\unet\lib\ssl.py", line 1073, in _create
    self.do_handshake()
  File "E:\Anaconda\envs\unet\lib\ssl.py", line 1342, in do_handshake
    self._sslobj.do_handshake()
ConnectionResetError: [WinError 10054] 远程主机强迫关闭了一个现有的连接。

During handling of the above exception, another exception occurred:

Traceback (most recent call last):
  File "E:\Anaconda\envs\unet\lib\site-packages\requests\adapters.py", line 486, in send
    resp = conn.urlopen(
  File "E:\Anaconda\envs\unet\lib\site-packages\urllib3\connectionpool.py", line 847, in urlopen
    retries = retries.increment(
  File "E:\Anaconda\envs\unet\lib\site-packages\urllib3\util\retry.py", line 470, in increment
    raise reraise(type(error), error, _stacktrace)
  File "E:\Anaconda\envs\unet\lib\site-packages\urllib3\util\util.py", line 38, in reraise
    raise value.with_traceback(tb)
  File "E:\Anaconda\envs\unet\lib\site-packages\urllib3\connectionpool.py", line 793, in urlopen
    response = self._make_request(
  File "E:\Anaconda\envs\unet\lib\site-packages\urllib3\connectionpool.py", line 491, in _make_request
    raise new_e
  File "E:\Anaconda\envs\unet\lib\site-packages\urllib3\connectionpool.py", line 467, in _make_request
    self._validate_conn(conn)
  File "E:\Anaconda\envs\unet\lib\site-packages\urllib3\connectionpool.py", line 1099, in _validate_conn
    conn.connect()
  File "E:\Anaconda\envs\unet\lib\site-packages\urllib3\connection.py", line 653, in connect
    sock_and_verified = _ssl_wrap_socket_and_match_hostname(
  File "E:\Anaconda\envs\unet\lib\site-packages\urllib3\connection.py", line 806, in _ssl_wrap_socket_and_match_hostname
    ssl_sock = ssl_wrap_socket(
  File "E:\Anaconda\envs\unet\lib\site-packages\urllib3\util\ssl_.py", line 465, in ssl_wrap_socket
    ssl_sock = _ssl_wrap_socket_impl(sock, context, tls_in_tls, server_hostname)
  File "E:\Anaconda\envs\unet\lib\site-packages\urllib3\util\ssl_.py", line 509, in _ssl_wrap_socket_impl
    return ssl_context.wrap_socket(sock, server_hostname=server_hostname)
  File "E:\Anaconda\envs\unet\lib\ssl.py", line 500, in wrap_socket
    return self.sslsocket_class._create(
  File "E:\Anaconda\envs\unet\lib\ssl.py", line 1073, in _create
    self.do_handshake()
  File "E:\Anaconda\envs\unet\lib\ssl.py", line 1342, in do_handshake
    self._sslobj.do_handshake()
urllib3.exceptions.ProtocolError: ('Connection aborted.', ConnectionResetError(10054, '远程主机强迫关闭了一个现有的连接。', None, 10054, None))

During handling of the above exception, another exception occurred:

Traceback (most recent call last):
  File "C:\Users\19086\AppData\Roaming\Python\Python38\site-packages\wandb\sdk\internal\internal_api.py", line 1637, in upload_file
    response = requests.put(url, data=progress, headers=extra_headers)
  File "E:\Anaconda\envs\unet\lib\site-packages\requests\api.py", line 130, in put
    return request("put", url, data=data, **kwargs)
  File "E:\Anaconda\envs\unet\lib\site-packages\requests\api.py", line 59, in request
    return session.request(method=method, url=url, **kwargs)
  File "E:\Anaconda\envs\unet\lib\site-packages\requests\sessions.py", line 589, in request
    resp = self.send(prep, **send_kwargs)
  File "E:\Anaconda\envs\unet\lib\site-packages\requests\sessions.py", line 703, in send
    r = adapter.send(request, **kwargs)
  File "E:\Anaconda\envs\unet\lib\site-packages\requests\adapters.py", line 501, in send
    raise ConnectionError(err, request=request)
requests.exceptions.ConnectionError: ('Connection aborted.', ConnectionResetError(10054, '远程主机强迫关闭了一个现有的连接。', None, 10054, None))

During handling of the above exception, another exception occurred:

Traceback (most recent call last):
  File "C:\Users\19086\AppData\Roaming\Python\Python38\site-packages\wandb\sdk\lib\retry.py", line 102, in __call__
    result = self._call_fn(*args, **kwargs)
  File "C:\Users\19086\AppData\Roaming\Python\Python38\site-packages\wandb\sdk\internal\internal_api.py", line 1653, in upload_file
    raise e.with_traceback(sys.exc_info()[2])
  File "C:\Users\19086\AppData\Roaming\Python\Python38\site-packages\wandb\sdk\internal\internal_api.py", line 1637, in upload_file
    response = requests.put(url, data=progress, headers=extra_headers)
  File "E:\Anaconda\envs\unet\lib\site-packages\requests\api.py", line 130, in put
    return request("put", url, data=data, **kwargs)
  File "E:\Anaconda\envs\unet\lib\site-packages\requests\api.py", line 59, in request
    return session.request(method=method, url=url, **kwargs)
  File "E:\Anaconda\envs\unet\lib\site-packages\requests\sessions.py", line 589, in request
    resp = self.send(prep, **send_kwargs)
  File "E:\Anaconda\envs\unet\lib\site-packages\requests\sessions.py", line 703, in send
    r = adapter.send(request, **kwargs)
  File "E:\Anaconda\envs\unet\lib\site-packages\requests\adapters.py", line 501, in send
    raise ConnectionError(err, request=request)
wandb.sdk.lib.retry.TransientError: None
2024-03-06 17:27:59,836 ERROR   Thread-17 :67432 [internal_api.py:upload_file():1640] upload_file exception https://storage.googleapis.com/wandb-production.appspot.com/shahwaiz/UNet-DAS/sugepeky/wandb-metadata.json?Expires=1709803670&GoogleAccessId=gorilla-files-url-signer-man%40wandb-production.iam.gserviceaccount.com&Signature=Wo1jcnokk6nK0GU9yVQMT5zw%2Fqmx4MUAuOGoFnob3P708ZcMhJt6wFhruWOoQJ49WoYIkjpYyjwUC4ccX8rTXYXyjDkUZMhHvyDgsomctoRd7vgfJJDFnq7pEUKwbW8zAA8XG7yLDJR7sp4kj5UfbFo%2BQ5coJIp6lLPtjR4J8CbWvBF0e3DMuK15jJonEQPwMqUnDs2er6o8snMi3oBaXy54F9i6jKZgI5kAnfZSZaIOlybJqre15hSYqx%2BMePV6XdTqKD5PAWo0ib99gX60ForkJXpvx%2FwWytOCq3sASFLRGqkG%2F1WVRWEOjkUzzz0V5%2BBw1hpJEBC5whLpbrCzxg%3D%3D: ('Connection aborted.', ConnectionResetError(10054, '远程主机强迫关闭了一个现有的连接。', None, 10054, None))
2024-03-06 17:27:59,836 ERROR   Thread-17 :67432 [internal_api.py:upload_file():1642] upload_file request headers: {'User-Agent': 'python-requests/2.31.0', 'Accept-Encoding': 'gzip, deflate', 'Accept': '*/*', 'Connection': 'keep-alive', 'Content-Length': '967'}
2024-03-06 17:27:59,836 ERROR   Thread-17 :67432 [internal_api.py:upload_file():1644] upload_file response body: 
2024-03-06 17:28:05,051 DEBUG   HandlerThread:67432 [handler.py:handle_request():141] handle_request: stop_status
2024-03-06 17:28:05,051 DEBUG   SenderThread:67432 [sender.py:send_request():249] send_request: stop_status
2024-03-06 17:28:08,464 ERROR   Thread-17 :67432 [internal_api.py:upload_file():1640] upload_file exception https://storage.googleapis.com/wandb-production.appspot.com/shahwaiz/UNet-DAS/sugepeky/wandb-metadata.json?Expires=1709803670&GoogleAccessId=gorilla-files-url-signer-man%40wandb-production.iam.gserviceaccount.com&Signature=Wo1jcnokk6nK0GU9yVQMT5zw%2Fqmx4MUAuOGoFnob3P708ZcMhJt6wFhruWOoQJ49WoYIkjpYyjwUC4ccX8rTXYXyjDkUZMhHvyDgsomctoRd7vgfJJDFnq7pEUKwbW8zAA8XG7yLDJR7sp4kj5UfbFo%2BQ5coJIp6lLPtjR4J8CbWvBF0e3DMuK15jJonEQPwMqUnDs2er6o8snMi3oBaXy54F9i6jKZgI5kAnfZSZaIOlybJqre15hSYqx%2BMePV6XdTqKD5PAWo0ib99gX60ForkJXpvx%2FwWytOCq3sASFLRGqkG%2F1WVRWEOjkUzzz0V5%2BBw1hpJEBC5whLpbrCzxg%3D%3D: ('Connection aborted.', ConnectionResetError(10054, '远程主机强迫关闭了一个现有的连接。', None, 10054, None))
2024-03-06 17:28:08,465 ERROR   Thread-17 :67432 [internal_api.py:upload_file():1642] upload_file request headers: {'User-Agent': 'python-requests/2.31.0', 'Accept-Encoding': 'gzip, deflate', 'Accept': '*/*', 'Connection': 'keep-alive', 'Content-Length': '967'}
2024-03-06 17:28:08,465 ERROR   Thread-17 :67432 [internal_api.py:upload_file():1644] upload_file response body: 
2024-03-06 17:28:11,382 INFO    Thread-11 :67432 [dir_watcher.py:_on_file_modified():269] file/dir modified: .\wandb\run-20240306_172740-sugepeky\files\output.log
2024-03-06 17:28:13,389 INFO    Thread-11 :67432 [dir_watcher.py:_on_file_modified():269] file/dir modified: .\wandb\run-20240306_172740-sugepeky\files\output.log
2024-03-06 17:28:15,422 ERROR   SenderThread:67432 [internal_api.py:execute():143] 409 response executing GraphQL.
2024-03-06 17:28:15,423 ERROR   SenderThread:67432 [internal_api.py:execute():144] {"errors":[{"message":"run shahwaiz/UNet-DAS/sugepeky was previously created and deleted; try a new run name","path":["upsertBucket"]}],"data":{"upsertBucket":null}}
2024-03-06 17:28:15,668 INFO    WriterThread:67432 [datastore.py:close():279] close: .\wandb\run-20240306_172740-sugepeky\run-sugepeky.wandb
2024-03-06 17:28:15,668 INFO    HandlerThread:67432 [handler.py:finish():806] shutting down handler
2024-03-06 17:28:15,683 ERROR   MainThread:67432 [internal.py:wandb_internal():165] Thread SenderThread:
Traceback (most recent call last):
  File "C:\Users\19086\AppData\Roaming\Python\Python38\site-packages\wandb\apis\normalize.py", line 22, in wrapper
    return func(*args, **kwargs)
  File "C:\Users\19086\AppData\Roaming\Python\Python38\site-packages\wandb\sdk\internal\internal_api.py", line 1319, in upsert_run
    response = self.gql(mutation, variable_values=variable_values, **kwargs)
  File "C:\Users\19086\AppData\Roaming\Python\Python38\site-packages\wandb\sdk\lib\retry.py", line 102, in __call__
    result = self._call_fn(*args, **kwargs)
  File "C:\Users\19086\AppData\Roaming\Python\Python38\site-packages\wandb\sdk\internal\internal_api.py", line 140, in execute
    return self.client.execute(*args, **kwargs)
  File "C:\Users\19086\AppData\Roaming\Python\Python38\site-packages\wandb\vendor\gql-0.2.0\wandb_gql\client.py", line 52, in execute
    result = self._get_result(document, *args, **kwargs)
  File "C:\Users\19086\AppData\Roaming\Python\Python38\site-packages\wandb\vendor\gql-0.2.0\wandb_gql\client.py", line 60, in _get_result
    return self.transport.execute(document, *args, **kwargs)
  File "C:\Users\19086\AppData\Roaming\Python\Python38\site-packages\wandb\vendor\gql-0.2.0\wandb_gql\transport\requests.py", line 39, in execute
    request.raise_for_status()
  File "E:\Anaconda\envs\unet\lib\site-packages\requests\models.py", line 1021, in raise_for_status
    raise HTTPError(http_error_msg, response=self)
requests.exceptions.HTTPError: 409 Client Error: Conflict for url: https://api.wandb.ai/graphql

During handling of the above exception, another exception occurred:

Traceback (most recent call last):
  File "C:\Users\19086\AppData\Roaming\Python\Python38\site-packages\wandb\sdk\internal\internal_util.py", line 51, in run
    self._run()
  File "C:\Users\19086\AppData\Roaming\Python\Python38\site-packages\wandb\sdk\internal\internal_util.py", line 95, in _run
    self._debounce()
  File "C:\Users\19086\AppData\Roaming\Python\Python38\site-packages\wandb\sdk\internal\internal.py", line 316, in _debounce
    self._sm.debounce()
  File "C:\Users\19086\AppData\Roaming\Python\Python38\site-packages\wandb\sdk\internal\sender.py", line 320, in debounce
    self._debounce_config()
  File "C:\Users\19086\AppData\Roaming\Python\Python38\site-packages\wandb\sdk\internal\sender.py", line 326, in _debounce_config
    self._api.upsert_run(
  File "C:\Users\19086\AppData\Roaming\Python\Python38\site-packages\wandb\apis\normalize.py", line 24, in wrapper
    raise CommError(err.response, err)
wandb.errors.CommError: <Response [409]>
2024-03-06 17:28:16,749 INFO    MainThread:67432 [internal.py:handle_exit():80] Internal process exited
