2024-03-06 15:29:19,478 INFO    MainThread:57348 [internal.py:wandb_internal():90] W&B internal server running at pid: 57348, started at: 2024-03-06 15:29:19.478588
2024-03-06 15:29:19,481 INFO    WriterThread:57348 [datastore.py:open_for_write():75] open: .\wandb\run-20240306_152917-1hl4cn36\run-1hl4cn36.wandb
2024-03-06 15:29:19,488 DEBUG   SenderThread:57348 [sender.py:send():235] send: header
2024-03-06 15:29:19,488 DEBUG   SenderThread:57348 [sender.py:send():235] send: run
2024-03-06 15:29:19,492 INFO    SenderThread:57348 [sender.py:_maybe_setup_resume():492] checking resume status for None/UNet-DAS/1hl4cn36
2024-03-06 15:29:22,592 DEBUG   HandlerThread:57348 [handler.py:handle_request():141] handle_request: check_version
2024-03-06 15:29:22,604 INFO    SenderThread:57348 [dir_watcher.py:__init__():205] watching files in: .\wandb\run-20240306_152917-1hl4cn36\files
2024-03-06 15:29:22,604 INFO    SenderThread:57348 [sender.py:_start_run_threads():812] run started: 1hl4cn36 with start time 1709710158
2024-03-06 15:29:22,604 DEBUG   SenderThread:57348 [sender.py:send():235] send: summary
2024-03-06 15:29:22,605 INFO    SenderThread:57348 [sender.py:_save_file():949] saving file wandb-summary.json with policy end
2024-03-06 15:29:22,606 DEBUG   SenderThread:57348 [sender.py:send_request():249] send_request: check_version
2024-03-06 15:29:23,498 DEBUG   HandlerThread:57348 [handler.py:handle_request():141] handle_request: run_start
2024-03-06 15:29:23,524 DEBUG   HandlerThread:57348 [meta.py:__init__():35] meta init
2024-03-06 15:29:23,524 DEBUG   HandlerThread:57348 [meta.py:__init__():49] meta init done
2024-03-06 15:29:23,524 DEBUG   HandlerThread:57348 [meta.py:probe():209] probe
2024-03-06 15:29:23,563 DEBUG   HandlerThread:57348 [meta.py:_setup_git():199] setup git
2024-03-06 15:29:23,623 INFO    Thread-16 :57348 [dir_watcher.py:_on_file_created():256] file/dir created: .\wandb\run-20240306_152917-1hl4cn36\files\wandb-summary.json
2024-03-06 15:29:23,685 DEBUG   HandlerThread:57348 [meta.py:_setup_git():206] setup git done
2024-03-06 15:29:23,685 DEBUG   HandlerThread:57348 [meta.py:_save_pip():53] save pip
2024-03-06 15:29:23,687 DEBUG   HandlerThread:57348 [meta.py:_save_pip():67] save pip done
2024-03-06 15:29:23,687 DEBUG   HandlerThread:57348 [meta.py:_save_conda():74] save conda
2024-03-06 15:29:24,628 INFO    Thread-16 :57348 [dir_watcher.py:_on_file_created():256] file/dir created: .\wandb\run-20240306_152917-1hl4cn36\files\conda-environment.yaml
2024-03-06 15:29:24,629 INFO    Thread-16 :57348 [dir_watcher.py:_on_file_created():256] file/dir created: .\wandb\run-20240306_152917-1hl4cn36\files\requirements.txt
2024-03-06 15:29:27,500 DEBUG   HandlerThread:57348 [meta.py:_save_conda():84] save conda done
2024-03-06 15:29:27,500 DEBUG   HandlerThread:57348 [meta.py:probe():247] probe done
2024-03-06 15:29:27,573 DEBUG   SenderThread:57348 [sender.py:send():235] send: files
2024-03-06 15:29:27,573 INFO    SenderThread:57348 [sender.py:_save_file():949] saving file wandb-metadata.json with policy now
2024-03-06 15:29:27,574 DEBUG   HandlerThread:57348 [handler.py:handle_request():141] handle_request: stop_status
2024-03-06 15:29:27,575 DEBUG   SenderThread:57348 [sender.py:send_request():249] send_request: stop_status
2024-03-06 15:29:27,652 INFO    Thread-16 :57348 [dir_watcher.py:_on_file_modified():269] file/dir modified: .\wandb\run-20240306_152917-1hl4cn36\files\conda-environment.yaml
2024-03-06 15:29:27,653 INFO    Thread-16 :57348 [dir_watcher.py:_on_file_created():256] file/dir created: .\wandb\run-20240306_152917-1hl4cn36\files\wandb-metadata.json
2024-03-06 15:29:27,653 INFO    Thread-16 :57348 [dir_watcher.py:_on_file_created():256] file/dir created: .\wandb\run-20240306_152917-1hl4cn36\files\output.log
2024-03-06 15:29:29,204 DEBUG   SenderThread:57348 [sender.py:send():235] send: telemetry
2024-03-06 15:29:29,204 DEBUG   SenderThread:57348 [sender.py:send():235] send: metric
2024-03-06 15:29:29,204 DEBUG   SenderThread:57348 [sender.py:send():235] send: telemetry
2024-03-06 15:29:29,204 DEBUG   SenderThread:57348 [sender.py:send():235] send: metric
2024-03-06 15:29:29,205 WARNING SenderThread:57348 [sender.py:send_metric():905] Seen metric with glob (shouldn't happen)
2024-03-06 15:29:29,205 DEBUG   SenderThread:57348 [sender.py:send():235] send: config
2024-03-06 15:29:29,670 INFO    Thread-16 :57348 [dir_watcher.py:_on_file_modified():269] file/dir modified: .\wandb\run-20240306_152917-1hl4cn36\files\output.log
2024-03-06 15:29:29,752 ERROR   Thread-22 :57348 [internal_api.py:upload_file():1640] upload_file exception https://storage.googleapis.com/wandb-production.appspot.com/shahwaiz/UNet-DAS/1hl4cn36/wandb-metadata.json?Expires=1709796569&GoogleAccessId=gorilla-files-url-signer-man%40wandb-production.iam.gserviceaccount.com&Signature=ZOjft9fu%2Bu1O4J0uXcPelW8mhQdVFFpO4cLhRnfytHRuf8RTAhMmZQsLOJAuYsL%2B3L8RbpoDVjYBhIONNE39EG6cJSI9VyRNxe7Ax1d3E2Hn2sgYKWxrCr3CJyhHJDW0wwtXk6MSDkmqG8QPQgbCzdGI0wS5QVuo8N6SR%2F9EjwT77D4SOE4CtNxRfDC%2Fsr3GzNNkWqBJhB8KCLgjDUo1mEDAYCmdSSFnbmnEuGZ18kru1a4wzQjfhjlJ2bZJD3lYwrAaij1ssbgU0ilKrf9He4aJuouPz%2BRyLCJRSvVNnslV4syKF6IyBELq9en4gqTDFdGkNKMc2N5dCi91%2B8QFyw%3D%3D: ('Connection aborted.', ConnectionResetError(10054, '远程主机强迫关闭了一个现有的连接。', None, 10054, None))
2024-03-06 15:29:29,752 ERROR   Thread-22 :57348 [internal_api.py:upload_file():1642] upload_file request headers: {'User-Agent': 'python-requests/2.31.0', 'Accept-Encoding': 'gzip, deflate', 'Accept': '*/*', 'Connection': 'keep-alive', 'Content-Length': '766'}
2024-03-06 15:29:29,753 ERROR   Thread-22 :57348 [internal_api.py:upload_file():1644] upload_file response body: 
2024-03-06 15:29:31,567 ERROR   Thread-22 :57348 [internal_api.py:upload_file():1640] upload_file exception https://storage.googleapis.com/wandb-production.appspot.com/shahwaiz/UNet-DAS/1hl4cn36/wandb-metadata.json?Expires=1709796569&GoogleAccessId=gorilla-files-url-signer-man%40wandb-production.iam.gserviceaccount.com&Signature=ZOjft9fu%2Bu1O4J0uXcPelW8mhQdVFFpO4cLhRnfytHRuf8RTAhMmZQsLOJAuYsL%2B3L8RbpoDVjYBhIONNE39EG6cJSI9VyRNxe7Ax1d3E2Hn2sgYKWxrCr3CJyhHJDW0wwtXk6MSDkmqG8QPQgbCzdGI0wS5QVuo8N6SR%2F9EjwT77D4SOE4CtNxRfDC%2Fsr3GzNNkWqBJhB8KCLgjDUo1mEDAYCmdSSFnbmnEuGZ18kru1a4wzQjfhjlJ2bZJD3lYwrAaij1ssbgU0ilKrf9He4aJuouPz%2BRyLCJRSvVNnslV4syKF6IyBELq9en4gqTDFdGkNKMc2N5dCi91%2B8QFyw%3D%3D: ('Connection aborted.', ConnectionResetError(10054, '远程主机强迫关闭了一个现有的连接。', None, 10054, None))
2024-03-06 15:29:31,567 ERROR   Thread-22 :57348 [internal_api.py:upload_file():1642] upload_file request headers: {'User-Agent': 'python-requests/2.31.0', 'Accept-Encoding': 'gzip, deflate', 'Accept': '*/*', 'Connection': 'keep-alive', 'Content-Length': '766'}
2024-03-06 15:29:31,567 ERROR   Thread-22 :57348 [internal_api.py:upload_file():1644] upload_file response body: 
2024-03-06 15:29:34,588 ERROR   Thread-22 :57348 [internal_api.py:upload_file():1640] upload_file exception https://storage.googleapis.com/wandb-production.appspot.com/shahwaiz/UNet-DAS/1hl4cn36/wandb-metadata.json?Expires=1709796569&GoogleAccessId=gorilla-files-url-signer-man%40wandb-production.iam.gserviceaccount.com&Signature=ZOjft9fu%2Bu1O4J0uXcPelW8mhQdVFFpO4cLhRnfytHRuf8RTAhMmZQsLOJAuYsL%2B3L8RbpoDVjYBhIONNE39EG6cJSI9VyRNxe7Ax1d3E2Hn2sgYKWxrCr3CJyhHJDW0wwtXk6MSDkmqG8QPQgbCzdGI0wS5QVuo8N6SR%2F9EjwT77D4SOE4CtNxRfDC%2Fsr3GzNNkWqBJhB8KCLgjDUo1mEDAYCmdSSFnbmnEuGZ18kru1a4wzQjfhjlJ2bZJD3lYwrAaij1ssbgU0ilKrf9He4aJuouPz%2BRyLCJRSvVNnslV4syKF6IyBELq9en4gqTDFdGkNKMc2N5dCi91%2B8QFyw%3D%3D: ('Connection aborted.', ConnectionResetError(10054, '远程主机强迫关闭了一个现有的连接。', None, 10054, None))
2024-03-06 15:29:34,589 ERROR   Thread-22 :57348 [internal_api.py:upload_file():1642] upload_file request headers: {'User-Agent': 'python-requests/2.31.0', 'Accept-Encoding': 'gzip, deflate', 'Accept': '*/*', 'Connection': 'keep-alive', 'Content-Length': '766'}
2024-03-06 15:29:34,589 ERROR   Thread-22 :57348 [internal_api.py:upload_file():1644] upload_file response body: 
2024-03-06 15:29:34,589 ERROR   Thread-22 :57348 [retry.py:__call__():126] Retry attempt failed:
Traceback (most recent call last):
  File "E:\Anaconda\envs\unet\lib\site-packages\urllib3\connectionpool.py", line 793, in urlopen
    response = self._make_request(
  File "E:\Anaconda\envs\unet\lib\site-packages\urllib3\connectionpool.py", line 491, in _make_request
    raise new_e
  File "E:\Anaconda\envs\unet\lib\site-packages\urllib3\connectionpool.py", line 467, in _make_request
    self._validate_conn(conn)
  File "E:\Anaconda\envs\unet\lib\site-packages\urllib3\connectionpool.py", line 1099, in _validate_conn
    conn.connect()
  File "E:\Anaconda\envs\unet\lib\site-packages\urllib3\connection.py", line 653, in connect
    sock_and_verified = _ssl_wrap_socket_and_match_hostname(
  File "E:\Anaconda\envs\unet\lib\site-packages\urllib3\connection.py", line 806, in _ssl_wrap_socket_and_match_hostname
    ssl_sock = ssl_wrap_socket(
  File "E:\Anaconda\envs\unet\lib\site-packages\urllib3\util\ssl_.py", line 465, in ssl_wrap_socket
    ssl_sock = _ssl_wrap_socket_impl(sock, context, tls_in_tls, server_hostname)
  File "E:\Anaconda\envs\unet\lib\site-packages\urllib3\util\ssl_.py", line 509, in _ssl_wrap_socket_impl
    return ssl_context.wrap_socket(sock, server_hostname=server_hostname)
  File "E:\Anaconda\envs\unet\lib\ssl.py", line 500, in wrap_socket
    return self.sslsocket_class._create(
  File "E:\Anaconda\envs\unet\lib\ssl.py", line 1073, in _create
    self.do_handshake()
  File "E:\Anaconda\envs\unet\lib\ssl.py", line 1342, in do_handshake
    self._sslobj.do_handshake()
ConnectionResetError: [WinError 10054] 远程主机强迫关闭了一个现有的连接。

During handling of the above exception, another exception occurred:

Traceback (most recent call last):
  File "E:\Anaconda\envs\unet\lib\site-packages\requests\adapters.py", line 486, in send
    resp = conn.urlopen(
  File "E:\Anaconda\envs\unet\lib\site-packages\urllib3\connectionpool.py", line 847, in urlopen
    retries = retries.increment(
  File "E:\Anaconda\envs\unet\lib\site-packages\urllib3\util\retry.py", line 470, in increment
    raise reraise(type(error), error, _stacktrace)
  File "E:\Anaconda\envs\unet\lib\site-packages\urllib3\util\util.py", line 38, in reraise
    raise value.with_traceback(tb)
  File "E:\Anaconda\envs\unet\lib\site-packages\urllib3\connectionpool.py", line 793, in urlopen
    response = self._make_request(
  File "E:\Anaconda\envs\unet\lib\site-packages\urllib3\connectionpool.py", line 491, in _make_request
    raise new_e
  File "E:\Anaconda\envs\unet\lib\site-packages\urllib3\connectionpool.py", line 467, in _make_request
    self._validate_conn(conn)
  File "E:\Anaconda\envs\unet\lib\site-packages\urllib3\connectionpool.py", line 1099, in _validate_conn
    conn.connect()
  File "E:\Anaconda\envs\unet\lib\site-packages\urllib3\connection.py", line 653, in connect
    sock_and_verified = _ssl_wrap_socket_and_match_hostname(
  File "E:\Anaconda\envs\unet\lib\site-packages\urllib3\connection.py", line 806, in _ssl_wrap_socket_and_match_hostname
    ssl_sock = ssl_wrap_socket(
  File "E:\Anaconda\envs\unet\lib\site-packages\urllib3\util\ssl_.py", line 465, in ssl_wrap_socket
    ssl_sock = _ssl_wrap_socket_impl(sock, context, tls_in_tls, server_hostname)
  File "E:\Anaconda\envs\unet\lib\site-packages\urllib3\util\ssl_.py", line 509, in _ssl_wrap_socket_impl
    return ssl_context.wrap_socket(sock, server_hostname=server_hostname)
  File "E:\Anaconda\envs\unet\lib\ssl.py", line 500, in wrap_socket
    return self.sslsocket_class._create(
  File "E:\Anaconda\envs\unet\lib\ssl.py", line 1073, in _create
    self.do_handshake()
  File "E:\Anaconda\envs\unet\lib\ssl.py", line 1342, in do_handshake
    self._sslobj.do_handshake()
urllib3.exceptions.ProtocolError: ('Connection aborted.', ConnectionResetError(10054, '远程主机强迫关闭了一个现有的连接。', None, 10054, None))

During handling of the above exception, another exception occurred:

Traceback (most recent call last):
  File "C:\Users\19086\AppData\Roaming\Python\Python38\site-packages\wandb\sdk\internal\internal_api.py", line 1637, in upload_file
    response = requests.put(url, data=progress, headers=extra_headers)
  File "E:\Anaconda\envs\unet\lib\site-packages\requests\api.py", line 130, in put
    return request("put", url, data=data, **kwargs)
  File "E:\Anaconda\envs\unet\lib\site-packages\requests\api.py", line 59, in request
    return session.request(method=method, url=url, **kwargs)
  File "E:\Anaconda\envs\unet\lib\site-packages\requests\sessions.py", line 589, in request
    resp = self.send(prep, **send_kwargs)
  File "E:\Anaconda\envs\unet\lib\site-packages\requests\sessions.py", line 703, in send
    r = adapter.send(request, **kwargs)
  File "E:\Anaconda\envs\unet\lib\site-packages\requests\adapters.py", line 501, in send
    raise ConnectionError(err, request=request)
requests.exceptions.ConnectionError: ('Connection aborted.', ConnectionResetError(10054, '远程主机强迫关闭了一个现有的连接。', None, 10054, None))

During handling of the above exception, another exception occurred:

Traceback (most recent call last):
  File "C:\Users\19086\AppData\Roaming\Python\Python38\site-packages\wandb\sdk\lib\retry.py", line 102, in __call__
    result = self._call_fn(*args, **kwargs)
  File "C:\Users\19086\AppData\Roaming\Python\Python38\site-packages\wandb\sdk\internal\internal_api.py", line 1653, in upload_file
    raise e.with_traceback(sys.exc_info()[2])
  File "C:\Users\19086\AppData\Roaming\Python\Python38\site-packages\wandb\sdk\internal\internal_api.py", line 1637, in upload_file
    response = requests.put(url, data=progress, headers=extra_headers)
  File "E:\Anaconda\envs\unet\lib\site-packages\requests\api.py", line 130, in put
    return request("put", url, data=data, **kwargs)
  File "E:\Anaconda\envs\unet\lib\site-packages\requests\api.py", line 59, in request
    return session.request(method=method, url=url, **kwargs)
  File "E:\Anaconda\envs\unet\lib\site-packages\requests\sessions.py", line 589, in request
    resp = self.send(prep, **send_kwargs)
  File "E:\Anaconda\envs\unet\lib\site-packages\requests\sessions.py", line 703, in send
    r = adapter.send(request, **kwargs)
  File "E:\Anaconda\envs\unet\lib\site-packages\requests\adapters.py", line 501, in send
    raise ConnectionError(err, request=request)
wandb.sdk.lib.retry.TransientError: None
2024-03-06 15:29:39,895 ERROR   Thread-22 :57348 [internal_api.py:upload_file():1640] upload_file exception https://storage.googleapis.com/wandb-production.appspot.com/shahwaiz/UNet-DAS/1hl4cn36/wandb-metadata.json?Expires=1709796569&GoogleAccessId=gorilla-files-url-signer-man%40wandb-production.iam.gserviceaccount.com&Signature=ZOjft9fu%2Bu1O4J0uXcPelW8mhQdVFFpO4cLhRnfytHRuf8RTAhMmZQsLOJAuYsL%2B3L8RbpoDVjYBhIONNE39EG6cJSI9VyRNxe7Ax1d3E2Hn2sgYKWxrCr3CJyhHJDW0wwtXk6MSDkmqG8QPQgbCzdGI0wS5QVuo8N6SR%2F9EjwT77D4SOE4CtNxRfDC%2Fsr3GzNNkWqBJhB8KCLgjDUo1mEDAYCmdSSFnbmnEuGZ18kru1a4wzQjfhjlJ2bZJD3lYwrAaij1ssbgU0ilKrf9He4aJuouPz%2BRyLCJRSvVNnslV4syKF6IyBELq9en4gqTDFdGkNKMc2N5dCi91%2B8QFyw%3D%3D: ('Connection aborted.', ConnectionResetError(10054, '远程主机强迫关闭了一个现有的连接。', None, 10054, None))
2024-03-06 15:29:39,895 ERROR   Thread-22 :57348 [internal_api.py:upload_file():1642] upload_file request headers: {'User-Agent': 'python-requests/2.31.0', 'Accept-Encoding': 'gzip, deflate', 'Accept': '*/*', 'Connection': 'keep-alive', 'Content-Length': '766'}
2024-03-06 15:29:39,896 ERROR   Thread-22 :57348 [internal_api.py:upload_file():1644] upload_file response body: 
2024-03-06 15:29:43,776 INFO    Thread-16 :57348 [dir_watcher.py:_on_file_modified():269] file/dir modified: .\wandb\run-20240306_152917-1hl4cn36\files\output.log
2024-03-06 15:29:44,208 DEBUG   HandlerThread:57348 [handler.py:handle_request():141] handle_request: stop_status
2024-03-06 15:29:44,209 DEBUG   SenderThread:57348 [sender.py:send_request():249] send_request: stop_status
2024-03-06 15:29:44,832 DEBUG   HandlerThread:57348 [handler.py:handle_request():141] handle_request: poll_exit
2024-03-06 15:29:45,604 DEBUG   SenderThread:57348 [sender.py:send():235] send: telemetry
2024-03-06 15:29:45,604 DEBUG   SenderThread:57348 [sender.py:send():235] send: exit
2024-03-06 15:29:45,604 INFO    SenderThread:57348 [sender.py:send_exit():371] handling exit code: 0
2024-03-06 15:29:45,604 INFO    SenderThread:57348 [sender.py:send_exit():373] handling runtime: 21
2024-03-06 15:29:45,607 INFO    SenderThread:57348 [sender.py:_save_file():949] saving file wandb-summary.json with policy end
2024-03-06 15:29:45,608 INFO    SenderThread:57348 [sender.py:send_exit():379] send defer
2024-03-06 15:29:45,608 DEBUG   SenderThread:57348 [sender.py:send_request():249] send_request: poll_exit
2024-03-06 15:29:45,609 DEBUG   HandlerThread:57348 [handler.py:handle_request():141] handle_request: defer
2024-03-06 15:29:45,609 INFO    HandlerThread:57348 [handler.py:handle_request_defer():164] handle defer: 0
2024-03-06 15:29:45,610 DEBUG   SenderThread:57348 [sender.py:send_request():249] send_request: defer
2024-03-06 15:29:45,610 INFO    SenderThread:57348 [sender.py:send_request_defer():388] handle sender defer: 0
2024-03-06 15:29:45,610 INFO    SenderThread:57348 [sender.py:transition_state():392] send defer: 1
2024-03-06 15:29:45,610 DEBUG   HandlerThread:57348 [handler.py:handle_request():141] handle_request: defer
2024-03-06 15:29:45,610 INFO    HandlerThread:57348 [handler.py:handle_request_defer():164] handle defer: 1
2024-03-06 15:29:45,722 DEBUG   HandlerThread:57348 [handler.py:handle_request():141] handle_request: poll_exit
2024-03-06 15:29:45,722 DEBUG   SenderThread:57348 [sender.py:send_request():249] send_request: defer
2024-03-06 15:29:45,722 INFO    SenderThread:57348 [sender.py:send_request_defer():388] handle sender defer: 1
2024-03-06 15:29:45,722 INFO    SenderThread:57348 [sender.py:transition_state():392] send defer: 2
2024-03-06 15:29:45,723 DEBUG   SenderThread:57348 [sender.py:send_request():249] send_request: poll_exit
2024-03-06 15:29:45,723 DEBUG   HandlerThread:57348 [handler.py:handle_request():141] handle_request: defer
2024-03-06 15:29:45,723 DEBUG   SenderThread:57348 [sender.py:send():235] send: stats
2024-03-06 15:29:45,724 INFO    HandlerThread:57348 [handler.py:handle_request_defer():164] handle defer: 2
2024-03-06 15:29:45,724 DEBUG   SenderThread:57348 [sender.py:send_request():249] send_request: defer
2024-03-06 15:29:45,724 INFO    SenderThread:57348 [sender.py:send_request_defer():388] handle sender defer: 2
2024-03-06 15:29:45,724 INFO    SenderThread:57348 [sender.py:transition_state():392] send defer: 3
2024-03-06 15:29:45,725 DEBUG   HandlerThread:57348 [handler.py:handle_request():141] handle_request: defer
2024-03-06 15:29:45,725 INFO    HandlerThread:57348 [handler.py:handle_request_defer():164] handle defer: 3
2024-03-06 15:29:45,725 DEBUG   SenderThread:57348 [sender.py:send_request():249] send_request: defer
2024-03-06 15:29:45,725 INFO    SenderThread:57348 [sender.py:send_request_defer():388] handle sender defer: 3
2024-03-06 15:29:45,725 INFO    SenderThread:57348 [sender.py:transition_state():392] send defer: 4
2024-03-06 15:29:45,725 DEBUG   HandlerThread:57348 [handler.py:handle_request():141] handle_request: defer
2024-03-06 15:29:45,726 INFO    HandlerThread:57348 [handler.py:handle_request_defer():164] handle defer: 4
2024-03-06 15:29:45,726 DEBUG   SenderThread:57348 [sender.py:send():235] send: summary
2024-03-06 15:29:45,726 INFO    SenderThread:57348 [sender.py:_save_file():949] saving file wandb-summary.json with policy end
2024-03-06 15:29:45,727 DEBUG   SenderThread:57348 [sender.py:send_request():249] send_request: defer
2024-03-06 15:29:45,727 INFO    SenderThread:57348 [sender.py:send_request_defer():388] handle sender defer: 4
2024-03-06 15:29:45,727 INFO    SenderThread:57348 [sender.py:transition_state():392] send defer: 5
2024-03-06 15:29:45,727 DEBUG   HandlerThread:57348 [handler.py:handle_request():141] handle_request: defer
2024-03-06 15:29:45,727 INFO    HandlerThread:57348 [handler.py:handle_request_defer():164] handle defer: 5
2024-03-06 15:29:45,728 DEBUG   SenderThread:57348 [sender.py:send_request():249] send_request: defer
2024-03-06 15:29:45,728 INFO    SenderThread:57348 [sender.py:send_request_defer():388] handle sender defer: 5
2024-03-06 15:29:45,794 INFO    Thread-16 :57348 [dir_watcher.py:_on_file_modified():269] file/dir modified: .\wandb\run-20240306_152917-1hl4cn36\files\output.log
2024-03-06 15:29:45,795 INFO    Thread-16 :57348 [dir_watcher.py:_on_file_modified():269] file/dir modified: .\wandb\run-20240306_152917-1hl4cn36\files\wandb-summary.json
2024-03-06 15:29:45,839 DEBUG   HandlerThread:57348 [handler.py:handle_request():141] handle_request: poll_exit
2024-03-06 15:29:47,075 INFO    SenderThread:57348 [sender.py:transition_state():392] send defer: 6
2024-03-06 15:29:47,075 DEBUG   SenderThread:57348 [sender.py:send_request():249] send_request: poll_exit
2024-03-06 15:29:47,076 DEBUG   HandlerThread:57348 [handler.py:handle_request():141] handle_request: defer
2024-03-06 15:29:47,076 INFO    HandlerThread:57348 [handler.py:handle_request_defer():164] handle defer: 6
2024-03-06 15:29:47,076 DEBUG   SenderThread:57348 [sender.py:send_request():249] send_request: defer
2024-03-06 15:29:47,076 INFO    SenderThread:57348 [sender.py:send_request_defer():388] handle sender defer: 6
2024-03-06 15:29:47,077 INFO    SenderThread:57348 [dir_watcher.py:finish():336] shutting down directory watcher
2024-03-06 15:29:47,177 DEBUG   HandlerThread:57348 [handler.py:handle_request():141] handle_request: poll_exit
2024-03-06 15:29:47,810 INFO    SenderThread:57348 [dir_watcher.py:_on_file_modified():269] file/dir modified: .\wandb\run-20240306_152917-1hl4cn36\files\config.yaml
2024-03-06 15:29:47,811 INFO    SenderThread:57348 [dir_watcher.py:finish():366] scan: .\wandb\run-20240306_152917-1hl4cn36\files
2024-03-06 15:29:47,811 INFO    SenderThread:57348 [dir_watcher.py:finish():380] scan save: .\wandb\run-20240306_152917-1hl4cn36\files\conda-environment.yaml conda-environment.yaml
2024-03-06 15:29:47,812 INFO    SenderThread:57348 [dir_watcher.py:finish():380] scan save: .\wandb\run-20240306_152917-1hl4cn36\files\config.yaml config.yaml
2024-03-06 15:29:47,819 INFO    SenderThread:57348 [dir_watcher.py:finish():380] scan save: .\wandb\run-20240306_152917-1hl4cn36\files\output.log output.log
2024-03-06 15:29:47,824 INFO    SenderThread:57348 [dir_watcher.py:finish():380] scan save: .\wandb\run-20240306_152917-1hl4cn36\files\requirements.txt requirements.txt
2024-03-06 15:29:47,833 INFO    SenderThread:57348 [dir_watcher.py:finish():380] scan save: .\wandb\run-20240306_152917-1hl4cn36\files\wandb-metadata.json wandb-metadata.json
2024-03-06 15:29:47,833 INFO    SenderThread:57348 [dir_watcher.py:finish():380] scan save: .\wandb\run-20240306_152917-1hl4cn36\files\wandb-summary.json wandb-summary.json
2024-03-06 15:29:47,840 INFO    SenderThread:57348 [sender.py:transition_state():392] send defer: 7
2024-03-06 15:29:47,840 DEBUG   SenderThread:57348 [sender.py:send_request():249] send_request: poll_exit
2024-03-06 15:29:47,847 DEBUG   HandlerThread:57348 [handler.py:handle_request():141] handle_request: defer
2024-03-06 15:29:47,847 INFO    HandlerThread:57348 [handler.py:handle_request_defer():164] handle defer: 7
2024-03-06 15:29:47,847 DEBUG   SenderThread:57348 [sender.py:send_request():249] send_request: defer
2024-03-06 15:29:47,847 INFO    SenderThread:57348 [sender.py:send_request_defer():388] handle sender defer: 7
2024-03-06 15:29:47,848 INFO    SenderThread:57348 [file_pusher.py:finish():145] shutting down file pusher
2024-03-06 15:29:47,948 DEBUG   HandlerThread:57348 [handler.py:handle_request():141] handle_request: poll_exit
2024-03-06 15:29:47,949 DEBUG   SenderThread:57348 [sender.py:send_request():249] send_request: poll_exit
2024-03-06 15:29:48,056 DEBUG   HandlerThread:57348 [handler.py:handle_request():141] handle_request: poll_exit
2024-03-06 15:29:48,057 DEBUG   SenderThread:57348 [sender.py:send_request():249] send_request: poll_exit
2024-03-06 15:29:48,164 DEBUG   HandlerThread:57348 [handler.py:handle_request():141] handle_request: poll_exit
2024-03-06 15:29:48,165 DEBUG   SenderThread:57348 [sender.py:send_request():249] send_request: poll_exit
2024-03-06 15:29:48,271 DEBUG   HandlerThread:57348 [handler.py:handle_request():141] handle_request: poll_exit
2024-03-06 15:29:48,271 DEBUG   SenderThread:57348 [sender.py:send_request():249] send_request: poll_exit
2024-03-06 15:29:48,379 DEBUG   HandlerThread:57348 [handler.py:handle_request():141] handle_request: poll_exit
2024-03-06 15:29:48,379 DEBUG   SenderThread:57348 [sender.py:send_request():249] send_request: poll_exit
2024-03-06 15:29:48,488 DEBUG   HandlerThread:57348 [handler.py:handle_request():141] handle_request: poll_exit
2024-03-06 15:29:48,489 DEBUG   SenderThread:57348 [sender.py:send_request():249] send_request: poll_exit
2024-03-06 15:29:48,596 DEBUG   HandlerThread:57348 [handler.py:handle_request():141] handle_request: poll_exit
2024-03-06 15:29:48,596 DEBUG   SenderThread:57348 [sender.py:send_request():249] send_request: poll_exit
2024-03-06 15:29:48,704 DEBUG   HandlerThread:57348 [handler.py:handle_request():141] handle_request: poll_exit
2024-03-06 15:29:48,705 DEBUG   SenderThread:57348 [sender.py:send_request():249] send_request: poll_exit
2024-03-06 15:29:48,813 DEBUG   HandlerThread:57348 [handler.py:handle_request():141] handle_request: poll_exit
2024-03-06 15:29:48,814 DEBUG   SenderThread:57348 [sender.py:send_request():249] send_request: poll_exit
2024-03-06 15:29:48,918 DEBUG   HandlerThread:57348 [handler.py:handle_request():141] handle_request: poll_exit
2024-03-06 15:29:48,919 DEBUG   SenderThread:57348 [sender.py:send_request():249] send_request: poll_exit
2024-03-06 15:29:48,927 ERROR   Thread-22 :57348 [internal_api.py:upload_file():1640] upload_file exception https://storage.googleapis.com/wandb-production.appspot.com/shahwaiz/UNet-DAS/1hl4cn36/wandb-metadata.json?Expires=1709796569&GoogleAccessId=gorilla-files-url-signer-man%40wandb-production.iam.gserviceaccount.com&Signature=ZOjft9fu%2Bu1O4J0uXcPelW8mhQdVFFpO4cLhRnfytHRuf8RTAhMmZQsLOJAuYsL%2B3L8RbpoDVjYBhIONNE39EG6cJSI9VyRNxe7Ax1d3E2Hn2sgYKWxrCr3CJyhHJDW0wwtXk6MSDkmqG8QPQgbCzdGI0wS5QVuo8N6SR%2F9EjwT77D4SOE4CtNxRfDC%2Fsr3GzNNkWqBJhB8KCLgjDUo1mEDAYCmdSSFnbmnEuGZ18kru1a4wzQjfhjlJ2bZJD3lYwrAaij1ssbgU0ilKrf9He4aJuouPz%2BRyLCJRSvVNnslV4syKF6IyBELq9en4gqTDFdGkNKMc2N5dCi91%2B8QFyw%3D%3D: ('Connection aborted.', ConnectionResetError(10054, '远程主机强迫关闭了一个现有的连接。', None, 10054, None))
2024-03-06 15:29:48,927 ERROR   Thread-22 :57348 [internal_api.py:upload_file():1642] upload_file request headers: {'User-Agent': 'python-requests/2.31.0', 'Accept-Encoding': 'gzip, deflate', 'Accept': '*/*', 'Connection': 'keep-alive', 'Content-Length': '766'}
2024-03-06 15:29:48,927 ERROR   Thread-22 :57348 [internal_api.py:upload_file():1644] upload_file response body: 
2024-03-06 15:29:49,026 DEBUG   HandlerThread:57348 [handler.py:handle_request():141] handle_request: poll_exit
2024-03-06 15:29:49,027 DEBUG   SenderThread:57348 [sender.py:send_request():249] send_request: poll_exit
2024-03-06 15:29:49,134 DEBUG   HandlerThread:57348 [handler.py:handle_request():141] handle_request: poll_exit
2024-03-06 15:29:49,136 DEBUG   SenderThread:57348 [sender.py:send_request():249] send_request: poll_exit
2024-03-06 15:29:49,244 DEBUG   HandlerThread:57348 [handler.py:handle_request():141] handle_request: poll_exit
2024-03-06 15:29:49,245 DEBUG   SenderThread:57348 [sender.py:send_request():249] send_request: poll_exit
2024-03-06 15:29:49,352 DEBUG   HandlerThread:57348 [handler.py:handle_request():141] handle_request: poll_exit
2024-03-06 15:29:49,353 DEBUG   SenderThread:57348 [sender.py:send_request():249] send_request: poll_exit
2024-03-06 15:29:49,459 DEBUG   HandlerThread:57348 [handler.py:handle_request():141] handle_request: poll_exit
2024-03-06 15:29:49,459 DEBUG   SenderThread:57348 [sender.py:send_request():249] send_request: poll_exit
2024-03-06 15:29:49,568 DEBUG   HandlerThread:57348 [handler.py:handle_request():141] handle_request: poll_exit
2024-03-06 15:29:49,569 DEBUG   SenderThread:57348 [sender.py:send_request():249] send_request: poll_exit
2024-03-06 15:29:49,676 DEBUG   HandlerThread:57348 [handler.py:handle_request():141] handle_request: poll_exit
2024-03-06 15:29:49,677 DEBUG   SenderThread:57348 [sender.py:send_request():249] send_request: poll_exit
2024-03-06 15:29:49,784 DEBUG   HandlerThread:57348 [handler.py:handle_request():141] handle_request: poll_exit
2024-03-06 15:29:49,785 DEBUG   SenderThread:57348 [sender.py:send_request():249] send_request: poll_exit
2024-03-06 15:29:49,837 ERROR   Thread-24 :57348 [internal_api.py:upload_file():1640] upload_file exception https://storage.googleapis.com/wandb-production.appspot.com/shahwaiz/UNet-DAS/1hl4cn36/config.yaml?Expires=1709796589&GoogleAccessId=gorilla-files-url-signer-man%40wandb-production.iam.gserviceaccount.com&Signature=wkFRpJf4KRAWj%2FVuw9aJm1MAI8zFH%2Bohfev9Fl%2FDoJGLKKvFs4%2FiMXW2STEL%2B2eBpuzlRsBO1BK3SjvKbcV71pO5GY4ZyuH8Zadd0ouv8tuHeajzwYBZpGfUbJNhmGIuFbhNJLTzqKu5DQTVQURsrakNT0EvtLseVbhg6rvR%2FNJHELK7Gx2IgS14CjZM1WUVZ3v2zdl1SblPymb10aMUeVwmlvQR%2FTPY%2FTx1dopjpSkSPs4O1YI8ed5HaR6nE%2FPoqUd%2FPAHyIOk05%2B7gNOxgUE7XNn6cdOEikyNxuVYI5Zn9DbvGVIABJGr1S0oINOlGCmAgRyODaXHJl0dRE7Dvzw%3D%3D: ('Connection aborted.', ConnectionResetError(10054, '远程主机强迫关闭了一个现有的连接。', None, 10054, None))
2024-03-06 15:29:49,838 ERROR   Thread-24 :57348 [internal_api.py:upload_file():1642] upload_file request headers: {'User-Agent': 'python-requests/2.31.0', 'Accept-Encoding': 'gzip, deflate', 'Accept': '*/*', 'Connection': 'keep-alive', 'Content-Length': '1577'}
2024-03-06 15:29:49,838 ERROR   Thread-24 :57348 [internal_api.py:upload_file():1644] upload_file response body: 
2024-03-06 15:29:49,894 DEBUG   HandlerThread:57348 [handler.py:handle_request():141] handle_request: poll_exit
2024-03-06 15:29:49,895 DEBUG   SenderThread:57348 [sender.py:send_request():249] send_request: poll_exit
2024-03-06 15:29:50,003 DEBUG   HandlerThread:57348 [handler.py:handle_request():141] handle_request: poll_exit
2024-03-06 15:29:50,004 DEBUG   SenderThread:57348 [sender.py:send_request():249] send_request: poll_exit
2024-03-06 15:29:50,060 ERROR   Thread-26 :57348 [internal_api.py:upload_file():1640] upload_file exception https://storage.googleapis.com/wandb-production.appspot.com/shahwaiz/UNet-DAS/1hl4cn36/requirements.txt?Expires=1709796589&GoogleAccessId=gorilla-files-url-signer-man%40wandb-production.iam.gserviceaccount.com&Signature=TWM77nhE6PdyHkEs%2FdPIu0Z6PMu4QmRfQ3UuXP%2FUuAZ2kot4bUvryRPA05onYecXzJyqCwegqIQNPIMfUfLW8ITv1TfKaMCThBOXixXBJPPWLmybEdUKq1n2EY18yoDk%2Bp0cthglEuPHz7ytkM3XTiTRDKQEX0hD%2BsYYvDEPXyVQrXC67HBZHp3Ynr1Dfm6YuJ4E62EaknIDsMBMwLYAfRlREUKMsF8WlTZzt7g1ThbtM3Yj42zrx%2Fqd%2FFQEoNvACowUssKf1eTFJv9B8maKbMgM%2FeQkMKdUKm0dyu36H9s5GFuJmnKdD4kxIqNPjoPZwZNMw6WRqskNSNYuT0rkqA%3D%3D: ('Connection aborted.', ConnectionResetError(10054, '远程主机强迫关闭了一个现有的连接。', None, 10054, None))
2024-03-06 15:29:50,060 ERROR   Thread-26 :57348 [internal_api.py:upload_file():1642] upload_file request headers: {'User-Agent': 'python-requests/2.31.0', 'Accept-Encoding': 'gzip, deflate', 'Accept': '*/*', 'Connection': 'keep-alive', 'Content-Length': '1252'}
2024-03-06 15:29:50,061 ERROR   Thread-26 :57348 [internal_api.py:upload_file():1644] upload_file response body: 
2024-03-06 15:29:50,110 DEBUG   HandlerThread:57348 [handler.py:handle_request():141] handle_request: poll_exit
2024-03-06 15:29:50,111 DEBUG   SenderThread:57348 [sender.py:send_request():249] send_request: poll_exit
2024-03-06 15:29:50,218 DEBUG   HandlerThread:57348 [handler.py:handle_request():141] handle_request: poll_exit
2024-03-06 15:29:50,219 DEBUG   SenderThread:57348 [sender.py:send_request():249] send_request: poll_exit
2024-03-06 15:29:50,326 DEBUG   HandlerThread:57348 [handler.py:handle_request():141] handle_request: poll_exit
2024-03-06 15:29:50,327 DEBUG   SenderThread:57348 [sender.py:send_request():249] send_request: poll_exit
2024-03-06 15:29:50,435 DEBUG   HandlerThread:57348 [handler.py:handle_request():141] handle_request: poll_exit
2024-03-06 15:29:50,436 DEBUG   SenderThread:57348 [sender.py:send_request():249] send_request: poll_exit
2024-03-06 15:29:50,479 INFO    Thread-25 :57348 [upload_job.py:push():132] Uploaded file .\wandb\run-20240306_152917-1hl4cn36\files\output.log
2024-03-06 15:29:50,543 DEBUG   HandlerThread:57348 [handler.py:handle_request():141] handle_request: poll_exit
2024-03-06 15:29:50,544 DEBUG   SenderThread:57348 [sender.py:send_request():249] send_request: poll_exit
2024-03-06 15:29:50,650 DEBUG   HandlerThread:57348 [handler.py:handle_request():141] handle_request: poll_exit
2024-03-06 15:29:50,651 DEBUG   SenderThread:57348 [sender.py:send_request():249] send_request: poll_exit
2024-03-06 15:29:50,757 DEBUG   HandlerThread:57348 [handler.py:handle_request():141] handle_request: poll_exit
2024-03-06 15:29:50,758 DEBUG   SenderThread:57348 [sender.py:send_request():249] send_request: poll_exit
2024-03-06 15:29:50,867 DEBUG   HandlerThread:57348 [handler.py:handle_request():141] handle_request: poll_exit
2024-03-06 15:29:50,868 DEBUG   SenderThread:57348 [sender.py:send_request():249] send_request: poll_exit
2024-03-06 15:29:50,975 DEBUG   HandlerThread:57348 [handler.py:handle_request():141] handle_request: poll_exit
2024-03-06 15:29:50,976 DEBUG   SenderThread:57348 [sender.py:send_request():249] send_request: poll_exit
2024-03-06 15:29:50,995 ERROR   Thread-23 :57348 [internal_api.py:upload_file():1640] upload_file exception https://storage.googleapis.com/wandb-production.appspot.com/shahwaiz/UNet-DAS/1hl4cn36/conda-environment.yaml?Expires=1709796589&GoogleAccessId=gorilla-files-url-signer-man%40wandb-production.iam.gserviceaccount.com&Signature=e4PNO03CSgIECIWQbZOmQjiF8B6Fsic%2FKgIVpMY4rtewUbPMrXCuHEMo%2BA0Wty761fVpYrS7LodlL9rQHfJ5VLZaQeLMABxDpSZTsrEFwuH%2Fx3NsAFkIBenKQGy32KEqXqadMrFnOV5I5NY21BG%2FzuxkEWd%2Bfmh9%2BHCwZAOc9F6%2F%2BmpJuc2Wzi5mtq47FCux4tiAiYCohJyCI2UiutftKTZ%2Byv%2BzmkzAcn%2BBtsEY2WlzteIN7UY3m%2BlW4K8fuC5TXf4sI56J4ZmvutpVt69T%2Fc64G3KYaGnaz9DDBgjAZR119L00N8VVD3uVxcpYzG6ahXinO1F2jw6EkB8oev10qA%3D%3D: ('Connection aborted.', ConnectionResetError(10054, '远程主机强迫关闭了一个现有的连接。', None, 10054, None))
2024-03-06 15:29:50,995 ERROR   Thread-23 :57348 [internal_api.py:upload_file():1642] upload_file request headers: {'User-Agent': 'python-requests/2.31.0', 'Accept-Encoding': 'gzip, deflate', 'Accept': '*/*', 'Connection': 'keep-alive', 'Content-Length': '1983'}
2024-03-06 15:29:50,995 ERROR   Thread-23 :57348 [internal_api.py:upload_file():1644] upload_file response body: 
2024-03-06 15:29:51,081 DEBUG   HandlerThread:57348 [handler.py:handle_request():141] handle_request: poll_exit
2024-03-06 15:29:51,082 DEBUG   SenderThread:57348 [sender.py:send_request():249] send_request: poll_exit
2024-03-06 15:29:51,189 DEBUG   HandlerThread:57348 [handler.py:handle_request():141] handle_request: poll_exit
2024-03-06 15:29:51,190 DEBUG   SenderThread:57348 [sender.py:send_request():249] send_request: poll_exit
2024-03-06 15:29:51,298 DEBUG   HandlerThread:57348 [handler.py:handle_request():141] handle_request: poll_exit
2024-03-06 15:29:51,299 DEBUG   SenderThread:57348 [sender.py:send_request():249] send_request: poll_exit
2024-03-06 15:29:51,409 DEBUG   HandlerThread:57348 [handler.py:handle_request():141] handle_request: poll_exit
2024-03-06 15:29:51,410 DEBUG   SenderThread:57348 [sender.py:send_request():249] send_request: poll_exit
2024-03-06 15:29:51,515 DEBUG   HandlerThread:57348 [handler.py:handle_request():141] handle_request: poll_exit
2024-03-06 15:29:51,516 DEBUG   SenderThread:57348 [sender.py:send_request():249] send_request: poll_exit
2024-03-06 15:29:51,622 DEBUG   HandlerThread:57348 [handler.py:handle_request():141] handle_request: poll_exit
2024-03-06 15:29:51,623 DEBUG   SenderThread:57348 [sender.py:send_request():249] send_request: poll_exit
2024-03-06 15:29:51,731 DEBUG   HandlerThread:57348 [handler.py:handle_request():141] handle_request: poll_exit
2024-03-06 15:29:51,732 DEBUG   SenderThread:57348 [sender.py:send_request():249] send_request: poll_exit
2024-03-06 15:29:51,840 ERROR   Thread-26 :57348 [internal_api.py:upload_file():1640] upload_file exception https://storage.googleapis.com/wandb-production.appspot.com/shahwaiz/UNet-DAS/1hl4cn36/requirements.txt?Expires=1709796589&GoogleAccessId=gorilla-files-url-signer-man%40wandb-production.iam.gserviceaccount.com&Signature=TWM77nhE6PdyHkEs%2FdPIu0Z6PMu4QmRfQ3UuXP%2FUuAZ2kot4bUvryRPA05onYecXzJyqCwegqIQNPIMfUfLW8ITv1TfKaMCThBOXixXBJPPWLmybEdUKq1n2EY18yoDk%2Bp0cthglEuPHz7ytkM3XTiTRDKQEX0hD%2BsYYvDEPXyVQrXC67HBZHp3Ynr1Dfm6YuJ4E62EaknIDsMBMwLYAfRlREUKMsF8WlTZzt7g1ThbtM3Yj42zrx%2Fqd%2FFQEoNvACowUssKf1eTFJv9B8maKbMgM%2FeQkMKdUKm0dyu36H9s5GFuJmnKdD4kxIqNPjoPZwZNMw6WRqskNSNYuT0rkqA%3D%3D: ('Connection aborted.', ConnectionResetError(10054, '远程主机强迫关闭了一个现有的连接。', None, 10054, None))
2024-03-06 15:29:51,840 ERROR   Thread-26 :57348 [internal_api.py:upload_file():1642] upload_file request headers: {'User-Agent': 'python-requests/2.31.0', 'Accept-Encoding': 'gzip, deflate', 'Accept': '*/*', 'Connection': 'keep-alive', 'Content-Length': '1252'}
2024-03-06 15:29:51,840 ERROR   Thread-26 :57348 [internal_api.py:upload_file():1644] upload_file response body: 
2024-03-06 15:29:51,840 ERROR   Thread-26 :57348 [retry.py:__call__():126] Retry attempt failed:
Traceback (most recent call last):
  File "E:\Anaconda\envs\unet\lib\site-packages\urllib3\connectionpool.py", line 793, in urlopen
    response = self._make_request(
  File "E:\Anaconda\envs\unet\lib\site-packages\urllib3\connectionpool.py", line 491, in _make_request
    raise new_e
  File "E:\Anaconda\envs\unet\lib\site-packages\urllib3\connectionpool.py", line 467, in _make_request
    self._validate_conn(conn)
  File "E:\Anaconda\envs\unet\lib\site-packages\urllib3\connectionpool.py", line 1099, in _validate_conn
    conn.connect()
  File "E:\Anaconda\envs\unet\lib\site-packages\urllib3\connection.py", line 653, in connect
    sock_and_verified = _ssl_wrap_socket_and_match_hostname(
  File "E:\Anaconda\envs\unet\lib\site-packages\urllib3\connection.py", line 806, in _ssl_wrap_socket_and_match_hostname
    ssl_sock = ssl_wrap_socket(
  File "E:\Anaconda\envs\unet\lib\site-packages\urllib3\util\ssl_.py", line 465, in ssl_wrap_socket
    ssl_sock = _ssl_wrap_socket_impl(sock, context, tls_in_tls, server_hostname)
  File "E:\Anaconda\envs\unet\lib\site-packages\urllib3\util\ssl_.py", line 509, in _ssl_wrap_socket_impl
    return ssl_context.wrap_socket(sock, server_hostname=server_hostname)
  File "E:\Anaconda\envs\unet\lib\ssl.py", line 500, in wrap_socket
    return self.sslsocket_class._create(
  File "E:\Anaconda\envs\unet\lib\ssl.py", line 1073, in _create
    self.do_handshake()
  File "E:\Anaconda\envs\unet\lib\ssl.py", line 1342, in do_handshake
    self._sslobj.do_handshake()
ConnectionResetError: [WinError 10054] 远程主机强迫关闭了一个现有的连接。

During handling of the above exception, another exception occurred:

Traceback (most recent call last):
  File "E:\Anaconda\envs\unet\lib\site-packages\requests\adapters.py", line 486, in send
    resp = conn.urlopen(
  File "E:\Anaconda\envs\unet\lib\site-packages\urllib3\connectionpool.py", line 847, in urlopen
    retries = retries.increment(
  File "E:\Anaconda\envs\unet\lib\site-packages\urllib3\util\retry.py", line 470, in increment
    raise reraise(type(error), error, _stacktrace)
  File "E:\Anaconda\envs\unet\lib\site-packages\urllib3\util\util.py", line 38, in reraise
    raise value.with_traceback(tb)
  File "E:\Anaconda\envs\unet\lib\site-packages\urllib3\connectionpool.py", line 793, in urlopen
    response = self._make_request(
  File "E:\Anaconda\envs\unet\lib\site-packages\urllib3\connectionpool.py", line 491, in _make_request
    raise new_e
  File "E:\Anaconda\envs\unet\lib\site-packages\urllib3\connectionpool.py", line 467, in _make_request
    self._validate_conn(conn)
  File "E:\Anaconda\envs\unet\lib\site-packages\urllib3\connectionpool.py", line 1099, in _validate_conn
    conn.connect()
  File "E:\Anaconda\envs\unet\lib\site-packages\urllib3\connection.py", line 653, in connect
    sock_and_verified = _ssl_wrap_socket_and_match_hostname(
  File "E:\Anaconda\envs\unet\lib\site-packages\urllib3\connection.py", line 806, in _ssl_wrap_socket_and_match_hostname
    ssl_sock = ssl_wrap_socket(
  File "E:\Anaconda\envs\unet\lib\site-packages\urllib3\util\ssl_.py", line 465, in ssl_wrap_socket
    ssl_sock = _ssl_wrap_socket_impl(sock, context, tls_in_tls, server_hostname)
  File "E:\Anaconda\envs\unet\lib\site-packages\urllib3\util\ssl_.py", line 509, in _ssl_wrap_socket_impl
    return ssl_context.wrap_socket(sock, server_hostname=server_hostname)
  File "E:\Anaconda\envs\unet\lib\ssl.py", line 500, in wrap_socket
    return self.sslsocket_class._create(
  File "E:\Anaconda\envs\unet\lib\ssl.py", line 1073, in _create
    self.do_handshake()
  File "E:\Anaconda\envs\unet\lib\ssl.py", line 1342, in do_handshake
    self._sslobj.do_handshake()
urllib3.exceptions.ProtocolError: ('Connection aborted.', ConnectionResetError(10054, '远程主机强迫关闭了一个现有的连接。', None, 10054, None))

During handling of the above exception, another exception occurred:

Traceback (most recent call last):
  File "C:\Users\19086\AppData\Roaming\Python\Python38\site-packages\wandb\sdk\internal\internal_api.py", line 1637, in upload_file
    response = requests.put(url, data=progress, headers=extra_headers)
  File "E:\Anaconda\envs\unet\lib\site-packages\requests\api.py", line 130, in put
    return request("put", url, data=data, **kwargs)
  File "E:\Anaconda\envs\unet\lib\site-packages\requests\api.py", line 59, in request
    return session.request(method=method, url=url, **kwargs)
  File "E:\Anaconda\envs\unet\lib\site-packages\requests\sessions.py", line 589, in request
    resp = self.send(prep, **send_kwargs)
  File "E:\Anaconda\envs\unet\lib\site-packages\requests\sessions.py", line 703, in send
    r = adapter.send(request, **kwargs)
  File "E:\Anaconda\envs\unet\lib\site-packages\requests\adapters.py", line 501, in send
    raise ConnectionError(err, request=request)
requests.exceptions.ConnectionError: ('Connection aborted.', ConnectionResetError(10054, '远程主机强迫关闭了一个现有的连接。', None, 10054, None))

During handling of the above exception, another exception occurred:

Traceback (most recent call last):
  File "C:\Users\19086\AppData\Roaming\Python\Python38\site-packages\wandb\sdk\lib\retry.py", line 102, in __call__
    result = self._call_fn(*args, **kwargs)
  File "C:\Users\19086\AppData\Roaming\Python\Python38\site-packages\wandb\sdk\internal\internal_api.py", line 1653, in upload_file
    raise e.with_traceback(sys.exc_info()[2])
  File "C:\Users\19086\AppData\Roaming\Python\Python38\site-packages\wandb\sdk\internal\internal_api.py", line 1637, in upload_file
    response = requests.put(url, data=progress, headers=extra_headers)
  File "E:\Anaconda\envs\unet\lib\site-packages\requests\api.py", line 130, in put
    return request("put", url, data=data, **kwargs)
  File "E:\Anaconda\envs\unet\lib\site-packages\requests\api.py", line 59, in request
    return session.request(method=method, url=url, **kwargs)
  File "E:\Anaconda\envs\unet\lib\site-packages\requests\sessions.py", line 589, in request
    resp = self.send(prep, **send_kwargs)
  File "E:\Anaconda\envs\unet\lib\site-packages\requests\sessions.py", line 703, in send
    r = adapter.send(request, **kwargs)
  File "E:\Anaconda\envs\unet\lib\site-packages\requests\adapters.py", line 501, in send
    raise ConnectionError(err, request=request)
wandb.sdk.lib.retry.TransientError: None
2024-03-06 15:29:51,841 DEBUG   HandlerThread:57348 [handler.py:handle_request():141] handle_request: poll_exit
2024-03-06 15:29:51,844 DEBUG   SenderThread:57348 [sender.py:send_request():249] send_request: poll_exit
2024-03-06 15:29:51,948 DEBUG   HandlerThread:57348 [handler.py:handle_request():141] handle_request: poll_exit
2024-03-06 15:29:51,949 DEBUG   SenderThread:57348 [sender.py:send_request():249] send_request: poll_exit
2024-03-06 15:29:52,056 DEBUG   HandlerThread:57348 [handler.py:handle_request():141] handle_request: poll_exit
2024-03-06 15:29:52,057 DEBUG   SenderThread:57348 [sender.py:send_request():249] send_request: poll_exit
2024-03-06 15:29:52,162 DEBUG   HandlerThread:57348 [handler.py:handle_request():141] handle_request: poll_exit
2024-03-06 15:29:52,163 DEBUG   SenderThread:57348 [sender.py:send_request():249] send_request: poll_exit
2024-03-06 15:29:52,271 DEBUG   HandlerThread:57348 [handler.py:handle_request():141] handle_request: poll_exit
2024-03-06 15:29:52,272 DEBUG   SenderThread:57348 [sender.py:send_request():249] send_request: poll_exit
2024-03-06 15:29:52,380 DEBUG   HandlerThread:57348 [handler.py:handle_request():141] handle_request: poll_exit
2024-03-06 15:29:52,381 DEBUG   SenderThread:57348 [sender.py:send_request():249] send_request: poll_exit
2024-03-06 15:29:52,487 DEBUG   HandlerThread:57348 [handler.py:handle_request():141] handle_request: poll_exit
2024-03-06 15:29:52,488 DEBUG   SenderThread:57348 [sender.py:send_request():249] send_request: poll_exit
2024-03-06 15:29:52,593 DEBUG   HandlerThread:57348 [handler.py:handle_request():141] handle_request: poll_exit
2024-03-06 15:29:52,594 DEBUG   SenderThread:57348 [sender.py:send_request():249] send_request: poll_exit
2024-03-06 15:29:52,701 DEBUG   HandlerThread:57348 [handler.py:handle_request():141] handle_request: poll_exit
2024-03-06 15:29:52,702 DEBUG   SenderThread:57348 [sender.py:send_request():249] send_request: poll_exit
2024-03-06 15:29:52,756 INFO    Thread-24 :57348 [upload_job.py:push():132] Uploaded file .\wandb\run-20240306_152917-1hl4cn36\files\config.yaml
2024-03-06 15:29:52,809 DEBUG   HandlerThread:57348 [handler.py:handle_request():141] handle_request: poll_exit
2024-03-06 15:29:52,810 DEBUG   SenderThread:57348 [sender.py:send_request():249] send_request: poll_exit
2024-03-06 15:29:52,917 DEBUG   HandlerThread:57348 [handler.py:handle_request():141] handle_request: poll_exit
2024-03-06 15:29:52,918 DEBUG   SenderThread:57348 [sender.py:send_request():249] send_request: poll_exit
2024-03-06 15:29:53,024 DEBUG   HandlerThread:57348 [handler.py:handle_request():141] handle_request: poll_exit
2024-03-06 15:29:53,025 DEBUG   SenderThread:57348 [sender.py:send_request():249] send_request: poll_exit
2024-03-06 15:29:53,131 DEBUG   HandlerThread:57348 [handler.py:handle_request():141] handle_request: poll_exit
2024-03-06 15:29:53,132 DEBUG   SenderThread:57348 [sender.py:send_request():249] send_request: poll_exit
2024-03-06 15:29:53,240 DEBUG   HandlerThread:57348 [handler.py:handle_request():141] handle_request: poll_exit
2024-03-06 15:29:53,241 DEBUG   SenderThread:57348 [sender.py:send_request():249] send_request: poll_exit
2024-03-06 15:29:53,347 DEBUG   HandlerThread:57348 [handler.py:handle_request():141] handle_request: poll_exit
2024-03-06 15:29:53,348 DEBUG   SenderThread:57348 [sender.py:send_request():249] send_request: poll_exit
2024-03-06 15:29:53,359 INFO    Thread-23 :57348 [upload_job.py:push():132] Uploaded file .\wandb\run-20240306_152917-1hl4cn36\files\conda-environment.yaml
2024-03-06 15:29:53,456 DEBUG   HandlerThread:57348 [handler.py:handle_request():141] handle_request: poll_exit
2024-03-06 15:29:53,457 DEBUG   SenderThread:57348 [sender.py:send_request():249] send_request: poll_exit
2024-03-06 15:29:53,564 DEBUG   HandlerThread:57348 [handler.py:handle_request():141] handle_request: poll_exit
2024-03-06 15:29:53,565 DEBUG   SenderThread:57348 [sender.py:send_request():249] send_request: poll_exit
2024-03-06 15:29:53,573 ERROR   Thread-27 :57348 [internal_api.py:upload_file():1640] upload_file exception https://storage.googleapis.com/wandb-production.appspot.com/shahwaiz/UNet-DAS/1hl4cn36/wandb-summary.json?Expires=1709796593&GoogleAccessId=gorilla-files-url-signer-man%40wandb-production.iam.gserviceaccount.com&Signature=CwkEqLSLdyS9bQWY3QTUnnbnPQdc9108SaWLQVvS9PXt3jfh25%2FGAE3cuSV2rxUZCnt4kYWt0sL41VgoTrJKW9wKhjlkvk%2FDYtbaeFk5DZE0Vn3rT7QSqQsOVrnPveJO%2F%2FyhibU8bv4BN%2FdnmFIf3p%2F3TiUw0GBou74Uth0hlJXZlNSbYvMYPX9qisEgXJoQ3x0Azs9YrvJL8zMx%2FpTvQE70J8jKLXDer2yAUIYoKfrQetjaH0%2F1myRsgmqMCWw36ccPwjLQTexUyB1Z0%2FEBOGKYjITChVKZiZxgJuZzKkFb7Dz8EIeCO6lZu4SKYihKTc%2FnsCqbvUcyWhtdN5kN8g%3D%3D: ('Connection aborted.', ConnectionResetError(10054, '远程主机强迫关闭了一个现有的连接。', None, 10054, None))
2024-03-06 15:29:53,573 ERROR   Thread-27 :57348 [internal_api.py:upload_file():1642] upload_file request headers: {'User-Agent': 'python-requests/2.31.0', 'Accept-Encoding': 'gzip, deflate', 'Accept': '*/*', 'Connection': 'keep-alive', 'Content-Length': '27'}
2024-03-06 15:29:53,573 ERROR   Thread-27 :57348 [internal_api.py:upload_file():1644] upload_file response body: 
2024-03-06 15:29:53,673 DEBUG   HandlerThread:57348 [handler.py:handle_request():141] handle_request: poll_exit
2024-03-06 15:29:53,674 DEBUG   SenderThread:57348 [sender.py:send_request():249] send_request: poll_exit
2024-03-06 15:29:53,783 DEBUG   HandlerThread:57348 [handler.py:handle_request():141] handle_request: poll_exit
2024-03-06 15:29:53,784 DEBUG   SenderThread:57348 [sender.py:send_request():249] send_request: poll_exit
2024-03-06 15:29:53,892 DEBUG   HandlerThread:57348 [handler.py:handle_request():141] handle_request: poll_exit
2024-03-06 15:29:53,893 DEBUG   SenderThread:57348 [sender.py:send_request():249] send_request: poll_exit
2024-03-06 15:29:54,000 DEBUG   HandlerThread:57348 [handler.py:handle_request():141] handle_request: poll_exit
2024-03-06 15:29:54,001 DEBUG   SenderThread:57348 [sender.py:send_request():249] send_request: poll_exit
2024-03-06 15:29:54,108 DEBUG   HandlerThread:57348 [handler.py:handle_request():141] handle_request: poll_exit
2024-03-06 15:29:54,109 DEBUG   SenderThread:57348 [sender.py:send_request():249] send_request: poll_exit
2024-03-06 15:29:54,217 DEBUG   HandlerThread:57348 [handler.py:handle_request():141] handle_request: poll_exit
2024-03-06 15:29:54,218 DEBUG   SenderThread:57348 [sender.py:send_request():249] send_request: poll_exit
2024-03-06 15:29:54,328 DEBUG   HandlerThread:57348 [handler.py:handle_request():141] handle_request: poll_exit
2024-03-06 15:29:54,329 DEBUG   SenderThread:57348 [sender.py:send_request():249] send_request: poll_exit
2024-03-06 15:29:54,437 DEBUG   HandlerThread:57348 [handler.py:handle_request():141] handle_request: poll_exit
2024-03-06 15:29:54,438 DEBUG   SenderThread:57348 [sender.py:send_request():249] send_request: poll_exit
2024-03-06 15:29:54,445 ERROR   Thread-26 :57348 [internal_api.py:upload_file():1640] upload_file exception https://storage.googleapis.com/wandb-production.appspot.com/shahwaiz/UNet-DAS/1hl4cn36/requirements.txt?Expires=1709796589&GoogleAccessId=gorilla-files-url-signer-man%40wandb-production.iam.gserviceaccount.com&Signature=TWM77nhE6PdyHkEs%2FdPIu0Z6PMu4QmRfQ3UuXP%2FUuAZ2kot4bUvryRPA05onYecXzJyqCwegqIQNPIMfUfLW8ITv1TfKaMCThBOXixXBJPPWLmybEdUKq1n2EY18yoDk%2Bp0cthglEuPHz7ytkM3XTiTRDKQEX0hD%2BsYYvDEPXyVQrXC67HBZHp3Ynr1Dfm6YuJ4E62EaknIDsMBMwLYAfRlREUKMsF8WlTZzt7g1ThbtM3Yj42zrx%2Fqd%2FFQEoNvACowUssKf1eTFJv9B8maKbMgM%2FeQkMKdUKm0dyu36H9s5GFuJmnKdD4kxIqNPjoPZwZNMw6WRqskNSNYuT0rkqA%3D%3D: ('Connection aborted.', ConnectionResetError(10054, '远程主机强迫关闭了一个现有的连接。', None, 10054, None))
2024-03-06 15:29:54,445 ERROR   Thread-26 :57348 [internal_api.py:upload_file():1642] upload_file request headers: {'User-Agent': 'python-requests/2.31.0', 'Accept-Encoding': 'gzip, deflate', 'Accept': '*/*', 'Connection': 'keep-alive', 'Content-Length': '1252'}
2024-03-06 15:29:54,446 ERROR   Thread-26 :57348 [internal_api.py:upload_file():1644] upload_file response body: 
2024-03-06 15:29:54,545 DEBUG   HandlerThread:57348 [handler.py:handle_request():141] handle_request: poll_exit
2024-03-06 15:29:54,546 DEBUG   SenderThread:57348 [sender.py:send_request():249] send_request: poll_exit
2024-03-06 15:29:54,655 DEBUG   HandlerThread:57348 [handler.py:handle_request():141] handle_request: poll_exit
2024-03-06 15:29:54,656 DEBUG   SenderThread:57348 [sender.py:send_request():249] send_request: poll_exit
2024-03-06 15:29:54,684 WARNING MainThread:57348 [internal.py:wandb_internal():153] Internal process interrupt: 1
2024-03-06 15:29:55,324 ERROR   Thread-27 :57348 [internal_api.py:upload_file():1640] upload_file exception https://storage.googleapis.com/wandb-production.appspot.com/shahwaiz/UNet-DAS/1hl4cn36/wandb-summary.json?Expires=1709796593&GoogleAccessId=gorilla-files-url-signer-man%40wandb-production.iam.gserviceaccount.com&Signature=CwkEqLSLdyS9bQWY3QTUnnbnPQdc9108SaWLQVvS9PXt3jfh25%2FGAE3cuSV2rxUZCnt4kYWt0sL41VgoTrJKW9wKhjlkvk%2FDYtbaeFk5DZE0Vn3rT7QSqQsOVrnPveJO%2F%2FyhibU8bv4BN%2FdnmFIf3p%2F3TiUw0GBou74Uth0hlJXZlNSbYvMYPX9qisEgXJoQ3x0Azs9YrvJL8zMx%2FpTvQE70J8jKLXDer2yAUIYoKfrQetjaH0%2F1myRsgmqMCWw36ccPwjLQTexUyB1Z0%2FEBOGKYjITChVKZiZxgJuZzKkFb7Dz8EIeCO6lZu4SKYihKTc%2FnsCqbvUcyWhtdN5kN8g%3D%3D: ('Connection aborted.', ConnectionResetError(10054, '远程主机强迫关闭了一个现有的连接。', None, 10054, None))
2024-03-06 15:29:55,324 ERROR   Thread-27 :57348 [internal_api.py:upload_file():1642] upload_file request headers: {'User-Agent': 'python-requests/2.31.0', 'Accept-Encoding': 'gzip, deflate', 'Accept': '*/*', 'Connection': 'keep-alive', 'Content-Length': '27'}
2024-03-06 15:29:55,324 ERROR   Thread-27 :57348 [internal_api.py:upload_file():1644] upload_file response body: 
2024-03-06 15:29:55,324 ERROR   Thread-27 :57348 [retry.py:__call__():126] Retry attempt failed:
Traceback (most recent call last):
  File "E:\Anaconda\envs\unet\lib\site-packages\urllib3\connectionpool.py", line 793, in urlopen
    response = self._make_request(
  File "E:\Anaconda\envs\unet\lib\site-packages\urllib3\connectionpool.py", line 491, in _make_request
    raise new_e
  File "E:\Anaconda\envs\unet\lib\site-packages\urllib3\connectionpool.py", line 467, in _make_request
    self._validate_conn(conn)
  File "E:\Anaconda\envs\unet\lib\site-packages\urllib3\connectionpool.py", line 1099, in _validate_conn
    conn.connect()
  File "E:\Anaconda\envs\unet\lib\site-packages\urllib3\connection.py", line 653, in connect
    sock_and_verified = _ssl_wrap_socket_and_match_hostname(
  File "E:\Anaconda\envs\unet\lib\site-packages\urllib3\connection.py", line 806, in _ssl_wrap_socket_and_match_hostname
    ssl_sock = ssl_wrap_socket(
  File "E:\Anaconda\envs\unet\lib\site-packages\urllib3\util\ssl_.py", line 465, in ssl_wrap_socket
    ssl_sock = _ssl_wrap_socket_impl(sock, context, tls_in_tls, server_hostname)
  File "E:\Anaconda\envs\unet\lib\site-packages\urllib3\util\ssl_.py", line 509, in _ssl_wrap_socket_impl
    return ssl_context.wrap_socket(sock, server_hostname=server_hostname)
  File "E:\Anaconda\envs\unet\lib\ssl.py", line 500, in wrap_socket
    return self.sslsocket_class._create(
  File "E:\Anaconda\envs\unet\lib\ssl.py", line 1073, in _create
    self.do_handshake()
  File "E:\Anaconda\envs\unet\lib\ssl.py", line 1342, in do_handshake
    self._sslobj.do_handshake()
ConnectionResetError: [WinError 10054] 远程主机强迫关闭了一个现有的连接。

During handling of the above exception, another exception occurred:

Traceback (most recent call last):
  File "E:\Anaconda\envs\unet\lib\site-packages\requests\adapters.py", line 486, in send
    resp = conn.urlopen(
  File "E:\Anaconda\envs\unet\lib\site-packages\urllib3\connectionpool.py", line 847, in urlopen
    retries = retries.increment(
  File "E:\Anaconda\envs\unet\lib\site-packages\urllib3\util\retry.py", line 470, in increment
    raise reraise(type(error), error, _stacktrace)
  File "E:\Anaconda\envs\unet\lib\site-packages\urllib3\util\util.py", line 38, in reraise
    raise value.with_traceback(tb)
  File "E:\Anaconda\envs\unet\lib\site-packages\urllib3\connectionpool.py", line 793, in urlopen
    response = self._make_request(
  File "E:\Anaconda\envs\unet\lib\site-packages\urllib3\connectionpool.py", line 491, in _make_request
    raise new_e
  File "E:\Anaconda\envs\unet\lib\site-packages\urllib3\connectionpool.py", line 467, in _make_request
    self._validate_conn(conn)
  File "E:\Anaconda\envs\unet\lib\site-packages\urllib3\connectionpool.py", line 1099, in _validate_conn
    conn.connect()
  File "E:\Anaconda\envs\unet\lib\site-packages\urllib3\connection.py", line 653, in connect
    sock_and_verified = _ssl_wrap_socket_and_match_hostname(
  File "E:\Anaconda\envs\unet\lib\site-packages\urllib3\connection.py", line 806, in _ssl_wrap_socket_and_match_hostname
    ssl_sock = ssl_wrap_socket(
  File "E:\Anaconda\envs\unet\lib\site-packages\urllib3\util\ssl_.py", line 465, in ssl_wrap_socket
    ssl_sock = _ssl_wrap_socket_impl(sock, context, tls_in_tls, server_hostname)
  File "E:\Anaconda\envs\unet\lib\site-packages\urllib3\util\ssl_.py", line 509, in _ssl_wrap_socket_impl
    return ssl_context.wrap_socket(sock, server_hostname=server_hostname)
  File "E:\Anaconda\envs\unet\lib\ssl.py", line 500, in wrap_socket
    return self.sslsocket_class._create(
  File "E:\Anaconda\envs\unet\lib\ssl.py", line 1073, in _create
    self.do_handshake()
  File "E:\Anaconda\envs\unet\lib\ssl.py", line 1342, in do_handshake
    self._sslobj.do_handshake()
urllib3.exceptions.ProtocolError: ('Connection aborted.', ConnectionResetError(10054, '远程主机强迫关闭了一个现有的连接。', None, 10054, None))

During handling of the above exception, another exception occurred:

Traceback (most recent call last):
  File "C:\Users\19086\AppData\Roaming\Python\Python38\site-packages\wandb\sdk\internal\internal_api.py", line 1637, in upload_file
    response = requests.put(url, data=progress, headers=extra_headers)
  File "E:\Anaconda\envs\unet\lib\site-packages\requests\api.py", line 130, in put
    return request("put", url, data=data, **kwargs)
  File "E:\Anaconda\envs\unet\lib\site-packages\requests\api.py", line 59, in request
    return session.request(method=method, url=url, **kwargs)
  File "E:\Anaconda\envs\unet\lib\site-packages\requests\sessions.py", line 589, in request
    resp = self.send(prep, **send_kwargs)
  File "E:\Anaconda\envs\unet\lib\site-packages\requests\sessions.py", line 703, in send
    r = adapter.send(request, **kwargs)
  File "E:\Anaconda\envs\unet\lib\site-packages\requests\adapters.py", line 501, in send
    raise ConnectionError(err, request=request)
requests.exceptions.ConnectionError: ('Connection aborted.', ConnectionResetError(10054, '远程主机强迫关闭了一个现有的连接。', None, 10054, None))

During handling of the above exception, another exception occurred:

Traceback (most recent call last):
  File "C:\Users\19086\AppData\Roaming\Python\Python38\site-packages\wandb\sdk\lib\retry.py", line 102, in __call__
    result = self._call_fn(*args, **kwargs)
  File "C:\Users\19086\AppData\Roaming\Python\Python38\site-packages\wandb\sdk\internal\internal_api.py", line 1653, in upload_file
    raise e.with_traceback(sys.exc_info()[2])
  File "C:\Users\19086\AppData\Roaming\Python\Python38\site-packages\wandb\sdk\internal\internal_api.py", line 1637, in upload_file
    response = requests.put(url, data=progress, headers=extra_headers)
  File "E:\Anaconda\envs\unet\lib\site-packages\requests\api.py", line 130, in put
    return request("put", url, data=data, **kwargs)
  File "E:\Anaconda\envs\unet\lib\site-packages\requests\api.py", line 59, in request
    return session.request(method=method, url=url, **kwargs)
  File "E:\Anaconda\envs\unet\lib\site-packages\requests\sessions.py", line 589, in request
    resp = self.send(prep, **send_kwargs)
  File "E:\Anaconda\envs\unet\lib\site-packages\requests\sessions.py", line 703, in send
    r = adapter.send(request, **kwargs)
  File "E:\Anaconda\envs\unet\lib\site-packages\requests\adapters.py", line 501, in send
    raise ConnectionError(err, request=request)
wandb.sdk.lib.retry.TransientError: None
2024-03-06 15:29:57,910 ERROR   Thread-27 :57348 [internal_api.py:upload_file():1640] upload_file exception https://storage.googleapis.com/wandb-production.appspot.com/shahwaiz/UNet-DAS/1hl4cn36/wandb-summary.json?Expires=1709796593&GoogleAccessId=gorilla-files-url-signer-man%40wandb-production.iam.gserviceaccount.com&Signature=CwkEqLSLdyS9bQWY3QTUnnbnPQdc9108SaWLQVvS9PXt3jfh25%2FGAE3cuSV2rxUZCnt4kYWt0sL41VgoTrJKW9wKhjlkvk%2FDYtbaeFk5DZE0Vn3rT7QSqQsOVrnPveJO%2F%2FyhibU8bv4BN%2FdnmFIf3p%2F3TiUw0GBou74Uth0hlJXZlNSbYvMYPX9qisEgXJoQ3x0Azs9YrvJL8zMx%2FpTvQE70J8jKLXDer2yAUIYoKfrQetjaH0%2F1myRsgmqMCWw36ccPwjLQTexUyB1Z0%2FEBOGKYjITChVKZiZxgJuZzKkFb7Dz8EIeCO6lZu4SKYihKTc%2FnsCqbvUcyWhtdN5kN8g%3D%3D: ('Connection aborted.', ConnectionResetError(10054, '远程主机强迫关闭了一个现有的连接。', None, 10054, None))
2024-03-06 15:29:57,910 ERROR   Thread-27 :57348 [internal_api.py:upload_file():1642] upload_file request headers: {'User-Agent': 'python-requests/2.31.0', 'Accept-Encoding': 'gzip, deflate', 'Accept': '*/*', 'Connection': 'keep-alive', 'Content-Length': '27'}
2024-03-06 15:29:57,910 ERROR   Thread-27 :57348 [internal_api.py:upload_file():1644] upload_file response body: 
2024-03-06 15:29:59,287 ERROR   Thread-26 :57348 [internal_api.py:upload_file():1640] upload_file exception https://storage.googleapis.com/wandb-production.appspot.com/shahwaiz/UNet-DAS/1hl4cn36/requirements.txt?Expires=1709796589&GoogleAccessId=gorilla-files-url-signer-man%40wandb-production.iam.gserviceaccount.com&Signature=TWM77nhE6PdyHkEs%2FdPIu0Z6PMu4QmRfQ3UuXP%2FUuAZ2kot4bUvryRPA05onYecXzJyqCwegqIQNPIMfUfLW8ITv1TfKaMCThBOXixXBJPPWLmybEdUKq1n2EY18yoDk%2Bp0cthglEuPHz7ytkM3XTiTRDKQEX0hD%2BsYYvDEPXyVQrXC67HBZHp3Ynr1Dfm6YuJ4E62EaknIDsMBMwLYAfRlREUKMsF8WlTZzt7g1ThbtM3Yj42zrx%2Fqd%2FFQEoNvACowUssKf1eTFJv9B8maKbMgM%2FeQkMKdUKm0dyu36H9s5GFuJmnKdD4kxIqNPjoPZwZNMw6WRqskNSNYuT0rkqA%3D%3D: ('Connection aborted.', ConnectionResetError(10054, '远程主机强迫关闭了一个现有的连接。', None, 10054, None))
2024-03-06 15:29:59,287 ERROR   Thread-26 :57348 [internal_api.py:upload_file():1642] upload_file request headers: {'User-Agent': 'python-requests/2.31.0', 'Accept-Encoding': 'gzip, deflate', 'Accept': '*/*', 'Connection': 'keep-alive', 'Content-Length': '1252'}
2024-03-06 15:29:59,288 ERROR   Thread-26 :57348 [internal_api.py:upload_file():1644] upload_file response body: 
2024-03-06 15:30:01,749 WARNING MainThread:57348 [internal.py:is_dead():387] Internal process exiting, parent pid 61400 disappeared
2024-03-06 15:30:01,749 ERROR   MainThread:57348 [internal.py:wandb_internal():149] Internal process shutdown.
2024-03-06 15:30:01,838 INFO    WriterThread:57348 [datastore.py:close():279] close: .\wandb\run-20240306_152917-1hl4cn36\run-1hl4cn36.wandb
2024-03-06 15:30:02,618 ERROR   Thread-27 :57348 [internal_api.py:upload_file():1640] upload_file exception https://storage.googleapis.com/wandb-production.appspot.com/shahwaiz/UNet-DAS/1hl4cn36/wandb-summary.json?Expires=1709796593&GoogleAccessId=gorilla-files-url-signer-man%40wandb-production.iam.gserviceaccount.com&Signature=CwkEqLSLdyS9bQWY3QTUnnbnPQdc9108SaWLQVvS9PXt3jfh25%2FGAE3cuSV2rxUZCnt4kYWt0sL41VgoTrJKW9wKhjlkvk%2FDYtbaeFk5DZE0Vn3rT7QSqQsOVrnPveJO%2F%2FyhibU8bv4BN%2FdnmFIf3p%2F3TiUw0GBou74Uth0hlJXZlNSbYvMYPX9qisEgXJoQ3x0Azs9YrvJL8zMx%2FpTvQE70J8jKLXDer2yAUIYoKfrQetjaH0%2F1myRsgmqMCWw36ccPwjLQTexUyB1Z0%2FEBOGKYjITChVKZiZxgJuZzKkFb7Dz8EIeCO6lZu4SKYihKTc%2FnsCqbvUcyWhtdN5kN8g%3D%3D: ('Connection aborted.', ConnectionResetError(10054, '远程主机强迫关闭了一个现有的连接。', None, 10054, None))
2024-03-06 15:30:02,619 ERROR   Thread-27 :57348 [internal_api.py:upload_file():1642] upload_file request headers: {'User-Agent': 'python-requests/2.31.0', 'Accept-Encoding': 'gzip, deflate', 'Accept': '*/*', 'Connection': 'keep-alive', 'Content-Length': '27'}
2024-03-06 15:30:02,619 ERROR   Thread-27 :57348 [internal_api.py:upload_file():1644] upload_file response body: 
2024-03-06 15:30:02,719 INFO    SenderThread:57348 [sender.py:finish():1111] shutting down sender
2024-03-06 15:30:02,719 INFO    SenderThread:57348 [file_pusher.py:finish():145] shutting down file pusher
2024-03-06 15:30:02,719 INFO    HandlerThread:57348 [handler.py:finish():806] shutting down handler
2024-03-06 15:30:02,719 INFO    SenderThread:57348 [file_pusher.py:join():150] waiting for file pusher
2024-03-06 15:30:07,370 ERROR   Thread-22 :57348 [internal_api.py:upload_file():1640] upload_file exception https://storage.googleapis.com/wandb-production.appspot.com/shahwaiz/UNet-DAS/1hl4cn36/wandb-metadata.json?Expires=1709796569&GoogleAccessId=gorilla-files-url-signer-man%40wandb-production.iam.gserviceaccount.com&Signature=ZOjft9fu%2Bu1O4J0uXcPelW8mhQdVFFpO4cLhRnfytHRuf8RTAhMmZQsLOJAuYsL%2B3L8RbpoDVjYBhIONNE39EG6cJSI9VyRNxe7Ax1d3E2Hn2sgYKWxrCr3CJyhHJDW0wwtXk6MSDkmqG8QPQgbCzdGI0wS5QVuo8N6SR%2F9EjwT77D4SOE4CtNxRfDC%2Fsr3GzNNkWqBJhB8KCLgjDUo1mEDAYCmdSSFnbmnEuGZ18kru1a4wzQjfhjlJ2bZJD3lYwrAaij1ssbgU0ilKrf9He4aJuouPz%2BRyLCJRSvVNnslV4syKF6IyBELq9en4gqTDFdGkNKMc2N5dCi91%2B8QFyw%3D%3D: ('Connection aborted.', ConnectionResetError(10054, '远程主机强迫关闭了一个现有的连接。', None, 10054, None))
2024-03-06 15:30:07,370 ERROR   Thread-22 :57348 [internal_api.py:upload_file():1642] upload_file request headers: {'User-Agent': 'python-requests/2.31.0', 'Accept-Encoding': 'gzip, deflate', 'Accept': '*/*', 'Connection': 'keep-alive', 'Content-Length': '766'}
2024-03-06 15:30:07,370 ERROR   Thread-22 :57348 [internal_api.py:upload_file():1644] upload_file response body: 
2024-03-06 15:30:08,866 ERROR   Thread-26 :57348 [internal_api.py:upload_file():1640] upload_file exception https://storage.googleapis.com/wandb-production.appspot.com/shahwaiz/UNet-DAS/1hl4cn36/requirements.txt?Expires=1709796589&GoogleAccessId=gorilla-files-url-signer-man%40wandb-production.iam.gserviceaccount.com&Signature=TWM77nhE6PdyHkEs%2FdPIu0Z6PMu4QmRfQ3UuXP%2FUuAZ2kot4bUvryRPA05onYecXzJyqCwegqIQNPIMfUfLW8ITv1TfKaMCThBOXixXBJPPWLmybEdUKq1n2EY18yoDk%2Bp0cthglEuPHz7ytkM3XTiTRDKQEX0hD%2BsYYvDEPXyVQrXC67HBZHp3Ynr1Dfm6YuJ4E62EaknIDsMBMwLYAfRlREUKMsF8WlTZzt7g1ThbtM3Yj42zrx%2Fqd%2FFQEoNvACowUssKf1eTFJv9B8maKbMgM%2FeQkMKdUKm0dyu36H9s5GFuJmnKdD4kxIqNPjoPZwZNMw6WRqskNSNYuT0rkqA%3D%3D: ('Connection aborted.', ConnectionResetError(10054, '远程主机强迫关闭了一个现有的连接。', None, 10054, None))
2024-03-06 15:30:08,866 ERROR   Thread-26 :57348 [internal_api.py:upload_file():1642] upload_file request headers: {'User-Agent': 'python-requests/2.31.0', 'Accept-Encoding': 'gzip, deflate', 'Accept': '*/*', 'Connection': 'keep-alive', 'Content-Length': '1252'}
2024-03-06 15:30:08,866 ERROR   Thread-26 :57348 [internal_api.py:upload_file():1644] upload_file response body: 
2024-03-06 15:30:11,450 ERROR   Thread-27 :57348 [internal_api.py:upload_file():1640] upload_file exception https://storage.googleapis.com/wandb-production.appspot.com/shahwaiz/UNet-DAS/1hl4cn36/wandb-summary.json?Expires=1709796593&GoogleAccessId=gorilla-files-url-signer-man%40wandb-production.iam.gserviceaccount.com&Signature=CwkEqLSLdyS9bQWY3QTUnnbnPQdc9108SaWLQVvS9PXt3jfh25%2FGAE3cuSV2rxUZCnt4kYWt0sL41VgoTrJKW9wKhjlkvk%2FDYtbaeFk5DZE0Vn3rT7QSqQsOVrnPveJO%2F%2FyhibU8bv4BN%2FdnmFIf3p%2F3TiUw0GBou74Uth0hlJXZlNSbYvMYPX9qisEgXJoQ3x0Azs9YrvJL8zMx%2FpTvQE70J8jKLXDer2yAUIYoKfrQetjaH0%2F1myRsgmqMCWw36ccPwjLQTexUyB1Z0%2FEBOGKYjITChVKZiZxgJuZzKkFb7Dz8EIeCO6lZu4SKYihKTc%2FnsCqbvUcyWhtdN5kN8g%3D%3D: ('Connection aborted.', ConnectionResetError(10054, '远程主机强迫关闭了一个现有的连接。', None, 10054, None))
2024-03-06 15:30:11,450 ERROR   Thread-27 :57348 [internal_api.py:upload_file():1642] upload_file request headers: {'User-Agent': 'python-requests/2.31.0', 'Accept-Encoding': 'gzip, deflate', 'Accept': '*/*', 'Connection': 'keep-alive', 'Content-Length': '27'}
2024-03-06 15:30:11,450 ERROR   Thread-27 :57348 [internal_api.py:upload_file():1644] upload_file response body: 
2024-03-06 15:30:27,580 ERROR   Thread-26 :57348 [internal_api.py:upload_file():1640] upload_file exception https://storage.googleapis.com/wandb-production.appspot.com/shahwaiz/UNet-DAS/1hl4cn36/requirements.txt?Expires=1709796589&GoogleAccessId=gorilla-files-url-signer-man%40wandb-production.iam.gserviceaccount.com&Signature=TWM77nhE6PdyHkEs%2FdPIu0Z6PMu4QmRfQ3UuXP%2FUuAZ2kot4bUvryRPA05onYecXzJyqCwegqIQNPIMfUfLW8ITv1TfKaMCThBOXixXBJPPWLmybEdUKq1n2EY18yoDk%2Bp0cthglEuPHz7ytkM3XTiTRDKQEX0hD%2BsYYvDEPXyVQrXC67HBZHp3Ynr1Dfm6YuJ4E62EaknIDsMBMwLYAfRlREUKMsF8WlTZzt7g1ThbtM3Yj42zrx%2Fqd%2FFQEoNvACowUssKf1eTFJv9B8maKbMgM%2FeQkMKdUKm0dyu36H9s5GFuJmnKdD4kxIqNPjoPZwZNMw6WRqskNSNYuT0rkqA%3D%3D: ('Connection aborted.', ConnectionResetError(10054, '远程主机强迫关闭了一个现有的连接。', None, 10054, None))
2024-03-06 15:30:27,580 ERROR   Thread-26 :57348 [internal_api.py:upload_file():1642] upload_file request headers: {'User-Agent': 'python-requests/2.31.0', 'Accept-Encoding': 'gzip, deflate', 'Accept': '*/*', 'Connection': 'keep-alive', 'Content-Length': '1252'}
2024-03-06 15:30:27,580 ERROR   Thread-26 :57348 [internal_api.py:upload_file():1644] upload_file response body: 
2024-03-06 15:30:30,536 ERROR   Thread-27 :57348 [internal_api.py:upload_file():1640] upload_file exception https://storage.googleapis.com/wandb-production.appspot.com/shahwaiz/UNet-DAS/1hl4cn36/wandb-summary.json?Expires=1709796593&GoogleAccessId=gorilla-files-url-signer-man%40wandb-production.iam.gserviceaccount.com&Signature=CwkEqLSLdyS9bQWY3QTUnnbnPQdc9108SaWLQVvS9PXt3jfh25%2FGAE3cuSV2rxUZCnt4kYWt0sL41VgoTrJKW9wKhjlkvk%2FDYtbaeFk5DZE0Vn3rT7QSqQsOVrnPveJO%2F%2FyhibU8bv4BN%2FdnmFIf3p%2F3TiUw0GBou74Uth0hlJXZlNSbYvMYPX9qisEgXJoQ3x0Azs9YrvJL8zMx%2FpTvQE70J8jKLXDer2yAUIYoKfrQetjaH0%2F1myRsgmqMCWw36ccPwjLQTexUyB1Z0%2FEBOGKYjITChVKZiZxgJuZzKkFb7Dz8EIeCO6lZu4SKYihKTc%2FnsCqbvUcyWhtdN5kN8g%3D%3D: ('Connection aborted.', ConnectionResetError(10054, '远程主机强迫关闭了一个现有的连接。', None, 10054, None))
2024-03-06 15:30:30,537 ERROR   Thread-27 :57348 [internal_api.py:upload_file():1642] upload_file request headers: {'User-Agent': 'python-requests/2.31.0', 'Accept-Encoding': 'gzip, deflate', 'Accept': '*/*', 'Connection': 'keep-alive', 'Content-Length': '27'}
2024-03-06 15:30:30,537 ERROR   Thread-27 :57348 [internal_api.py:upload_file():1644] upload_file response body: 
2024-03-06 15:30:44,264 ERROR   Thread-22 :57348 [internal_api.py:upload_file():1640] upload_file exception https://storage.googleapis.com/wandb-production.appspot.com/shahwaiz/UNet-DAS/1hl4cn36/wandb-metadata.json?Expires=1709796569&GoogleAccessId=gorilla-files-url-signer-man%40wandb-production.iam.gserviceaccount.com&Signature=ZOjft9fu%2Bu1O4J0uXcPelW8mhQdVFFpO4cLhRnfytHRuf8RTAhMmZQsLOJAuYsL%2B3L8RbpoDVjYBhIONNE39EG6cJSI9VyRNxe7Ax1d3E2Hn2sgYKWxrCr3CJyhHJDW0wwtXk6MSDkmqG8QPQgbCzdGI0wS5QVuo8N6SR%2F9EjwT77D4SOE4CtNxRfDC%2Fsr3GzNNkWqBJhB8KCLgjDUo1mEDAYCmdSSFnbmnEuGZ18kru1a4wzQjfhjlJ2bZJD3lYwrAaij1ssbgU0ilKrf9He4aJuouPz%2BRyLCJRSvVNnslV4syKF6IyBELq9en4gqTDFdGkNKMc2N5dCi91%2B8QFyw%3D%3D: ('Connection aborted.', ConnectionResetError(10054, '远程主机强迫关闭了一个现有的连接。', None, 10054, None))
2024-03-06 15:30:44,264 ERROR   Thread-22 :57348 [internal_api.py:upload_file():1642] upload_file request headers: {'User-Agent': 'python-requests/2.31.0', 'Accept-Encoding': 'gzip, deflate', 'Accept': '*/*', 'Connection': 'keep-alive', 'Content-Length': '766'}
2024-03-06 15:30:44,265 ERROR   Thread-22 :57348 [internal_api.py:upload_file():1644] upload_file response body: 
2024-03-06 15:31:05,391 INFO    Thread-27 :57348 [upload_job.py:push():132] Uploaded file .\wandb\run-20240306_152917-1hl4cn36\files\wandb-summary.json
2024-03-06 15:31:06,595 ERROR   Thread-26 :57348 [internal_api.py:upload_file():1640] upload_file exception https://storage.googleapis.com/wandb-production.appspot.com/shahwaiz/UNet-DAS/1hl4cn36/requirements.txt?Expires=1709796589&GoogleAccessId=gorilla-files-url-signer-man%40wandb-production.iam.gserviceaccount.com&Signature=TWM77nhE6PdyHkEs%2FdPIu0Z6PMu4QmRfQ3UuXP%2FUuAZ2kot4bUvryRPA05onYecXzJyqCwegqIQNPIMfUfLW8ITv1TfKaMCThBOXixXBJPPWLmybEdUKq1n2EY18yoDk%2Bp0cthglEuPHz7ytkM3XTiTRDKQEX0hD%2BsYYvDEPXyVQrXC67HBZHp3Ynr1Dfm6YuJ4E62EaknIDsMBMwLYAfRlREUKMsF8WlTZzt7g1ThbtM3Yj42zrx%2Fqd%2FFQEoNvACowUssKf1eTFJv9B8maKbMgM%2FeQkMKdUKm0dyu36H9s5GFuJmnKdD4kxIqNPjoPZwZNMw6WRqskNSNYuT0rkqA%3D%3D: ('Connection aborted.', ConnectionResetError(10054, '远程主机强迫关闭了一个现有的连接。', None, 10054, None))
2024-03-06 15:31:06,596 ERROR   Thread-26 :57348 [internal_api.py:upload_file():1642] upload_file request headers: {'User-Agent': 'python-requests/2.31.0', 'Accept-Encoding': 'gzip, deflate', 'Accept': '*/*', 'Connection': 'keep-alive', 'Content-Length': '1252'}
2024-03-06 15:31:06,596 ERROR   Thread-26 :57348 [internal_api.py:upload_file():1644] upload_file response body: 
2024-03-06 15:32:00,029 ERROR   Thread-22 :57348 [internal_api.py:upload_file():1640] upload_file exception https://storage.googleapis.com/wandb-production.appspot.com/shahwaiz/UNet-DAS/1hl4cn36/wandb-metadata.json?Expires=1709796569&GoogleAccessId=gorilla-files-url-signer-man%40wandb-production.iam.gserviceaccount.com&Signature=ZOjft9fu%2Bu1O4J0uXcPelW8mhQdVFFpO4cLhRnfytHRuf8RTAhMmZQsLOJAuYsL%2B3L8RbpoDVjYBhIONNE39EG6cJSI9VyRNxe7Ax1d3E2Hn2sgYKWxrCr3CJyhHJDW0wwtXk6MSDkmqG8QPQgbCzdGI0wS5QVuo8N6SR%2F9EjwT77D4SOE4CtNxRfDC%2Fsr3GzNNkWqBJhB8KCLgjDUo1mEDAYCmdSSFnbmnEuGZ18kru1a4wzQjfhjlJ2bZJD3lYwrAaij1ssbgU0ilKrf9He4aJuouPz%2BRyLCJRSvVNnslV4syKF6IyBELq9en4gqTDFdGkNKMc2N5dCi91%2B8QFyw%3D%3D: ('Connection aborted.', ConnectionResetError(10054, '远程主机强迫关闭了一个现有的连接。', None, 10054, None))
2024-03-06 15:32:00,029 ERROR   Thread-22 :57348 [internal_api.py:upload_file():1642] upload_file request headers: {'User-Agent': 'python-requests/2.31.0', 'Accept-Encoding': 'gzip, deflate', 'Accept': '*/*', 'Connection': 'keep-alive', 'Content-Length': '766'}
2024-03-06 15:32:00,029 ERROR   Thread-22 :57348 [internal_api.py:upload_file():1644] upload_file response body: 
2024-03-06 15:32:26,577 ERROR   Thread-26 :57348 [internal_api.py:upload_file():1640] upload_file exception https://storage.googleapis.com/wandb-production.appspot.com/shahwaiz/UNet-DAS/1hl4cn36/requirements.txt?Expires=1709796589&GoogleAccessId=gorilla-files-url-signer-man%40wandb-production.iam.gserviceaccount.com&Signature=TWM77nhE6PdyHkEs%2FdPIu0Z6PMu4QmRfQ3UuXP%2FUuAZ2kot4bUvryRPA05onYecXzJyqCwegqIQNPIMfUfLW8ITv1TfKaMCThBOXixXBJPPWLmybEdUKq1n2EY18yoDk%2Bp0cthglEuPHz7ytkM3XTiTRDKQEX0hD%2BsYYvDEPXyVQrXC67HBZHp3Ynr1Dfm6YuJ4E62EaknIDsMBMwLYAfRlREUKMsF8WlTZzt7g1ThbtM3Yj42zrx%2Fqd%2FFQEoNvACowUssKf1eTFJv9B8maKbMgM%2FeQkMKdUKm0dyu36H9s5GFuJmnKdD4kxIqNPjoPZwZNMw6WRqskNSNYuT0rkqA%3D%3D: ('Connection aborted.', ConnectionResetError(10054, '远程主机强迫关闭了一个现有的连接。', None, 10054, None))
2024-03-06 15:32:26,577 ERROR   Thread-26 :57348 [internal_api.py:upload_file():1642] upload_file request headers: {'User-Agent': 'python-requests/2.31.0', 'Accept-Encoding': 'gzip, deflate', 'Accept': '*/*', 'Connection': 'keep-alive', 'Content-Length': '1252'}
2024-03-06 15:32:26,577 ERROR   Thread-26 :57348 [internal_api.py:upload_file():1644] upload_file response body: 
2024-03-06 15:32:58,609 WARNING FileStreamThread:57348 [file_stream.py:request_with_retry():593] requests_with_retry encountered retryable exception: HTTPSConnectionPool(host='api.wandb.ai', port=443): Max retries exceeded with url: /files/shahwaiz/UNet-DAS/1hl4cn36/file_stream (Caused by ProxyError('Unable to connect to proxy', SSLError(SSLZeroReturnError(6, 'TLS/SSL connection has been closed (EOF) (_ssl.c:1131)')))). func: <bound method Session.post of <requests.sessions.Session object at 0x000002E9A00A3CD0>>, args: ('https://api.wandb.ai/files/shahwaiz/UNet-DAS/1hl4cn36/file_stream',), kwargs: {'json': {'complete': False, 'failed': False, 'dropped': 0, 'uploaded': ['wandb-summary.json']}}
2024-03-06 15:33:00,953 WARNING FileStreamThread:57348 [file_stream.py:request_with_retry():593] requests_with_retry encountered retryable exception: HTTPSConnectionPool(host='api.wandb.ai', port=443): Max retries exceeded with url: /files/shahwaiz/UNet-DAS/1hl4cn36/file_stream (Caused by ProxyError('Unable to connect to proxy', SSLError(SSLZeroReturnError(6, 'TLS/SSL connection has been closed (EOF) (_ssl.c:1131)')))). func: <bound method Session.post of <requests.sessions.Session object at 0x000002E9A00A3CD0>>, args: ('https://api.wandb.ai/files/shahwaiz/UNet-DAS/1hl4cn36/file_stream',), kwargs: {'json': {'complete': False, 'failed': False, 'dropped': 0, 'uploaded': ['wandb-summary.json']}}
2024-03-06 15:33:05,352 WARNING FileStreamThread:57348 [file_stream.py:request_with_retry():593] requests_with_retry encountered retryable exception: HTTPSConnectionPool(host='api.wandb.ai', port=443): Max retries exceeded with url: /files/shahwaiz/UNet-DAS/1hl4cn36/file_stream (Caused by ProxyError('Unable to connect to proxy', SSLError(SSLZeroReturnError(6, 'TLS/SSL connection has been closed (EOF) (_ssl.c:1131)')))). func: <bound method Session.post of <requests.sessions.Session object at 0x000002E9A00A3CD0>>, args: ('https://api.wandb.ai/files/shahwaiz/UNet-DAS/1hl4cn36/file_stream',), kwargs: {'json': {'complete': False, 'failed': False, 'dropped': 0, 'uploaded': ['wandb-summary.json']}}
2024-03-06 15:33:13,777 WARNING FileStreamThread:57348 [file_stream.py:request_with_retry():593] requests_with_retry encountered retryable exception: HTTPSConnectionPool(host='api.wandb.ai', port=443): Max retries exceeded with url: /files/shahwaiz/UNet-DAS/1hl4cn36/file_stream (Caused by ProxyError('Unable to connect to proxy', SSLError(SSLZeroReturnError(6, 'TLS/SSL connection has been closed (EOF) (_ssl.c:1131)')))). func: <bound method Session.post of <requests.sessions.Session object at 0x000002E9A00A3CD0>>, args: ('https://api.wandb.ai/files/shahwaiz/UNet-DAS/1hl4cn36/file_stream',), kwargs: {'json': {'complete': False, 'failed': False, 'dropped': 0, 'uploaded': ['wandb-summary.json']}}
2024-03-06 15:33:31,132 WARNING FileStreamThread:57348 [file_stream.py:request_with_retry():593] requests_with_retry encountered retryable exception: HTTPSConnectionPool(host='api.wandb.ai', port=443): Max retries exceeded with url: /files/shahwaiz/UNet-DAS/1hl4cn36/file_stream (Caused by ProxyError('Unable to connect to proxy', SSLError(SSLZeroReturnError(6, 'TLS/SSL connection has been closed (EOF) (_ssl.c:1131)')))). func: <bound method Session.post of <requests.sessions.Session object at 0x000002E9A00A3CD0>>, args: ('https://api.wandb.ai/files/shahwaiz/UNet-DAS/1hl4cn36/file_stream',), kwargs: {'json': {'complete': False, 'failed': False, 'dropped': 0, 'uploaded': ['wandb-summary.json']}}
2024-03-06 15:34:35,540 ERROR   Thread-22 :57348 [internal_api.py:upload_file():1640] upload_file exception https://storage.googleapis.com/wandb-production.appspot.com/shahwaiz/UNet-DAS/1hl4cn36/wandb-metadata.json?Expires=1709796569&GoogleAccessId=gorilla-files-url-signer-man%40wandb-production.iam.gserviceaccount.com&Signature=ZOjft9fu%2Bu1O4J0uXcPelW8mhQdVFFpO4cLhRnfytHRuf8RTAhMmZQsLOJAuYsL%2B3L8RbpoDVjYBhIONNE39EG6cJSI9VyRNxe7Ax1d3E2Hn2sgYKWxrCr3CJyhHJDW0wwtXk6MSDkmqG8QPQgbCzdGI0wS5QVuo8N6SR%2F9EjwT77D4SOE4CtNxRfDC%2Fsr3GzNNkWqBJhB8KCLgjDUo1mEDAYCmdSSFnbmnEuGZ18kru1a4wzQjfhjlJ2bZJD3lYwrAaij1ssbgU0ilKrf9He4aJuouPz%2BRyLCJRSvVNnslV4syKF6IyBELq9en4gqTDFdGkNKMc2N5dCi91%2B8QFyw%3D%3D: ('Connection aborted.', ConnectionResetError(10054, '远程主机强迫关闭了一个现有的连接。', None, 10054, None))
2024-03-06 15:34:35,540 ERROR   Thread-22 :57348 [internal_api.py:upload_file():1642] upload_file request headers: {'User-Agent': 'python-requests/2.31.0', 'Accept-Encoding': 'gzip, deflate', 'Accept': '*/*', 'Connection': 'keep-alive', 'Content-Length': '766'}
2024-03-06 15:34:35,540 ERROR   Thread-22 :57348 [internal_api.py:upload_file():1644] upload_file response body: 
2024-03-06 15:35:06,673 ERROR   Thread-26 :57348 [internal_api.py:upload_file():1640] upload_file exception https://storage.googleapis.com/wandb-production.appspot.com/shahwaiz/UNet-DAS/1hl4cn36/requirements.txt?Expires=1709796589&GoogleAccessId=gorilla-files-url-signer-man%40wandb-production.iam.gserviceaccount.com&Signature=TWM77nhE6PdyHkEs%2FdPIu0Z6PMu4QmRfQ3UuXP%2FUuAZ2kot4bUvryRPA05onYecXzJyqCwegqIQNPIMfUfLW8ITv1TfKaMCThBOXixXBJPPWLmybEdUKq1n2EY18yoDk%2Bp0cthglEuPHz7ytkM3XTiTRDKQEX0hD%2BsYYvDEPXyVQrXC67HBZHp3Ynr1Dfm6YuJ4E62EaknIDsMBMwLYAfRlREUKMsF8WlTZzt7g1ThbtM3Yj42zrx%2Fqd%2FFQEoNvACowUssKf1eTFJv9B8maKbMgM%2FeQkMKdUKm0dyu36H9s5GFuJmnKdD4kxIqNPjoPZwZNMw6WRqskNSNYuT0rkqA%3D%3D: ('Connection aborted.', ConnectionResetError(10054, '远程主机强迫关闭了一个现有的连接。', None, 10054, None))
2024-03-06 15:35:06,673 ERROR   Thread-26 :57348 [internal_api.py:upload_file():1642] upload_file request headers: {'User-Agent': 'python-requests/2.31.0', 'Accept-Encoding': 'gzip, deflate', 'Accept': '*/*', 'Connection': 'keep-alive', 'Content-Length': '1252'}
2024-03-06 15:35:06,674 ERROR   Thread-26 :57348 [internal_api.py:upload_file():1644] upload_file response body: 
2024-03-06 15:39:20,197 ERROR   Thread-22 :57348 [internal_api.py:upload_file():1640] upload_file exception https://storage.googleapis.com/wandb-production.appspot.com/shahwaiz/UNet-DAS/1hl4cn36/wandb-metadata.json?Expires=1709796569&GoogleAccessId=gorilla-files-url-signer-man%40wandb-production.iam.gserviceaccount.com&Signature=ZOjft9fu%2Bu1O4J0uXcPelW8mhQdVFFpO4cLhRnfytHRuf8RTAhMmZQsLOJAuYsL%2B3L8RbpoDVjYBhIONNE39EG6cJSI9VyRNxe7Ax1d3E2Hn2sgYKWxrCr3CJyhHJDW0wwtXk6MSDkmqG8QPQgbCzdGI0wS5QVuo8N6SR%2F9EjwT77D4SOE4CtNxRfDC%2Fsr3GzNNkWqBJhB8KCLgjDUo1mEDAYCmdSSFnbmnEuGZ18kru1a4wzQjfhjlJ2bZJD3lYwrAaij1ssbgU0ilKrf9He4aJuouPz%2BRyLCJRSvVNnslV4syKF6IyBELq9en4gqTDFdGkNKMc2N5dCi91%2B8QFyw%3D%3D: ('Connection aborted.', ConnectionResetError(10054, '远程主机强迫关闭了一个现有的连接。', None, 10054, None))
2024-03-06 15:39:20,198 ERROR   Thread-22 :57348 [internal_api.py:upload_file():1642] upload_file request headers: {'User-Agent': 'python-requests/2.31.0', 'Accept-Encoding': 'gzip, deflate', 'Accept': '*/*', 'Connection': 'keep-alive', 'Content-Length': '766'}
2024-03-06 15:39:20,198 ERROR   Thread-22 :57348 [internal_api.py:upload_file():1644] upload_file response body: 
2024-03-06 15:40:13,505 ERROR   Thread-26 :57348 [internal_api.py:upload_file():1640] upload_file exception https://storage.googleapis.com/wandb-production.appspot.com/shahwaiz/UNet-DAS/1hl4cn36/requirements.txt?Expires=1709796589&GoogleAccessId=gorilla-files-url-signer-man%40wandb-production.iam.gserviceaccount.com&Signature=TWM77nhE6PdyHkEs%2FdPIu0Z6PMu4QmRfQ3UuXP%2FUuAZ2kot4bUvryRPA05onYecXzJyqCwegqIQNPIMfUfLW8ITv1TfKaMCThBOXixXBJPPWLmybEdUKq1n2EY18yoDk%2Bp0cthglEuPHz7ytkM3XTiTRDKQEX0hD%2BsYYvDEPXyVQrXC67HBZHp3Ynr1Dfm6YuJ4E62EaknIDsMBMwLYAfRlREUKMsF8WlTZzt7g1ThbtM3Yj42zrx%2Fqd%2FFQEoNvACowUssKf1eTFJv9B8maKbMgM%2FeQkMKdUKm0dyu36H9s5GFuJmnKdD4kxIqNPjoPZwZNMw6WRqskNSNYuT0rkqA%3D%3D: ('Connection aborted.', ConnectionResetError(10054, '远程主机强迫关闭了一个现有的连接。', None, 10054, None))
2024-03-06 15:40:13,505 ERROR   Thread-26 :57348 [internal_api.py:upload_file():1642] upload_file request headers: {'User-Agent': 'python-requests/2.31.0', 'Accept-Encoding': 'gzip, deflate', 'Accept': '*/*', 'Connection': 'keep-alive', 'Content-Length': '1252'}
2024-03-06 15:40:13,506 ERROR   Thread-26 :57348 [internal_api.py:upload_file():1644] upload_file response body: 
2024-03-06 15:44:35,025 ERROR   Thread-22 :57348 [internal_api.py:upload_file():1640] upload_file exception https://storage.googleapis.com/wandb-production.appspot.com/shahwaiz/UNet-DAS/1hl4cn36/wandb-metadata.json?Expires=1709796569&GoogleAccessId=gorilla-files-url-signer-man%40wandb-production.iam.gserviceaccount.com&Signature=ZOjft9fu%2Bu1O4J0uXcPelW8mhQdVFFpO4cLhRnfytHRuf8RTAhMmZQsLOJAuYsL%2B3L8RbpoDVjYBhIONNE39EG6cJSI9VyRNxe7Ax1d3E2Hn2sgYKWxrCr3CJyhHJDW0wwtXk6MSDkmqG8QPQgbCzdGI0wS5QVuo8N6SR%2F9EjwT77D4SOE4CtNxRfDC%2Fsr3GzNNkWqBJhB8KCLgjDUo1mEDAYCmdSSFnbmnEuGZ18kru1a4wzQjfhjlJ2bZJD3lYwrAaij1ssbgU0ilKrf9He4aJuouPz%2BRyLCJRSvVNnslV4syKF6IyBELq9en4gqTDFdGkNKMc2N5dCi91%2B8QFyw%3D%3D: ('Connection aborted.', ConnectionResetError(10054, '远程主机强迫关闭了一个现有的连接。', None, 10054, None))
2024-03-06 15:44:35,025 ERROR   Thread-22 :57348 [internal_api.py:upload_file():1642] upload_file request headers: {'User-Agent': 'python-requests/2.31.0', 'Accept-Encoding': 'gzip, deflate', 'Accept': '*/*', 'Connection': 'keep-alive', 'Content-Length': '766'}
2024-03-06 15:44:35,025 ERROR   Thread-22 :57348 [internal_api.py:upload_file():1644] upload_file response body: 
2024-03-06 15:46:26,855 ERROR   Thread-26 :57348 [internal_api.py:upload_file():1640] upload_file exception https://storage.googleapis.com/wandb-production.appspot.com/shahwaiz/UNet-DAS/1hl4cn36/requirements.txt?Expires=1709796589&GoogleAccessId=gorilla-files-url-signer-man%40wandb-production.iam.gserviceaccount.com&Signature=TWM77nhE6PdyHkEs%2FdPIu0Z6PMu4QmRfQ3UuXP%2FUuAZ2kot4bUvryRPA05onYecXzJyqCwegqIQNPIMfUfLW8ITv1TfKaMCThBOXixXBJPPWLmybEdUKq1n2EY18yoDk%2Bp0cthglEuPHz7ytkM3XTiTRDKQEX0hD%2BsYYvDEPXyVQrXC67HBZHp3Ynr1Dfm6YuJ4E62EaknIDsMBMwLYAfRlREUKMsF8WlTZzt7g1ThbtM3Yj42zrx%2Fqd%2FFQEoNvACowUssKf1eTFJv9B8maKbMgM%2FeQkMKdUKm0dyu36H9s5GFuJmnKdD4kxIqNPjoPZwZNMw6WRqskNSNYuT0rkqA%3D%3D: ('Connection aborted.', ConnectionResetError(10054, '远程主机强迫关闭了一个现有的连接。', None, 10054, None))
2024-03-06 15:46:26,855 ERROR   Thread-26 :57348 [internal_api.py:upload_file():1642] upload_file request headers: {'User-Agent': 'python-requests/2.31.0', 'Accept-Encoding': 'gzip, deflate', 'Accept': '*/*', 'Connection': 'keep-alive', 'Content-Length': '1252'}
2024-03-06 15:46:26,855 ERROR   Thread-26 :57348 [internal_api.py:upload_file():1644] upload_file response body: 
2024-03-06 15:49:58,955 ERROR   Thread-22 :57348 [internal_api.py:upload_file():1640] upload_file exception https://storage.googleapis.com/wandb-production.appspot.com/shahwaiz/UNet-DAS/1hl4cn36/wandb-metadata.json?Expires=1709796569&GoogleAccessId=gorilla-files-url-signer-man%40wandb-production.iam.gserviceaccount.com&Signature=ZOjft9fu%2Bu1O4J0uXcPelW8mhQdVFFpO4cLhRnfytHRuf8RTAhMmZQsLOJAuYsL%2B3L8RbpoDVjYBhIONNE39EG6cJSI9VyRNxe7Ax1d3E2Hn2sgYKWxrCr3CJyhHJDW0wwtXk6MSDkmqG8QPQgbCzdGI0wS5QVuo8N6SR%2F9EjwT77D4SOE4CtNxRfDC%2Fsr3GzNNkWqBJhB8KCLgjDUo1mEDAYCmdSSFnbmnEuGZ18kru1a4wzQjfhjlJ2bZJD3lYwrAaij1ssbgU0ilKrf9He4aJuouPz%2BRyLCJRSvVNnslV4syKF6IyBELq9en4gqTDFdGkNKMc2N5dCi91%2B8QFyw%3D%3D: ('Connection aborted.', ConnectionResetError(10054, '远程主机强迫关闭了一个现有的连接。', None, 10054, None))
2024-03-06 15:49:58,956 ERROR   Thread-22 :57348 [internal_api.py:upload_file():1642] upload_file request headers: {'User-Agent': 'python-requests/2.31.0', 'Accept-Encoding': 'gzip, deflate', 'Accept': '*/*', 'Connection': 'keep-alive', 'Content-Length': '766'}
2024-03-06 15:49:58,956 ERROR   Thread-22 :57348 [internal_api.py:upload_file():1644] upload_file response body: 
2024-03-06 15:51:44,939 ERROR   Thread-26 :57348 [internal_api.py:upload_file():1640] upload_file exception https://storage.googleapis.com/wandb-production.appspot.com/shahwaiz/UNet-DAS/1hl4cn36/requirements.txt?Expires=1709796589&GoogleAccessId=gorilla-files-url-signer-man%40wandb-production.iam.gserviceaccount.com&Signature=TWM77nhE6PdyHkEs%2FdPIu0Z6PMu4QmRfQ3UuXP%2FUuAZ2kot4bUvryRPA05onYecXzJyqCwegqIQNPIMfUfLW8ITv1TfKaMCThBOXixXBJPPWLmybEdUKq1n2EY18yoDk%2Bp0cthglEuPHz7ytkM3XTiTRDKQEX0hD%2BsYYvDEPXyVQrXC67HBZHp3Ynr1Dfm6YuJ4E62EaknIDsMBMwLYAfRlREUKMsF8WlTZzt7g1ThbtM3Yj42zrx%2Fqd%2FFQEoNvACowUssKf1eTFJv9B8maKbMgM%2FeQkMKdUKm0dyu36H9s5GFuJmnKdD4kxIqNPjoPZwZNMw6WRqskNSNYuT0rkqA%3D%3D: ('Connection aborted.', ConnectionResetError(10054, '远程主机强迫关闭了一个现有的连接。', None, 10054, None))
2024-03-06 15:51:44,939 ERROR   Thread-26 :57348 [internal_api.py:upload_file():1642] upload_file request headers: {'User-Agent': 'python-requests/2.31.0', 'Accept-Encoding': 'gzip, deflate', 'Accept': '*/*', 'Connection': 'keep-alive', 'Content-Length': '1252'}
2024-03-06 15:51:44,939 ERROR   Thread-26 :57348 [internal_api.py:upload_file():1644] upload_file response body: 
2024-03-06 15:55:17,996 ERROR   Thread-22 :57348 [internal_api.py:upload_file():1640] upload_file exception https://storage.googleapis.com/wandb-production.appspot.com/shahwaiz/UNet-DAS/1hl4cn36/wandb-metadata.json?Expires=1709796569&GoogleAccessId=gorilla-files-url-signer-man%40wandb-production.iam.gserviceaccount.com&Signature=ZOjft9fu%2Bu1O4J0uXcPelW8mhQdVFFpO4cLhRnfytHRuf8RTAhMmZQsLOJAuYsL%2B3L8RbpoDVjYBhIONNE39EG6cJSI9VyRNxe7Ax1d3E2Hn2sgYKWxrCr3CJyhHJDW0wwtXk6MSDkmqG8QPQgbCzdGI0wS5QVuo8N6SR%2F9EjwT77D4SOE4CtNxRfDC%2Fsr3GzNNkWqBJhB8KCLgjDUo1mEDAYCmdSSFnbmnEuGZ18kru1a4wzQjfhjlJ2bZJD3lYwrAaij1ssbgU0ilKrf9He4aJuouPz%2BRyLCJRSvVNnslV4syKF6IyBELq9en4gqTDFdGkNKMc2N5dCi91%2B8QFyw%3D%3D: ('Connection aborted.', ConnectionResetError(10054, '远程主机强迫关闭了一个现有的连接。', None, 10054, None))
2024-03-06 15:55:17,997 ERROR   Thread-22 :57348 [internal_api.py:upload_file():1642] upload_file request headers: {'User-Agent': 'python-requests/2.31.0', 'Accept-Encoding': 'gzip, deflate', 'Accept': '*/*', 'Connection': 'keep-alive', 'Content-Length': '766'}
2024-03-06 15:55:17,997 ERROR   Thread-22 :57348 [internal_api.py:upload_file():1644] upload_file response body: 
2024-03-06 15:57:50,120 ERROR   Thread-26 :57348 [internal_api.py:upload_file():1640] upload_file exception https://storage.googleapis.com/wandb-production.appspot.com/shahwaiz/UNet-DAS/1hl4cn36/requirements.txt?Expires=1709796589&GoogleAccessId=gorilla-files-url-signer-man%40wandb-production.iam.gserviceaccount.com&Signature=TWM77nhE6PdyHkEs%2FdPIu0Z6PMu4QmRfQ3UuXP%2FUuAZ2kot4bUvryRPA05onYecXzJyqCwegqIQNPIMfUfLW8ITv1TfKaMCThBOXixXBJPPWLmybEdUKq1n2EY18yoDk%2Bp0cthglEuPHz7ytkM3XTiTRDKQEX0hD%2BsYYvDEPXyVQrXC67HBZHp3Ynr1Dfm6YuJ4E62EaknIDsMBMwLYAfRlREUKMsF8WlTZzt7g1ThbtM3Yj42zrx%2Fqd%2FFQEoNvACowUssKf1eTFJv9B8maKbMgM%2FeQkMKdUKm0dyu36H9s5GFuJmnKdD4kxIqNPjoPZwZNMw6WRqskNSNYuT0rkqA%3D%3D: ('Connection aborted.', ConnectionResetError(10054, '远程主机强迫关闭了一个现有的连接。', None, 10054, None))
2024-03-06 15:57:50,121 ERROR   Thread-26 :57348 [internal_api.py:upload_file():1642] upload_file request headers: {'User-Agent': 'python-requests/2.31.0', 'Accept-Encoding': 'gzip, deflate', 'Accept': '*/*', 'Connection': 'keep-alive', 'Content-Length': '1252'}
2024-03-06 15:57:50,121 ERROR   Thread-26 :57348 [internal_api.py:upload_file():1644] upload_file response body: 
2024-03-06 16:01:16,567 ERROR   Thread-22 :57348 [internal_api.py:upload_file():1640] upload_file exception https://storage.googleapis.com/wandb-production.appspot.com/shahwaiz/UNet-DAS/1hl4cn36/wandb-metadata.json?Expires=1709796569&GoogleAccessId=gorilla-files-url-signer-man%40wandb-production.iam.gserviceaccount.com&Signature=ZOjft9fu%2Bu1O4J0uXcPelW8mhQdVFFpO4cLhRnfytHRuf8RTAhMmZQsLOJAuYsL%2B3L8RbpoDVjYBhIONNE39EG6cJSI9VyRNxe7Ax1d3E2Hn2sgYKWxrCr3CJyhHJDW0wwtXk6MSDkmqG8QPQgbCzdGI0wS5QVuo8N6SR%2F9EjwT77D4SOE4CtNxRfDC%2Fsr3GzNNkWqBJhB8KCLgjDUo1mEDAYCmdSSFnbmnEuGZ18kru1a4wzQjfhjlJ2bZJD3lYwrAaij1ssbgU0ilKrf9He4aJuouPz%2BRyLCJRSvVNnslV4syKF6IyBELq9en4gqTDFdGkNKMc2N5dCi91%2B8QFyw%3D%3D: ('Connection aborted.', ConnectionResetError(10054, '远程主机强迫关闭了一个现有的连接。', None, 10054, None))
2024-03-06 16:01:16,568 ERROR   Thread-22 :57348 [internal_api.py:upload_file():1642] upload_file request headers: {'User-Agent': 'python-requests/2.31.0', 'Accept-Encoding': 'gzip, deflate', 'Accept': '*/*', 'Connection': 'keep-alive', 'Content-Length': '766'}
2024-03-06 16:01:16,568 ERROR   Thread-22 :57348 [internal_api.py:upload_file():1644] upload_file response body: 
2024-03-06 16:03:30,140 ERROR   Thread-26 :57348 [internal_api.py:upload_file():1640] upload_file exception https://storage.googleapis.com/wandb-production.appspot.com/shahwaiz/UNet-DAS/1hl4cn36/requirements.txt?Expires=1709796589&GoogleAccessId=gorilla-files-url-signer-man%40wandb-production.iam.gserviceaccount.com&Signature=TWM77nhE6PdyHkEs%2FdPIu0Z6PMu4QmRfQ3UuXP%2FUuAZ2kot4bUvryRPA05onYecXzJyqCwegqIQNPIMfUfLW8ITv1TfKaMCThBOXixXBJPPWLmybEdUKq1n2EY18yoDk%2Bp0cthglEuPHz7ytkM3XTiTRDKQEX0hD%2BsYYvDEPXyVQrXC67HBZHp3Ynr1Dfm6YuJ4E62EaknIDsMBMwLYAfRlREUKMsF8WlTZzt7g1ThbtM3Yj42zrx%2Fqd%2FFQEoNvACowUssKf1eTFJv9B8maKbMgM%2FeQkMKdUKm0dyu36H9s5GFuJmnKdD4kxIqNPjoPZwZNMw6WRqskNSNYuT0rkqA%3D%3D: ('Connection aborted.', ConnectionResetError(10054, '远程主机强迫关闭了一个现有的连接。', None, 10054, None))
2024-03-06 16:03:30,140 ERROR   Thread-26 :57348 [internal_api.py:upload_file():1642] upload_file request headers: {'User-Agent': 'python-requests/2.31.0', 'Accept-Encoding': 'gzip, deflate', 'Accept': '*/*', 'Connection': 'keep-alive', 'Content-Length': '1252'}
2024-03-06 16:03:30,140 ERROR   Thread-26 :57348 [internal_api.py:upload_file():1644] upload_file response body: 
2024-03-06 16:06:48,446 ERROR   Thread-22 :57348 [internal_api.py:upload_file():1640] upload_file exception https://storage.googleapis.com/wandb-production.appspot.com/shahwaiz/UNet-DAS/1hl4cn36/wandb-metadata.json?Expires=1709796569&GoogleAccessId=gorilla-files-url-signer-man%40wandb-production.iam.gserviceaccount.com&Signature=ZOjft9fu%2Bu1O4J0uXcPelW8mhQdVFFpO4cLhRnfytHRuf8RTAhMmZQsLOJAuYsL%2B3L8RbpoDVjYBhIONNE39EG6cJSI9VyRNxe7Ax1d3E2Hn2sgYKWxrCr3CJyhHJDW0wwtXk6MSDkmqG8QPQgbCzdGI0wS5QVuo8N6SR%2F9EjwT77D4SOE4CtNxRfDC%2Fsr3GzNNkWqBJhB8KCLgjDUo1mEDAYCmdSSFnbmnEuGZ18kru1a4wzQjfhjlJ2bZJD3lYwrAaij1ssbgU0ilKrf9He4aJuouPz%2BRyLCJRSvVNnslV4syKF6IyBELq9en4gqTDFdGkNKMc2N5dCi91%2B8QFyw%3D%3D: ('Connection aborted.', ConnectionResetError(10054, '远程主机强迫关闭了一个现有的连接。', None, 10054, None))
2024-03-06 16:06:48,447 ERROR   Thread-22 :57348 [internal_api.py:upload_file():1642] upload_file request headers: {'User-Agent': 'python-requests/2.31.0', 'Accept-Encoding': 'gzip, deflate', 'Accept': '*/*', 'Connection': 'keep-alive', 'Content-Length': '766'}
2024-03-06 16:06:48,447 ERROR   Thread-22 :57348 [internal_api.py:upload_file():1644] upload_file response body: 
2024-03-06 16:08:30,855 ERROR   Thread-26 :57348 [internal_api.py:upload_file():1640] upload_file exception https://storage.googleapis.com/wandb-production.appspot.com/shahwaiz/UNet-DAS/1hl4cn36/requirements.txt?Expires=1709796589&GoogleAccessId=gorilla-files-url-signer-man%40wandb-production.iam.gserviceaccount.com&Signature=TWM77nhE6PdyHkEs%2FdPIu0Z6PMu4QmRfQ3UuXP%2FUuAZ2kot4bUvryRPA05onYecXzJyqCwegqIQNPIMfUfLW8ITv1TfKaMCThBOXixXBJPPWLmybEdUKq1n2EY18yoDk%2Bp0cthglEuPHz7ytkM3XTiTRDKQEX0hD%2BsYYvDEPXyVQrXC67HBZHp3Ynr1Dfm6YuJ4E62EaknIDsMBMwLYAfRlREUKMsF8WlTZzt7g1ThbtM3Yj42zrx%2Fqd%2FFQEoNvACowUssKf1eTFJv9B8maKbMgM%2FeQkMKdUKm0dyu36H9s5GFuJmnKdD4kxIqNPjoPZwZNMw6WRqskNSNYuT0rkqA%3D%3D: ('Connection aborted.', ConnectionResetError(10054, '远程主机强迫关闭了一个现有的连接。', None, 10054, None))
2024-03-06 16:08:30,855 ERROR   Thread-26 :57348 [internal_api.py:upload_file():1642] upload_file request headers: {'User-Agent': 'python-requests/2.31.0', 'Accept-Encoding': 'gzip, deflate', 'Accept': '*/*', 'Connection': 'keep-alive', 'Content-Length': '1252'}
2024-03-06 16:08:30,855 ERROR   Thread-26 :57348 [internal_api.py:upload_file():1644] upload_file response body: 
2024-03-06 16:12:27,827 ERROR   Thread-22 :57348 [internal_api.py:upload_file():1640] upload_file exception https://storage.googleapis.com/wandb-production.appspot.com/shahwaiz/UNet-DAS/1hl4cn36/wandb-metadata.json?Expires=1709796569&GoogleAccessId=gorilla-files-url-signer-man%40wandb-production.iam.gserviceaccount.com&Signature=ZOjft9fu%2Bu1O4J0uXcPelW8mhQdVFFpO4cLhRnfytHRuf8RTAhMmZQsLOJAuYsL%2B3L8RbpoDVjYBhIONNE39EG6cJSI9VyRNxe7Ax1d3E2Hn2sgYKWxrCr3CJyhHJDW0wwtXk6MSDkmqG8QPQgbCzdGI0wS5QVuo8N6SR%2F9EjwT77D4SOE4CtNxRfDC%2Fsr3GzNNkWqBJhB8KCLgjDUo1mEDAYCmdSSFnbmnEuGZ18kru1a4wzQjfhjlJ2bZJD3lYwrAaij1ssbgU0ilKrf9He4aJuouPz%2BRyLCJRSvVNnslV4syKF6IyBELq9en4gqTDFdGkNKMc2N5dCi91%2B8QFyw%3D%3D: ('Connection aborted.', ConnectionResetError(10054, '远程主机强迫关闭了一个现有的连接。', None, 10054, None))
2024-03-06 16:12:27,828 ERROR   Thread-22 :57348 [internal_api.py:upload_file():1642] upload_file request headers: {'User-Agent': 'python-requests/2.31.0', 'Accept-Encoding': 'gzip, deflate', 'Accept': '*/*', 'Connection': 'keep-alive', 'Content-Length': '766'}
2024-03-06 16:12:27,828 ERROR   Thread-22 :57348 [internal_api.py:upload_file():1644] upload_file response body: 
2024-03-06 16:14:15,763 ERROR   Thread-26 :57348 [internal_api.py:upload_file():1640] upload_file exception https://storage.googleapis.com/wandb-production.appspot.com/shahwaiz/UNet-DAS/1hl4cn36/requirements.txt?Expires=1709796589&GoogleAccessId=gorilla-files-url-signer-man%40wandb-production.iam.gserviceaccount.com&Signature=TWM77nhE6PdyHkEs%2FdPIu0Z6PMu4QmRfQ3UuXP%2FUuAZ2kot4bUvryRPA05onYecXzJyqCwegqIQNPIMfUfLW8ITv1TfKaMCThBOXixXBJPPWLmybEdUKq1n2EY18yoDk%2Bp0cthglEuPHz7ytkM3XTiTRDKQEX0hD%2BsYYvDEPXyVQrXC67HBZHp3Ynr1Dfm6YuJ4E62EaknIDsMBMwLYAfRlREUKMsF8WlTZzt7g1ThbtM3Yj42zrx%2Fqd%2FFQEoNvACowUssKf1eTFJv9B8maKbMgM%2FeQkMKdUKm0dyu36H9s5GFuJmnKdD4kxIqNPjoPZwZNMw6WRqskNSNYuT0rkqA%3D%3D: ('Connection aborted.', ConnectionResetError(10054, '远程主机强迫关闭了一个现有的连接。', None, 10054, None))
2024-03-06 16:14:15,764 ERROR   Thread-26 :57348 [internal_api.py:upload_file():1642] upload_file request headers: {'User-Agent': 'python-requests/2.31.0', 'Accept-Encoding': 'gzip, deflate', 'Accept': '*/*', 'Connection': 'keep-alive', 'Content-Length': '1252'}
2024-03-06 16:14:15,764 ERROR   Thread-26 :57348 [internal_api.py:upload_file():1644] upload_file response body: 
2024-03-06 16:17:53,809 ERROR   Thread-22 :57348 [internal_api.py:upload_file():1640] upload_file exception https://storage.googleapis.com/wandb-production.appspot.com/shahwaiz/UNet-DAS/1hl4cn36/wandb-metadata.json?Expires=1709796569&GoogleAccessId=gorilla-files-url-signer-man%40wandb-production.iam.gserviceaccount.com&Signature=ZOjft9fu%2Bu1O4J0uXcPelW8mhQdVFFpO4cLhRnfytHRuf8RTAhMmZQsLOJAuYsL%2B3L8RbpoDVjYBhIONNE39EG6cJSI9VyRNxe7Ax1d3E2Hn2sgYKWxrCr3CJyhHJDW0wwtXk6MSDkmqG8QPQgbCzdGI0wS5QVuo8N6SR%2F9EjwT77D4SOE4CtNxRfDC%2Fsr3GzNNkWqBJhB8KCLgjDUo1mEDAYCmdSSFnbmnEuGZ18kru1a4wzQjfhjlJ2bZJD3lYwrAaij1ssbgU0ilKrf9He4aJuouPz%2BRyLCJRSvVNnslV4syKF6IyBELq9en4gqTDFdGkNKMc2N5dCi91%2B8QFyw%3D%3D: ('Connection aborted.', ConnectionResetError(10054, '远程主机强迫关闭了一个现有的连接。', None, 10054, None))
2024-03-06 16:17:53,810 ERROR   Thread-22 :57348 [internal_api.py:upload_file():1642] upload_file request headers: {'User-Agent': 'python-requests/2.31.0', 'Accept-Encoding': 'gzip, deflate', 'Accept': '*/*', 'Connection': 'keep-alive', 'Content-Length': '766'}
2024-03-06 16:17:53,810 ERROR   Thread-22 :57348 [internal_api.py:upload_file():1644] upload_file response body: 
2024-03-06 16:19:53,013 ERROR   Thread-26 :57348 [internal_api.py:upload_file():1640] upload_file exception https://storage.googleapis.com/wandb-production.appspot.com/shahwaiz/UNet-DAS/1hl4cn36/requirements.txt?Expires=1709796589&GoogleAccessId=gorilla-files-url-signer-man%40wandb-production.iam.gserviceaccount.com&Signature=TWM77nhE6PdyHkEs%2FdPIu0Z6PMu4QmRfQ3UuXP%2FUuAZ2kot4bUvryRPA05onYecXzJyqCwegqIQNPIMfUfLW8ITv1TfKaMCThBOXixXBJPPWLmybEdUKq1n2EY18yoDk%2Bp0cthglEuPHz7ytkM3XTiTRDKQEX0hD%2BsYYvDEPXyVQrXC67HBZHp3Ynr1Dfm6YuJ4E62EaknIDsMBMwLYAfRlREUKMsF8WlTZzt7g1ThbtM3Yj42zrx%2Fqd%2FFQEoNvACowUssKf1eTFJv9B8maKbMgM%2FeQkMKdUKm0dyu36H9s5GFuJmnKdD4kxIqNPjoPZwZNMw6WRqskNSNYuT0rkqA%3D%3D: ('Connection aborted.', ConnectionResetError(10054, '远程主机强迫关闭了一个现有的连接。', None, 10054, None))
2024-03-06 16:19:53,013 ERROR   Thread-26 :57348 [internal_api.py:upload_file():1642] upload_file request headers: {'User-Agent': 'python-requests/2.31.0', 'Accept-Encoding': 'gzip, deflate', 'Accept': '*/*', 'Connection': 'keep-alive', 'Content-Length': '1252'}
2024-03-06 16:19:53,013 ERROR   Thread-26 :57348 [internal_api.py:upload_file():1644] upload_file response body: 
2024-03-06 16:23:01,427 ERROR   Thread-22 :57348 [internal_api.py:upload_file():1640] upload_file exception https://storage.googleapis.com/wandb-production.appspot.com/shahwaiz/UNet-DAS/1hl4cn36/wandb-metadata.json?Expires=1709796569&GoogleAccessId=gorilla-files-url-signer-man%40wandb-production.iam.gserviceaccount.com&Signature=ZOjft9fu%2Bu1O4J0uXcPelW8mhQdVFFpO4cLhRnfytHRuf8RTAhMmZQsLOJAuYsL%2B3L8RbpoDVjYBhIONNE39EG6cJSI9VyRNxe7Ax1d3E2Hn2sgYKWxrCr3CJyhHJDW0wwtXk6MSDkmqG8QPQgbCzdGI0wS5QVuo8N6SR%2F9EjwT77D4SOE4CtNxRfDC%2Fsr3GzNNkWqBJhB8KCLgjDUo1mEDAYCmdSSFnbmnEuGZ18kru1a4wzQjfhjlJ2bZJD3lYwrAaij1ssbgU0ilKrf9He4aJuouPz%2BRyLCJRSvVNnslV4syKF6IyBELq9en4gqTDFdGkNKMc2N5dCi91%2B8QFyw%3D%3D: ('Connection aborted.', ConnectionResetError(10054, '远程主机强迫关闭了一个现有的连接。', None, 10054, None))
2024-03-06 16:23:01,428 ERROR   Thread-22 :57348 [internal_api.py:upload_file():1642] upload_file request headers: {'User-Agent': 'python-requests/2.31.0', 'Accept-Encoding': 'gzip, deflate', 'Accept': '*/*', 'Connection': 'keep-alive', 'Content-Length': '766'}
2024-03-06 16:23:01,428 ERROR   Thread-22 :57348 [internal_api.py:upload_file():1644] upload_file response body: 
2024-03-06 16:25:16,342 ERROR   Thread-26 :57348 [internal_api.py:upload_file():1640] upload_file exception https://storage.googleapis.com/wandb-production.appspot.com/shahwaiz/UNet-DAS/1hl4cn36/requirements.txt?Expires=1709796589&GoogleAccessId=gorilla-files-url-signer-man%40wandb-production.iam.gserviceaccount.com&Signature=TWM77nhE6PdyHkEs%2FdPIu0Z6PMu4QmRfQ3UuXP%2FUuAZ2kot4bUvryRPA05onYecXzJyqCwegqIQNPIMfUfLW8ITv1TfKaMCThBOXixXBJPPWLmybEdUKq1n2EY18yoDk%2Bp0cthglEuPHz7ytkM3XTiTRDKQEX0hD%2BsYYvDEPXyVQrXC67HBZHp3Ynr1Dfm6YuJ4E62EaknIDsMBMwLYAfRlREUKMsF8WlTZzt7g1ThbtM3Yj42zrx%2Fqd%2FFQEoNvACowUssKf1eTFJv9B8maKbMgM%2FeQkMKdUKm0dyu36H9s5GFuJmnKdD4kxIqNPjoPZwZNMw6WRqskNSNYuT0rkqA%3D%3D: ('Connection aborted.', ConnectionResetError(10054, '远程主机强迫关闭了一个现有的连接。', None, 10054, None))
2024-03-06 16:25:16,342 ERROR   Thread-26 :57348 [internal_api.py:upload_file():1642] upload_file request headers: {'User-Agent': 'python-requests/2.31.0', 'Accept-Encoding': 'gzip, deflate', 'Accept': '*/*', 'Connection': 'keep-alive', 'Content-Length': '1252'}
2024-03-06 16:25:16,342 ERROR   Thread-26 :57348 [internal_api.py:upload_file():1644] upload_file response body: 
2024-03-06 16:28:06,729 ERROR   Thread-22 :57348 [internal_api.py:upload_file():1640] upload_file exception https://storage.googleapis.com/wandb-production.appspot.com/shahwaiz/UNet-DAS/1hl4cn36/wandb-metadata.json?Expires=1709796569&GoogleAccessId=gorilla-files-url-signer-man%40wandb-production.iam.gserviceaccount.com&Signature=ZOjft9fu%2Bu1O4J0uXcPelW8mhQdVFFpO4cLhRnfytHRuf8RTAhMmZQsLOJAuYsL%2B3L8RbpoDVjYBhIONNE39EG6cJSI9VyRNxe7Ax1d3E2Hn2sgYKWxrCr3CJyhHJDW0wwtXk6MSDkmqG8QPQgbCzdGI0wS5QVuo8N6SR%2F9EjwT77D4SOE4CtNxRfDC%2Fsr3GzNNkWqBJhB8KCLgjDUo1mEDAYCmdSSFnbmnEuGZ18kru1a4wzQjfhjlJ2bZJD3lYwrAaij1ssbgU0ilKrf9He4aJuouPz%2BRyLCJRSvVNnslV4syKF6IyBELq9en4gqTDFdGkNKMc2N5dCi91%2B8QFyw%3D%3D: ('Connection aborted.', ConnectionResetError(10054, '远程主机强迫关闭了一个现有的连接。', None, 10054, None))
2024-03-06 16:28:06,729 ERROR   Thread-22 :57348 [internal_api.py:upload_file():1642] upload_file request headers: {'User-Agent': 'python-requests/2.31.0', 'Accept-Encoding': 'gzip, deflate', 'Accept': '*/*', 'Connection': 'keep-alive', 'Content-Length': '766'}
2024-03-06 16:28:06,729 ERROR   Thread-22 :57348 [internal_api.py:upload_file():1644] upload_file response body: 
2024-03-06 16:30:48,404 ERROR   Thread-26 :57348 [internal_api.py:upload_file():1640] upload_file exception https://storage.googleapis.com/wandb-production.appspot.com/shahwaiz/UNet-DAS/1hl4cn36/requirements.txt?Expires=1709796589&GoogleAccessId=gorilla-files-url-signer-man%40wandb-production.iam.gserviceaccount.com&Signature=TWM77nhE6PdyHkEs%2FdPIu0Z6PMu4QmRfQ3UuXP%2FUuAZ2kot4bUvryRPA05onYecXzJyqCwegqIQNPIMfUfLW8ITv1TfKaMCThBOXixXBJPPWLmybEdUKq1n2EY18yoDk%2Bp0cthglEuPHz7ytkM3XTiTRDKQEX0hD%2BsYYvDEPXyVQrXC67HBZHp3Ynr1Dfm6YuJ4E62EaknIDsMBMwLYAfRlREUKMsF8WlTZzt7g1ThbtM3Yj42zrx%2Fqd%2FFQEoNvACowUssKf1eTFJv9B8maKbMgM%2FeQkMKdUKm0dyu36H9s5GFuJmnKdD4kxIqNPjoPZwZNMw6WRqskNSNYuT0rkqA%3D%3D: ('Connection aborted.', ConnectionResetError(10054, '远程主机强迫关闭了一个现有的连接。', None, 10054, None))
2024-03-06 16:30:48,404 ERROR   Thread-26 :57348 [internal_api.py:upload_file():1642] upload_file request headers: {'User-Agent': 'python-requests/2.31.0', 'Accept-Encoding': 'gzip, deflate', 'Accept': '*/*', 'Connection': 'keep-alive', 'Content-Length': '1252'}
2024-03-06 16:30:48,404 ERROR   Thread-26 :57348 [internal_api.py:upload_file():1644] upload_file response body: 
2024-03-06 16:33:47,739 ERROR   Thread-22 :57348 [internal_api.py:upload_file():1640] upload_file exception https://storage.googleapis.com/wandb-production.appspot.com/shahwaiz/UNet-DAS/1hl4cn36/wandb-metadata.json?Expires=1709796569&GoogleAccessId=gorilla-files-url-signer-man%40wandb-production.iam.gserviceaccount.com&Signature=ZOjft9fu%2Bu1O4J0uXcPelW8mhQdVFFpO4cLhRnfytHRuf8RTAhMmZQsLOJAuYsL%2B3L8RbpoDVjYBhIONNE39EG6cJSI9VyRNxe7Ax1d3E2Hn2sgYKWxrCr3CJyhHJDW0wwtXk6MSDkmqG8QPQgbCzdGI0wS5QVuo8N6SR%2F9EjwT77D4SOE4CtNxRfDC%2Fsr3GzNNkWqBJhB8KCLgjDUo1mEDAYCmdSSFnbmnEuGZ18kru1a4wzQjfhjlJ2bZJD3lYwrAaij1ssbgU0ilKrf9He4aJuouPz%2BRyLCJRSvVNnslV4syKF6IyBELq9en4gqTDFdGkNKMc2N5dCi91%2B8QFyw%3D%3D: ('Connection aborted.', ConnectionResetError(10054, '远程主机强迫关闭了一个现有的连接。', None, 10054, None))
2024-03-06 16:33:47,739 ERROR   Thread-22 :57348 [internal_api.py:upload_file():1642] upload_file request headers: {'User-Agent': 'python-requests/2.31.0', 'Accept-Encoding': 'gzip, deflate', 'Accept': '*/*', 'Connection': 'keep-alive', 'Content-Length': '766'}
2024-03-06 16:33:47,740 ERROR   Thread-22 :57348 [internal_api.py:upload_file():1644] upload_file response body: 
2024-03-06 16:36:03,374 ERROR   Thread-26 :57348 [internal_api.py:upload_file():1640] upload_file exception https://storage.googleapis.com/wandb-production.appspot.com/shahwaiz/UNet-DAS/1hl4cn36/requirements.txt?Expires=1709796589&GoogleAccessId=gorilla-files-url-signer-man%40wandb-production.iam.gserviceaccount.com&Signature=TWM77nhE6PdyHkEs%2FdPIu0Z6PMu4QmRfQ3UuXP%2FUuAZ2kot4bUvryRPA05onYecXzJyqCwegqIQNPIMfUfLW8ITv1TfKaMCThBOXixXBJPPWLmybEdUKq1n2EY18yoDk%2Bp0cthglEuPHz7ytkM3XTiTRDKQEX0hD%2BsYYvDEPXyVQrXC67HBZHp3Ynr1Dfm6YuJ4E62EaknIDsMBMwLYAfRlREUKMsF8WlTZzt7g1ThbtM3Yj42zrx%2Fqd%2FFQEoNvACowUssKf1eTFJv9B8maKbMgM%2FeQkMKdUKm0dyu36H9s5GFuJmnKdD4kxIqNPjoPZwZNMw6WRqskNSNYuT0rkqA%3D%3D: ('Connection aborted.', ConnectionResetError(10054, '远程主机强迫关闭了一个现有的连接。', None, 10054, None))
2024-03-06 16:36:03,374 ERROR   Thread-26 :57348 [internal_api.py:upload_file():1642] upload_file request headers: {'User-Agent': 'python-requests/2.31.0', 'Accept-Encoding': 'gzip, deflate', 'Accept': '*/*', 'Connection': 'keep-alive', 'Content-Length': '1252'}
2024-03-06 16:36:03,374 ERROR   Thread-26 :57348 [internal_api.py:upload_file():1644] upload_file response body: 
2024-03-06 16:38:51,142 ERROR   Thread-22 :57348 [internal_api.py:upload_file():1640] upload_file exception https://storage.googleapis.com/wandb-production.appspot.com/shahwaiz/UNet-DAS/1hl4cn36/wandb-metadata.json?Expires=1709796569&GoogleAccessId=gorilla-files-url-signer-man%40wandb-production.iam.gserviceaccount.com&Signature=ZOjft9fu%2Bu1O4J0uXcPelW8mhQdVFFpO4cLhRnfytHRuf8RTAhMmZQsLOJAuYsL%2B3L8RbpoDVjYBhIONNE39EG6cJSI9VyRNxe7Ax1d3E2Hn2sgYKWxrCr3CJyhHJDW0wwtXk6MSDkmqG8QPQgbCzdGI0wS5QVuo8N6SR%2F9EjwT77D4SOE4CtNxRfDC%2Fsr3GzNNkWqBJhB8KCLgjDUo1mEDAYCmdSSFnbmnEuGZ18kru1a4wzQjfhjlJ2bZJD3lYwrAaij1ssbgU0ilKrf9He4aJuouPz%2BRyLCJRSvVNnslV4syKF6IyBELq9en4gqTDFdGkNKMc2N5dCi91%2B8QFyw%3D%3D: ('Connection aborted.', ConnectionResetError(10054, '远程主机强迫关闭了一个现有的连接。', None, 10054, None))
2024-03-06 16:38:51,142 ERROR   Thread-22 :57348 [internal_api.py:upload_file():1642] upload_file request headers: {'User-Agent': 'python-requests/2.31.0', 'Accept-Encoding': 'gzip, deflate', 'Accept': '*/*', 'Connection': 'keep-alive', 'Content-Length': '766'}
2024-03-06 16:38:51,142 ERROR   Thread-22 :57348 [internal_api.py:upload_file():1644] upload_file response body: 
2024-03-06 16:41:17,641 ERROR   Thread-26 :57348 [internal_api.py:upload_file():1640] upload_file exception https://storage.googleapis.com/wandb-production.appspot.com/shahwaiz/UNet-DAS/1hl4cn36/requirements.txt?Expires=1709796589&GoogleAccessId=gorilla-files-url-signer-man%40wandb-production.iam.gserviceaccount.com&Signature=TWM77nhE6PdyHkEs%2FdPIu0Z6PMu4QmRfQ3UuXP%2FUuAZ2kot4bUvryRPA05onYecXzJyqCwegqIQNPIMfUfLW8ITv1TfKaMCThBOXixXBJPPWLmybEdUKq1n2EY18yoDk%2Bp0cthglEuPHz7ytkM3XTiTRDKQEX0hD%2BsYYvDEPXyVQrXC67HBZHp3Ynr1Dfm6YuJ4E62EaknIDsMBMwLYAfRlREUKMsF8WlTZzt7g1ThbtM3Yj42zrx%2Fqd%2FFQEoNvACowUssKf1eTFJv9B8maKbMgM%2FeQkMKdUKm0dyu36H9s5GFuJmnKdD4kxIqNPjoPZwZNMw6WRqskNSNYuT0rkqA%3D%3D: ('Connection aborted.', ConnectionResetError(10054, '远程主机强迫关闭了一个现有的连接。', None, 10054, None))
2024-03-06 16:41:17,641 ERROR   Thread-26 :57348 [internal_api.py:upload_file():1642] upload_file request headers: {'User-Agent': 'python-requests/2.31.0', 'Accept-Encoding': 'gzip, deflate', 'Accept': '*/*', 'Connection': 'keep-alive', 'Content-Length': '1252'}
2024-03-06 16:41:17,641 ERROR   Thread-26 :57348 [internal_api.py:upload_file():1644] upload_file response body: 
2024-03-06 16:44:41,174 ERROR   Thread-22 :57348 [internal_api.py:upload_file():1640] upload_file exception https://storage.googleapis.com/wandb-production.appspot.com/shahwaiz/UNet-DAS/1hl4cn36/wandb-metadata.json?Expires=1709796569&GoogleAccessId=gorilla-files-url-signer-man%40wandb-production.iam.gserviceaccount.com&Signature=ZOjft9fu%2Bu1O4J0uXcPelW8mhQdVFFpO4cLhRnfytHRuf8RTAhMmZQsLOJAuYsL%2B3L8RbpoDVjYBhIONNE39EG6cJSI9VyRNxe7Ax1d3E2Hn2sgYKWxrCr3CJyhHJDW0wwtXk6MSDkmqG8QPQgbCzdGI0wS5QVuo8N6SR%2F9EjwT77D4SOE4CtNxRfDC%2Fsr3GzNNkWqBJhB8KCLgjDUo1mEDAYCmdSSFnbmnEuGZ18kru1a4wzQjfhjlJ2bZJD3lYwrAaij1ssbgU0ilKrf9He4aJuouPz%2BRyLCJRSvVNnslV4syKF6IyBELq9en4gqTDFdGkNKMc2N5dCi91%2B8QFyw%3D%3D: ('Connection aborted.', ConnectionResetError(10054, '远程主机强迫关闭了一个现有的连接。', None, 10054, None))
2024-03-06 16:44:41,175 ERROR   Thread-22 :57348 [internal_api.py:upload_file():1642] upload_file request headers: {'User-Agent': 'python-requests/2.31.0', 'Accept-Encoding': 'gzip, deflate', 'Accept': '*/*', 'Connection': 'keep-alive', 'Content-Length': '766'}
2024-03-06 16:44:41,175 ERROR   Thread-22 :57348 [internal_api.py:upload_file():1644] upload_file response body: 
2024-03-06 16:47:16,450 ERROR   Thread-26 :57348 [internal_api.py:upload_file():1640] upload_file exception https://storage.googleapis.com/wandb-production.appspot.com/shahwaiz/UNet-DAS/1hl4cn36/requirements.txt?Expires=1709796589&GoogleAccessId=gorilla-files-url-signer-man%40wandb-production.iam.gserviceaccount.com&Signature=TWM77nhE6PdyHkEs%2FdPIu0Z6PMu4QmRfQ3UuXP%2FUuAZ2kot4bUvryRPA05onYecXzJyqCwegqIQNPIMfUfLW8ITv1TfKaMCThBOXixXBJPPWLmybEdUKq1n2EY18yoDk%2Bp0cthglEuPHz7ytkM3XTiTRDKQEX0hD%2BsYYvDEPXyVQrXC67HBZHp3Ynr1Dfm6YuJ4E62EaknIDsMBMwLYAfRlREUKMsF8WlTZzt7g1ThbtM3Yj42zrx%2Fqd%2FFQEoNvACowUssKf1eTFJv9B8maKbMgM%2FeQkMKdUKm0dyu36H9s5GFuJmnKdD4kxIqNPjoPZwZNMw6WRqskNSNYuT0rkqA%3D%3D: ('Connection aborted.', ConnectionResetError(10054, '远程主机强迫关闭了一个现有的连接。', None, 10054, None))
2024-03-06 16:47:16,450 ERROR   Thread-26 :57348 [internal_api.py:upload_file():1642] upload_file request headers: {'User-Agent': 'python-requests/2.31.0', 'Accept-Encoding': 'gzip, deflate', 'Accept': '*/*', 'Connection': 'keep-alive', 'Content-Length': '1252'}
2024-03-06 16:47:16,450 ERROR   Thread-26 :57348 [internal_api.py:upload_file():1644] upload_file response body: 
2024-03-06 16:50:04,071 ERROR   Thread-22 :57348 [internal_api.py:upload_file():1640] upload_file exception https://storage.googleapis.com/wandb-production.appspot.com/shahwaiz/UNet-DAS/1hl4cn36/wandb-metadata.json?Expires=1709796569&GoogleAccessId=gorilla-files-url-signer-man%40wandb-production.iam.gserviceaccount.com&Signature=ZOjft9fu%2Bu1O4J0uXcPelW8mhQdVFFpO4cLhRnfytHRuf8RTAhMmZQsLOJAuYsL%2B3L8RbpoDVjYBhIONNE39EG6cJSI9VyRNxe7Ax1d3E2Hn2sgYKWxrCr3CJyhHJDW0wwtXk6MSDkmqG8QPQgbCzdGI0wS5QVuo8N6SR%2F9EjwT77D4SOE4CtNxRfDC%2Fsr3GzNNkWqBJhB8KCLgjDUo1mEDAYCmdSSFnbmnEuGZ18kru1a4wzQjfhjlJ2bZJD3lYwrAaij1ssbgU0ilKrf9He4aJuouPz%2BRyLCJRSvVNnslV4syKF6IyBELq9en4gqTDFdGkNKMc2N5dCi91%2B8QFyw%3D%3D: ('Connection aborted.', ConnectionResetError(10054, '远程主机强迫关闭了一个现有的连接。', None, 10054, None))
2024-03-06 16:50:04,072 ERROR   Thread-22 :57348 [internal_api.py:upload_file():1642] upload_file request headers: {'User-Agent': 'python-requests/2.31.0', 'Accept-Encoding': 'gzip, deflate', 'Accept': '*/*', 'Connection': 'keep-alive', 'Content-Length': '766'}
2024-03-06 16:50:04,072 ERROR   Thread-22 :57348 [internal_api.py:upload_file():1644] upload_file response body: 
2024-03-06 16:52:47,991 ERROR   Thread-26 :57348 [internal_api.py:upload_file():1640] upload_file exception https://storage.googleapis.com/wandb-production.appspot.com/shahwaiz/UNet-DAS/1hl4cn36/requirements.txt?Expires=1709796589&GoogleAccessId=gorilla-files-url-signer-man%40wandb-production.iam.gserviceaccount.com&Signature=TWM77nhE6PdyHkEs%2FdPIu0Z6PMu4QmRfQ3UuXP%2FUuAZ2kot4bUvryRPA05onYecXzJyqCwegqIQNPIMfUfLW8ITv1TfKaMCThBOXixXBJPPWLmybEdUKq1n2EY18yoDk%2Bp0cthglEuPHz7ytkM3XTiTRDKQEX0hD%2BsYYvDEPXyVQrXC67HBZHp3Ynr1Dfm6YuJ4E62EaknIDsMBMwLYAfRlREUKMsF8WlTZzt7g1ThbtM3Yj42zrx%2Fqd%2FFQEoNvACowUssKf1eTFJv9B8maKbMgM%2FeQkMKdUKm0dyu36H9s5GFuJmnKdD4kxIqNPjoPZwZNMw6WRqskNSNYuT0rkqA%3D%3D: ('Connection aborted.', ConnectionResetError(10054, '远程主机强迫关闭了一个现有的连接。', None, 10054, None))
2024-03-06 16:52:47,991 ERROR   Thread-26 :57348 [internal_api.py:upload_file():1642] upload_file request headers: {'User-Agent': 'python-requests/2.31.0', 'Accept-Encoding': 'gzip, deflate', 'Accept': '*/*', 'Connection': 'keep-alive', 'Content-Length': '1252'}
2024-03-06 16:52:47,991 ERROR   Thread-26 :57348 [internal_api.py:upload_file():1644] upload_file response body: 
2024-03-06 16:56:02,621 ERROR   Thread-22 :57348 [internal_api.py:upload_file():1640] upload_file exception https://storage.googleapis.com/wandb-production.appspot.com/shahwaiz/UNet-DAS/1hl4cn36/wandb-metadata.json?Expires=1709796569&GoogleAccessId=gorilla-files-url-signer-man%40wandb-production.iam.gserviceaccount.com&Signature=ZOjft9fu%2Bu1O4J0uXcPelW8mhQdVFFpO4cLhRnfytHRuf8RTAhMmZQsLOJAuYsL%2B3L8RbpoDVjYBhIONNE39EG6cJSI9VyRNxe7Ax1d3E2Hn2sgYKWxrCr3CJyhHJDW0wwtXk6MSDkmqG8QPQgbCzdGI0wS5QVuo8N6SR%2F9EjwT77D4SOE4CtNxRfDC%2Fsr3GzNNkWqBJhB8KCLgjDUo1mEDAYCmdSSFnbmnEuGZ18kru1a4wzQjfhjlJ2bZJD3lYwrAaij1ssbgU0ilKrf9He4aJuouPz%2BRyLCJRSvVNnslV4syKF6IyBELq9en4gqTDFdGkNKMc2N5dCi91%2B8QFyw%3D%3D: ('Connection aborted.', ConnectionResetError(10054, '远程主机强迫关闭了一个现有的连接。', None, 10054, None))
2024-03-06 16:56:02,621 ERROR   Thread-22 :57348 [internal_api.py:upload_file():1642] upload_file request headers: {'User-Agent': 'python-requests/2.31.0', 'Accept-Encoding': 'gzip, deflate', 'Accept': '*/*', 'Connection': 'keep-alive', 'Content-Length': '766'}
2024-03-06 16:56:02,622 ERROR   Thread-22 :57348 [internal_api.py:upload_file():1644] upload_file response body: 
2024-03-06 16:57:58,223 ERROR   Thread-26 :57348 [internal_api.py:upload_file():1640] upload_file exception https://storage.googleapis.com/wandb-production.appspot.com/shahwaiz/UNet-DAS/1hl4cn36/requirements.txt?Expires=1709796589&GoogleAccessId=gorilla-files-url-signer-man%40wandb-production.iam.gserviceaccount.com&Signature=TWM77nhE6PdyHkEs%2FdPIu0Z6PMu4QmRfQ3UuXP%2FUuAZ2kot4bUvryRPA05onYecXzJyqCwegqIQNPIMfUfLW8ITv1TfKaMCThBOXixXBJPPWLmybEdUKq1n2EY18yoDk%2Bp0cthglEuPHz7ytkM3XTiTRDKQEX0hD%2BsYYvDEPXyVQrXC67HBZHp3Ynr1Dfm6YuJ4E62EaknIDsMBMwLYAfRlREUKMsF8WlTZzt7g1ThbtM3Yj42zrx%2Fqd%2FFQEoNvACowUssKf1eTFJv9B8maKbMgM%2FeQkMKdUKm0dyu36H9s5GFuJmnKdD4kxIqNPjoPZwZNMw6WRqskNSNYuT0rkqA%3D%3D: ('Connection aborted.', ConnectionResetError(10054, '远程主机强迫关闭了一个现有的连接。', None, 10054, None))
2024-03-06 16:57:58,224 ERROR   Thread-26 :57348 [internal_api.py:upload_file():1642] upload_file request headers: {'User-Agent': 'python-requests/2.31.0', 'Accept-Encoding': 'gzip, deflate', 'Accept': '*/*', 'Connection': 'keep-alive', 'Content-Length': '1252'}
2024-03-06 16:57:58,224 ERROR   Thread-26 :57348 [internal_api.py:upload_file():1644] upload_file response body: 
2024-03-06 17:01:19,312 INFO    Thread-22 :57348 [upload_job.py:push():132] Uploaded file C:\Users\19086\AppData\Local\Temp\tmp_eiuy3gowandb\3r5757mg-wandb-metadata.json
2024-03-06 17:03:57,786 ERROR   Thread-26 :57348 [internal_api.py:upload_file():1640] upload_file exception https://storage.googleapis.com/wandb-production.appspot.com/shahwaiz/UNet-DAS/1hl4cn36/requirements.txt?Expires=1709796589&GoogleAccessId=gorilla-files-url-signer-man%40wandb-production.iam.gserviceaccount.com&Signature=TWM77nhE6PdyHkEs%2FdPIu0Z6PMu4QmRfQ3UuXP%2FUuAZ2kot4bUvryRPA05onYecXzJyqCwegqIQNPIMfUfLW8ITv1TfKaMCThBOXixXBJPPWLmybEdUKq1n2EY18yoDk%2Bp0cthglEuPHz7ytkM3XTiTRDKQEX0hD%2BsYYvDEPXyVQrXC67HBZHp3Ynr1Dfm6YuJ4E62EaknIDsMBMwLYAfRlREUKMsF8WlTZzt7g1ThbtM3Yj42zrx%2Fqd%2FFQEoNvACowUssKf1eTFJv9B8maKbMgM%2FeQkMKdUKm0dyu36H9s5GFuJmnKdD4kxIqNPjoPZwZNMw6WRqskNSNYuT0rkqA%3D%3D: ('Connection aborted.', ConnectionResetError(10054, '远程主机强迫关闭了一个现有的连接。', None, 10054, None))
2024-03-06 17:03:57,786 ERROR   Thread-26 :57348 [internal_api.py:upload_file():1642] upload_file request headers: {'User-Agent': 'python-requests/2.31.0', 'Accept-Encoding': 'gzip, deflate', 'Accept': '*/*', 'Connection': 'keep-alive', 'Content-Length': '1252'}
2024-03-06 17:03:57,786 ERROR   Thread-26 :57348 [internal_api.py:upload_file():1644] upload_file response body: 
2024-03-06 17:09:58,261 ERROR   Thread-26 :57348 [internal_api.py:upload_file():1640] upload_file exception https://storage.googleapis.com/wandb-production.appspot.com/shahwaiz/UNet-DAS/1hl4cn36/requirements.txt?Expires=1709796589&GoogleAccessId=gorilla-files-url-signer-man%40wandb-production.iam.gserviceaccount.com&Signature=TWM77nhE6PdyHkEs%2FdPIu0Z6PMu4QmRfQ3UuXP%2FUuAZ2kot4bUvryRPA05onYecXzJyqCwegqIQNPIMfUfLW8ITv1TfKaMCThBOXixXBJPPWLmybEdUKq1n2EY18yoDk%2Bp0cthglEuPHz7ytkM3XTiTRDKQEX0hD%2BsYYvDEPXyVQrXC67HBZHp3Ynr1Dfm6YuJ4E62EaknIDsMBMwLYAfRlREUKMsF8WlTZzt7g1ThbtM3Yj42zrx%2Fqd%2FFQEoNvACowUssKf1eTFJv9B8maKbMgM%2FeQkMKdUKm0dyu36H9s5GFuJmnKdD4kxIqNPjoPZwZNMw6WRqskNSNYuT0rkqA%3D%3D: ('Connection aborted.', ConnectionResetError(10054, '远程主机强迫关闭了一个现有的连接。', None, 10054, None))
2024-03-06 17:09:58,261 ERROR   Thread-26 :57348 [internal_api.py:upload_file():1642] upload_file request headers: {'User-Agent': 'python-requests/2.31.0', 'Accept-Encoding': 'gzip, deflate', 'Accept': '*/*', 'Connection': 'keep-alive', 'Content-Length': '1252'}
2024-03-06 17:09:58,262 ERROR   Thread-26 :57348 [internal_api.py:upload_file():1644] upload_file response body: 
2024-03-06 17:15:32,416 INFO    Thread-26 :57348 [upload_job.py:push():132] Uploaded file .\wandb\run-20240306_152917-1hl4cn36\files\requirements.txt
2024-03-06 17:15:32,623 INFO    Thread-15 :57348 [sender.py:transition_state():392] send defer: 8
2024-03-06 17:15:33,683 INFO    MainThread:57348 [internal.py:handle_exit():80] Internal process exited
