2024-03-06 13:54:39,051 INFO    MainThread:52708 [internal.py:wandb_internal():90] W&B internal server running at pid: 52708, started at: 2024-03-06 13:54:39.051104
2024-03-06 13:54:39,055 INFO    WriterThread:52708 [datastore.py:open_for_write():75] open: .\wandb\run-20240306_135436-fxayqnmn\run-fxayqnmn.wandb
2024-03-06 13:54:39,061 DEBUG   SenderThread:52708 [sender.py:send():235] send: header
2024-03-06 13:54:39,061 DEBUG   SenderThread:52708 [sender.py:send():235] send: run
2024-03-06 13:54:39,066 INFO    SenderThread:52708 [sender.py:_maybe_setup_resume():492] checking resume status for None/UNet-DAS/fxayqnmn
2024-03-06 13:54:52,812 DEBUG   HandlerThread:52708 [handler.py:handle_request():141] handle_request: check_version
2024-03-06 13:54:52,851 INFO    SenderThread:52708 [dir_watcher.py:__init__():205] watching files in: .\wandb\run-20240306_135436-fxayqnmn\files
2024-03-06 13:54:52,851 INFO    SenderThread:52708 [sender.py:_start_run_threads():812] run started: fxayqnmn with start time 1709704477
2024-03-06 13:54:52,851 DEBUG   SenderThread:52708 [sender.py:send():235] send: summary
2024-03-06 13:54:52,852 INFO    SenderThread:52708 [sender.py:_save_file():949] saving file wandb-summary.json with policy end
2024-03-06 13:54:52,853 DEBUG   SenderThread:52708 [sender.py:send_request():249] send_request: check_version
2024-03-06 13:54:53,745 DEBUG   HandlerThread:52708 [handler.py:handle_request():141] handle_request: run_start
2024-03-06 13:54:53,774 DEBUG   HandlerThread:52708 [meta.py:__init__():35] meta init
2024-03-06 13:54:53,774 DEBUG   HandlerThread:52708 [meta.py:__init__():49] meta init done
2024-03-06 13:54:53,775 DEBUG   HandlerThread:52708 [meta.py:probe():209] probe
2024-03-06 13:54:53,816 DEBUG   HandlerThread:52708 [meta.py:_setup_git():199] setup git
2024-03-06 13:54:53,863 INFO    Thread-16 :52708 [dir_watcher.py:_on_file_created():256] file/dir created: .\wandb\run-20240306_135436-fxayqnmn\files\wandb-summary.json
2024-03-06 13:54:53,977 DEBUG   HandlerThread:52708 [meta.py:_setup_git():206] setup git done
2024-03-06 13:54:53,977 DEBUG   HandlerThread:52708 [meta.py:_save_pip():53] save pip
2024-03-06 13:54:53,978 DEBUG   HandlerThread:52708 [meta.py:_save_pip():67] save pip done
2024-03-06 13:54:53,979 DEBUG   HandlerThread:52708 [meta.py:_save_conda():74] save conda
2024-03-06 13:54:54,871 INFO    Thread-16 :52708 [dir_watcher.py:_on_file_created():256] file/dir created: .\wandb\run-20240306_135436-fxayqnmn\files\requirements.txt
2024-03-06 13:54:54,872 INFO    Thread-16 :52708 [dir_watcher.py:_on_file_created():256] file/dir created: .\wandb\run-20240306_135436-fxayqnmn\files\conda-environment.yaml
2024-03-06 13:54:57,883 INFO    Thread-16 :52708 [dir_watcher.py:_on_file_modified():269] file/dir modified: .\wandb\run-20240306_135436-fxayqnmn\files\conda-environment.yaml
2024-03-06 13:54:57,917 DEBUG   HandlerThread:52708 [meta.py:_save_conda():84] save conda done
2024-03-06 13:54:57,917 DEBUG   HandlerThread:52708 [meta.py:probe():247] probe done
2024-03-06 13:54:58,009 DEBUG   SenderThread:52708 [sender.py:send():235] send: files
2024-03-06 13:54:58,009 DEBUG   HandlerThread:52708 [handler.py:handle_request():141] handle_request: stop_status
2024-03-06 13:54:58,010 INFO    SenderThread:52708 [sender.py:_save_file():949] saving file wandb-metadata.json with policy now
2024-03-06 13:54:58,011 DEBUG   SenderThread:52708 [sender.py:send_request():249] send_request: stop_status
2024-03-06 13:54:58,893 INFO    Thread-16 :52708 [dir_watcher.py:_on_file_created():256] file/dir created: .\wandb\run-20240306_135436-fxayqnmn\files\wandb-metadata.json
2024-03-06 13:54:58,893 INFO    Thread-16 :52708 [dir_watcher.py:_on_file_created():256] file/dir created: .\wandb\run-20240306_135436-fxayqnmn\files\output.log
2024-03-06 13:54:59,375 DEBUG   SenderThread:52708 [sender.py:send():235] send: telemetry
2024-03-06 13:54:59,375 DEBUG   SenderThread:52708 [sender.py:send():235] send: metric
2024-03-06 13:54:59,375 DEBUG   SenderThread:52708 [sender.py:send():235] send: telemetry
2024-03-06 13:54:59,376 DEBUG   SenderThread:52708 [sender.py:send():235] send: metric
2024-03-06 13:54:59,376 WARNING SenderThread:52708 [sender.py:send_metric():905] Seen metric with glob (shouldn't happen)
2024-03-06 13:54:59,376 DEBUG   SenderThread:52708 [sender.py:send():235] send: config
2024-03-06 13:55:00,061 ERROR   Thread-22 :52708 [internal_api.py:upload_file():1640] upload_file exception https://storage.googleapis.com/wandb-production.appspot.com/shahwaiz/UNet-DAS/fxayqnmn/wandb-metadata.json?Expires=1709790899&GoogleAccessId=gorilla-files-url-signer-man%40wandb-production.iam.gserviceaccount.com&Signature=mQQwc7RkYe4oDv%2FP0AwJNS9yfztXTIC4FJ6DarVoqRt4oFn0fd459isQGZeCDXAOQ%2F75SC51exHTkIuWfZ9XNs9eHxM51%2BTOXfHEwXhMfocf0q2x5Y0slBhydQbYuoQiMyfnLfe6ybor1bieRvKiEUpI6KDP0N02YledMJKd4cVb3BI1wHLmdafV7rDToWO3CpTG%2BaWoMIozrhfDInuqVhSOZZK73FGTeffR6ineDqqTlDTL%2BbBycevPjz4QoAiyHDC9o6tc7LMKgtZciplVvBPxFmq6Jz2NA%2BiydISOrvOiLOReDvs%2BX2sg%2BDGiCJ1uOtublCiqn1RlXWNbEHGaQA%3D%3D: ('Connection aborted.', ConnectionResetError(10054, '远程主机强迫关闭了一个现有的连接。', None, 10054, None))
2024-03-06 13:55:00,061 ERROR   Thread-22 :52708 [internal_api.py:upload_file():1642] upload_file request headers: {'User-Agent': 'python-requests/2.31.0', 'Accept-Encoding': 'gzip, deflate', 'Accept': '*/*', 'Connection': 'keep-alive', 'Content-Length': '766'}
2024-03-06 13:55:00,062 ERROR   Thread-22 :52708 [internal_api.py:upload_file():1644] upload_file response body: 
2024-03-06 13:55:00,908 INFO    Thread-16 :52708 [dir_watcher.py:_on_file_modified():269] file/dir modified: .\wandb\run-20240306_135436-fxayqnmn\files\output.log
2024-03-06 13:55:01,693 ERROR   Thread-22 :52708 [internal_api.py:upload_file():1640] upload_file exception https://storage.googleapis.com/wandb-production.appspot.com/shahwaiz/UNet-DAS/fxayqnmn/wandb-metadata.json?Expires=1709790899&GoogleAccessId=gorilla-files-url-signer-man%40wandb-production.iam.gserviceaccount.com&Signature=mQQwc7RkYe4oDv%2FP0AwJNS9yfztXTIC4FJ6DarVoqRt4oFn0fd459isQGZeCDXAOQ%2F75SC51exHTkIuWfZ9XNs9eHxM51%2BTOXfHEwXhMfocf0q2x5Y0slBhydQbYuoQiMyfnLfe6ybor1bieRvKiEUpI6KDP0N02YledMJKd4cVb3BI1wHLmdafV7rDToWO3CpTG%2BaWoMIozrhfDInuqVhSOZZK73FGTeffR6ineDqqTlDTL%2BbBycevPjz4QoAiyHDC9o6tc7LMKgtZciplVvBPxFmq6Jz2NA%2BiydISOrvOiLOReDvs%2BX2sg%2BDGiCJ1uOtublCiqn1RlXWNbEHGaQA%3D%3D: ('Connection aborted.', ConnectionResetError(10054, '远程主机强迫关闭了一个现有的连接。', None, 10054, None))
2024-03-06 13:55:01,693 ERROR   Thread-22 :52708 [internal_api.py:upload_file():1642] upload_file request headers: {'User-Agent': 'python-requests/2.31.0', 'Accept-Encoding': 'gzip, deflate', 'Accept': '*/*', 'Connection': 'keep-alive', 'Content-Length': '766'}
2024-03-06 13:55:01,693 ERROR   Thread-22 :52708 [internal_api.py:upload_file():1644] upload_file response body: 
2024-03-06 13:55:04,451 ERROR   Thread-22 :52708 [internal_api.py:upload_file():1640] upload_file exception https://storage.googleapis.com/wandb-production.appspot.com/shahwaiz/UNet-DAS/fxayqnmn/wandb-metadata.json?Expires=1709790899&GoogleAccessId=gorilla-files-url-signer-man%40wandb-production.iam.gserviceaccount.com&Signature=mQQwc7RkYe4oDv%2FP0AwJNS9yfztXTIC4FJ6DarVoqRt4oFn0fd459isQGZeCDXAOQ%2F75SC51exHTkIuWfZ9XNs9eHxM51%2BTOXfHEwXhMfocf0q2x5Y0slBhydQbYuoQiMyfnLfe6ybor1bieRvKiEUpI6KDP0N02YledMJKd4cVb3BI1wHLmdafV7rDToWO3CpTG%2BaWoMIozrhfDInuqVhSOZZK73FGTeffR6ineDqqTlDTL%2BbBycevPjz4QoAiyHDC9o6tc7LMKgtZciplVvBPxFmq6Jz2NA%2BiydISOrvOiLOReDvs%2BX2sg%2BDGiCJ1uOtublCiqn1RlXWNbEHGaQA%3D%3D: ('Connection aborted.', ConnectionResetError(10054, '远程主机强迫关闭了一个现有的连接。', None, 10054, None))
2024-03-06 13:55:04,452 ERROR   Thread-22 :52708 [internal_api.py:upload_file():1642] upload_file request headers: {'User-Agent': 'python-requests/2.31.0', 'Accept-Encoding': 'gzip, deflate', 'Accept': '*/*', 'Connection': 'keep-alive', 'Content-Length': '766'}
2024-03-06 13:55:04,452 ERROR   Thread-22 :52708 [internal_api.py:upload_file():1644] upload_file response body: 
2024-03-06 13:55:04,452 ERROR   Thread-22 :52708 [retry.py:__call__():126] Retry attempt failed:
Traceback (most recent call last):
  File "E:\Anaconda\envs\unet\lib\site-packages\urllib3\connectionpool.py", line 793, in urlopen
    response = self._make_request(
  File "E:\Anaconda\envs\unet\lib\site-packages\urllib3\connectionpool.py", line 491, in _make_request
    raise new_e
  File "E:\Anaconda\envs\unet\lib\site-packages\urllib3\connectionpool.py", line 467, in _make_request
    self._validate_conn(conn)
  File "E:\Anaconda\envs\unet\lib\site-packages\urllib3\connectionpool.py", line 1099, in _validate_conn
    conn.connect()
  File "E:\Anaconda\envs\unet\lib\site-packages\urllib3\connection.py", line 653, in connect
    sock_and_verified = _ssl_wrap_socket_and_match_hostname(
  File "E:\Anaconda\envs\unet\lib\site-packages\urllib3\connection.py", line 806, in _ssl_wrap_socket_and_match_hostname
    ssl_sock = ssl_wrap_socket(
  File "E:\Anaconda\envs\unet\lib\site-packages\urllib3\util\ssl_.py", line 465, in ssl_wrap_socket
    ssl_sock = _ssl_wrap_socket_impl(sock, context, tls_in_tls, server_hostname)
  File "E:\Anaconda\envs\unet\lib\site-packages\urllib3\util\ssl_.py", line 509, in _ssl_wrap_socket_impl
    return ssl_context.wrap_socket(sock, server_hostname=server_hostname)
  File "E:\Anaconda\envs\unet\lib\ssl.py", line 500, in wrap_socket
    return self.sslsocket_class._create(
  File "E:\Anaconda\envs\unet\lib\ssl.py", line 1073, in _create
    self.do_handshake()
  File "E:\Anaconda\envs\unet\lib\ssl.py", line 1342, in do_handshake
    self._sslobj.do_handshake()
ConnectionResetError: [WinError 10054] 远程主机强迫关闭了一个现有的连接。

During handling of the above exception, another exception occurred:

Traceback (most recent call last):
  File "E:\Anaconda\envs\unet\lib\site-packages\requests\adapters.py", line 486, in send
    resp = conn.urlopen(
  File "E:\Anaconda\envs\unet\lib\site-packages\urllib3\connectionpool.py", line 847, in urlopen
    retries = retries.increment(
  File "E:\Anaconda\envs\unet\lib\site-packages\urllib3\util\retry.py", line 470, in increment
    raise reraise(type(error), error, _stacktrace)
  File "E:\Anaconda\envs\unet\lib\site-packages\urllib3\util\util.py", line 38, in reraise
    raise value.with_traceback(tb)
  File "E:\Anaconda\envs\unet\lib\site-packages\urllib3\connectionpool.py", line 793, in urlopen
    response = self._make_request(
  File "E:\Anaconda\envs\unet\lib\site-packages\urllib3\connectionpool.py", line 491, in _make_request
    raise new_e
  File "E:\Anaconda\envs\unet\lib\site-packages\urllib3\connectionpool.py", line 467, in _make_request
    self._validate_conn(conn)
  File "E:\Anaconda\envs\unet\lib\site-packages\urllib3\connectionpool.py", line 1099, in _validate_conn
    conn.connect()
  File "E:\Anaconda\envs\unet\lib\site-packages\urllib3\connection.py", line 653, in connect
    sock_and_verified = _ssl_wrap_socket_and_match_hostname(
  File "E:\Anaconda\envs\unet\lib\site-packages\urllib3\connection.py", line 806, in _ssl_wrap_socket_and_match_hostname
    ssl_sock = ssl_wrap_socket(
  File "E:\Anaconda\envs\unet\lib\site-packages\urllib3\util\ssl_.py", line 465, in ssl_wrap_socket
    ssl_sock = _ssl_wrap_socket_impl(sock, context, tls_in_tls, server_hostname)
  File "E:\Anaconda\envs\unet\lib\site-packages\urllib3\util\ssl_.py", line 509, in _ssl_wrap_socket_impl
    return ssl_context.wrap_socket(sock, server_hostname=server_hostname)
  File "E:\Anaconda\envs\unet\lib\ssl.py", line 500, in wrap_socket
    return self.sslsocket_class._create(
  File "E:\Anaconda\envs\unet\lib\ssl.py", line 1073, in _create
    self.do_handshake()
  File "E:\Anaconda\envs\unet\lib\ssl.py", line 1342, in do_handshake
    self._sslobj.do_handshake()
urllib3.exceptions.ProtocolError: ('Connection aborted.', ConnectionResetError(10054, '远程主机强迫关闭了一个现有的连接。', None, 10054, None))

During handling of the above exception, another exception occurred:

Traceback (most recent call last):
  File "C:\Users\19086\AppData\Roaming\Python\Python38\site-packages\wandb\sdk\internal\internal_api.py", line 1637, in upload_file
    response = requests.put(url, data=progress, headers=extra_headers)
  File "E:\Anaconda\envs\unet\lib\site-packages\requests\api.py", line 130, in put
    return request("put", url, data=data, **kwargs)
  File "E:\Anaconda\envs\unet\lib\site-packages\requests\api.py", line 59, in request
    return session.request(method=method, url=url, **kwargs)
  File "E:\Anaconda\envs\unet\lib\site-packages\requests\sessions.py", line 589, in request
    resp = self.send(prep, **send_kwargs)
  File "E:\Anaconda\envs\unet\lib\site-packages\requests\sessions.py", line 703, in send
    r = adapter.send(request, **kwargs)
  File "E:\Anaconda\envs\unet\lib\site-packages\requests\adapters.py", line 501, in send
    raise ConnectionError(err, request=request)
requests.exceptions.ConnectionError: ('Connection aborted.', ConnectionResetError(10054, '远程主机强迫关闭了一个现有的连接。', None, 10054, None))

During handling of the above exception, another exception occurred:

Traceback (most recent call last):
  File "C:\Users\19086\AppData\Roaming\Python\Python38\site-packages\wandb\sdk\lib\retry.py", line 102, in __call__
    result = self._call_fn(*args, **kwargs)
  File "C:\Users\19086\AppData\Roaming\Python\Python38\site-packages\wandb\sdk\internal\internal_api.py", line 1653, in upload_file
    raise e.with_traceback(sys.exc_info()[2])
  File "C:\Users\19086\AppData\Roaming\Python\Python38\site-packages\wandb\sdk\internal\internal_api.py", line 1637, in upload_file
    response = requests.put(url, data=progress, headers=extra_headers)
  File "E:\Anaconda\envs\unet\lib\site-packages\requests\api.py", line 130, in put
    return request("put", url, data=data, **kwargs)
  File "E:\Anaconda\envs\unet\lib\site-packages\requests\api.py", line 59, in request
    return session.request(method=method, url=url, **kwargs)
  File "E:\Anaconda\envs\unet\lib\site-packages\requests\sessions.py", line 589, in request
    resp = self.send(prep, **send_kwargs)
  File "E:\Anaconda\envs\unet\lib\site-packages\requests\sessions.py", line 703, in send
    r = adapter.send(request, **kwargs)
  File "E:\Anaconda\envs\unet\lib\site-packages\requests\adapters.py", line 501, in send
    raise ConnectionError(err, request=request)
wandb.sdk.lib.retry.TransientError: None
2024-03-06 13:55:09,846 ERROR   Thread-22 :52708 [internal_api.py:upload_file():1640] upload_file exception https://storage.googleapis.com/wandb-production.appspot.com/shahwaiz/UNet-DAS/fxayqnmn/wandb-metadata.json?Expires=1709790899&GoogleAccessId=gorilla-files-url-signer-man%40wandb-production.iam.gserviceaccount.com&Signature=mQQwc7RkYe4oDv%2FP0AwJNS9yfztXTIC4FJ6DarVoqRt4oFn0fd459isQGZeCDXAOQ%2F75SC51exHTkIuWfZ9XNs9eHxM51%2BTOXfHEwXhMfocf0q2x5Y0slBhydQbYuoQiMyfnLfe6ybor1bieRvKiEUpI6KDP0N02YledMJKd4cVb3BI1wHLmdafV7rDToWO3CpTG%2BaWoMIozrhfDInuqVhSOZZK73FGTeffR6ineDqqTlDTL%2BbBycevPjz4QoAiyHDC9o6tc7LMKgtZciplVvBPxFmq6Jz2NA%2BiydISOrvOiLOReDvs%2BX2sg%2BDGiCJ1uOtublCiqn1RlXWNbEHGaQA%3D%3D: ('Connection aborted.', ConnectionResetError(10054, '远程主机强迫关闭了一个现有的连接。', None, 10054, None))
2024-03-06 13:55:09,847 ERROR   Thread-22 :52708 [internal_api.py:upload_file():1642] upload_file request headers: {'User-Agent': 'python-requests/2.31.0', 'Accept-Encoding': 'gzip, deflate', 'Accept': '*/*', 'Connection': 'keep-alive', 'Content-Length': '766'}
2024-03-06 13:55:09,847 ERROR   Thread-22 :52708 [internal_api.py:upload_file():1644] upload_file response body: 
2024-03-06 13:55:10,972 INFO    Thread-16 :52708 [dir_watcher.py:_on_file_modified():269] file/dir modified: .\wandb\run-20240306_135436-fxayqnmn\files\config.yaml
2024-03-06 13:55:14,383 DEBUG   HandlerThread:52708 [handler.py:handle_request():141] handle_request: stop_status
2024-03-06 13:55:14,384 DEBUG   SenderThread:52708 [sender.py:send_request():249] send_request: stop_status
2024-03-06 13:55:19,845 ERROR   Thread-22 :52708 [internal_api.py:upload_file():1640] upload_file exception https://storage.googleapis.com/wandb-production.appspot.com/shahwaiz/UNet-DAS/fxayqnmn/wandb-metadata.json?Expires=1709790899&GoogleAccessId=gorilla-files-url-signer-man%40wandb-production.iam.gserviceaccount.com&Signature=mQQwc7RkYe4oDv%2FP0AwJNS9yfztXTIC4FJ6DarVoqRt4oFn0fd459isQGZeCDXAOQ%2F75SC51exHTkIuWfZ9XNs9eHxM51%2BTOXfHEwXhMfocf0q2x5Y0slBhydQbYuoQiMyfnLfe6ybor1bieRvKiEUpI6KDP0N02YledMJKd4cVb3BI1wHLmdafV7rDToWO3CpTG%2BaWoMIozrhfDInuqVhSOZZK73FGTeffR6ineDqqTlDTL%2BbBycevPjz4QoAiyHDC9o6tc7LMKgtZciplVvBPxFmq6Jz2NA%2BiydISOrvOiLOReDvs%2BX2sg%2BDGiCJ1uOtublCiqn1RlXWNbEHGaQA%3D%3D: ('Connection aborted.', ConnectionResetError(10054, '远程主机强迫关闭了一个现有的连接。', None, 10054, None))
2024-03-06 13:55:19,845 ERROR   Thread-22 :52708 [internal_api.py:upload_file():1642] upload_file request headers: {'User-Agent': 'python-requests/2.31.0', 'Accept-Encoding': 'gzip, deflate', 'Accept': '*/*', 'Connection': 'keep-alive', 'Content-Length': '766'}
2024-03-06 13:55:19,845 ERROR   Thread-22 :52708 [internal_api.py:upload_file():1644] upload_file response body: 
2024-03-06 13:55:24,609 DEBUG   SenderThread:52708 [sender.py:send():235] send: stats
2024-03-06 13:55:34,393 DEBUG   HandlerThread:52708 [handler.py:handle_request():141] handle_request: stop_status
2024-03-06 13:55:34,393 DEBUG   SenderThread:52708 [sender.py:send_request():249] send_request: stop_status
2024-03-06 13:55:38,131 ERROR   Thread-22 :52708 [internal_api.py:upload_file():1640] upload_file exception https://storage.googleapis.com/wandb-production.appspot.com/shahwaiz/UNet-DAS/fxayqnmn/wandb-metadata.json?Expires=1709790899&GoogleAccessId=gorilla-files-url-signer-man%40wandb-production.iam.gserviceaccount.com&Signature=mQQwc7RkYe4oDv%2FP0AwJNS9yfztXTIC4FJ6DarVoqRt4oFn0fd459isQGZeCDXAOQ%2F75SC51exHTkIuWfZ9XNs9eHxM51%2BTOXfHEwXhMfocf0q2x5Y0slBhydQbYuoQiMyfnLfe6ybor1bieRvKiEUpI6KDP0N02YledMJKd4cVb3BI1wHLmdafV7rDToWO3CpTG%2BaWoMIozrhfDInuqVhSOZZK73FGTeffR6ineDqqTlDTL%2BbBycevPjz4QoAiyHDC9o6tc7LMKgtZciplVvBPxFmq6Jz2NA%2BiydISOrvOiLOReDvs%2BX2sg%2BDGiCJ1uOtublCiqn1RlXWNbEHGaQA%3D%3D: ('Connection aborted.', ConnectionResetError(10054, '远程主机强迫关闭了一个现有的连接。', None, 10054, None))
2024-03-06 13:55:38,131 ERROR   Thread-22 :52708 [internal_api.py:upload_file():1642] upload_file request headers: {'User-Agent': 'python-requests/2.31.0', 'Accept-Encoding': 'gzip, deflate', 'Accept': '*/*', 'Connection': 'keep-alive', 'Content-Length': '766'}
2024-03-06 13:55:38,132 ERROR   Thread-22 :52708 [internal_api.py:upload_file():1644] upload_file response body: 
2024-03-06 13:55:50,776 DEBUG   HandlerThread:52708 [handler.py:handle_request():141] handle_request: stop_status
2024-03-06 13:55:50,777 DEBUG   SenderThread:52708 [sender.py:send_request():249] send_request: stop_status
2024-03-06 13:55:57,468 DEBUG   SenderThread:52708 [sender.py:send():235] send: stats
2024-03-06 13:56:07,058 DEBUG   HandlerThread:52708 [handler.py:handle_request():141] handle_request: stop_status
2024-03-06 13:56:07,059 DEBUG   SenderThread:52708 [sender.py:send_request():249] send_request: stop_status
2024-03-06 13:56:12,737 ERROR   Thread-22 :52708 [internal_api.py:upload_file():1640] upload_file exception https://storage.googleapis.com/wandb-production.appspot.com/shahwaiz/UNet-DAS/fxayqnmn/wandb-metadata.json?Expires=1709790899&GoogleAccessId=gorilla-files-url-signer-man%40wandb-production.iam.gserviceaccount.com&Signature=mQQwc7RkYe4oDv%2FP0AwJNS9yfztXTIC4FJ6DarVoqRt4oFn0fd459isQGZeCDXAOQ%2F75SC51exHTkIuWfZ9XNs9eHxM51%2BTOXfHEwXhMfocf0q2x5Y0slBhydQbYuoQiMyfnLfe6ybor1bieRvKiEUpI6KDP0N02YledMJKd4cVb3BI1wHLmdafV7rDToWO3CpTG%2BaWoMIozrhfDInuqVhSOZZK73FGTeffR6ineDqqTlDTL%2BbBycevPjz4QoAiyHDC9o6tc7LMKgtZciplVvBPxFmq6Jz2NA%2BiydISOrvOiLOReDvs%2BX2sg%2BDGiCJ1uOtublCiqn1RlXWNbEHGaQA%3D%3D: ('Connection aborted.', ConnectionResetError(10054, '远程主机强迫关闭了一个现有的连接。', None, 10054, None))
2024-03-06 13:56:12,738 ERROR   Thread-22 :52708 [internal_api.py:upload_file():1642] upload_file request headers: {'User-Agent': 'python-requests/2.31.0', 'Accept-Encoding': 'gzip, deflate', 'Accept': '*/*', 'Connection': 'keep-alive', 'Content-Length': '766'}
2024-03-06 13:56:12,738 ERROR   Thread-22 :52708 [internal_api.py:upload_file():1644] upload_file response body: 
2024-03-06 13:56:23,373 DEBUG   HandlerThread:52708 [handler.py:handle_request():141] handle_request: stop_status
2024-03-06 13:56:23,373 DEBUG   SenderThread:52708 [sender.py:send_request():249] send_request: stop_status
2024-03-06 13:56:30,262 DEBUG   SenderThread:52708 [sender.py:send():235] send: stats
2024-03-06 13:56:39,719 DEBUG   HandlerThread:52708 [handler.py:handle_request():141] handle_request: stop_status
2024-03-06 13:56:39,720 DEBUG   SenderThread:52708 [sender.py:send_request():249] send_request: stop_status
2024-03-06 13:56:56,018 DEBUG   HandlerThread:52708 [handler.py:handle_request():141] handle_request: stop_status
2024-03-06 13:56:56,019 DEBUG   SenderThread:52708 [sender.py:send_request():249] send_request: stop_status
2024-03-06 13:57:03,090 DEBUG   SenderThread:52708 [sender.py:send():235] send: stats
2024-03-06 13:57:12,364 DEBUG   HandlerThread:52708 [handler.py:handle_request():141] handle_request: stop_status
2024-03-06 13:57:12,364 DEBUG   SenderThread:52708 [sender.py:send_request():249] send_request: stop_status
2024-03-06 13:57:30,030 ERROR   Thread-22 :52708 [internal_api.py:upload_file():1640] upload_file exception https://storage.googleapis.com/wandb-production.appspot.com/shahwaiz/UNet-DAS/fxayqnmn/wandb-metadata.json?Expires=1709790899&GoogleAccessId=gorilla-files-url-signer-man%40wandb-production.iam.gserviceaccount.com&Signature=mQQwc7RkYe4oDv%2FP0AwJNS9yfztXTIC4FJ6DarVoqRt4oFn0fd459isQGZeCDXAOQ%2F75SC51exHTkIuWfZ9XNs9eHxM51%2BTOXfHEwXhMfocf0q2x5Y0slBhydQbYuoQiMyfnLfe6ybor1bieRvKiEUpI6KDP0N02YledMJKd4cVb3BI1wHLmdafV7rDToWO3CpTG%2BaWoMIozrhfDInuqVhSOZZK73FGTeffR6ineDqqTlDTL%2BbBycevPjz4QoAiyHDC9o6tc7LMKgtZciplVvBPxFmq6Jz2NA%2BiydISOrvOiLOReDvs%2BX2sg%2BDGiCJ1uOtublCiqn1RlXWNbEHGaQA%3D%3D: ('Connection aborted.', ConnectionResetError(10054, '远程主机强迫关闭了一个现有的连接。', None, 10054, None))
2024-03-06 13:57:30,030 ERROR   Thread-22 :52708 [internal_api.py:upload_file():1642] upload_file request headers: {'User-Agent': 'python-requests/2.31.0', 'Accept-Encoding': 'gzip, deflate', 'Accept': '*/*', 'Connection': 'keep-alive', 'Content-Length': '766'}
2024-03-06 13:57:30,031 ERROR   Thread-22 :52708 [internal_api.py:upload_file():1644] upload_file response body: 
2024-03-06 13:57:32,372 DEBUG   HandlerThread:52708 [handler.py:handle_request():141] handle_request: stop_status
2024-03-06 13:57:32,373 DEBUG   SenderThread:52708 [sender.py:send_request():249] send_request: stop_status
2024-03-06 13:57:35,937 DEBUG   SenderThread:52708 [sender.py:send():235] send: stats
2024-03-06 13:57:50,051 DEBUG   HandlerThread:52708 [handler.py:handle_request():141] handle_request: stop_status
2024-03-06 13:57:50,051 DEBUG   SenderThread:52708 [sender.py:send_request():249] send_request: stop_status
2024-03-06 13:58:06,415 DEBUG   HandlerThread:52708 [handler.py:handle_request():141] handle_request: stop_status
2024-03-06 13:58:06,416 DEBUG   SenderThread:52708 [sender.py:send_request():249] send_request: stop_status
2024-03-06 13:58:08,780 DEBUG   SenderThread:52708 [sender.py:send():235] send: stats
2024-03-06 13:58:22,872 DEBUG   HandlerThread:52708 [handler.py:handle_request():141] handle_request: stop_status
2024-03-06 13:58:22,873 DEBUG   SenderThread:52708 [sender.py:send_request():249] send_request: stop_status
2024-03-06 13:58:39,541 DEBUG   HandlerThread:52708 [handler.py:handle_request():141] handle_request: stop_status
2024-03-06 13:58:39,542 DEBUG   SenderThread:52708 [sender.py:send_request():249] send_request: stop_status
2024-03-06 13:58:41,538 DEBUG   SenderThread:52708 [sender.py:send():235] send: stats
2024-03-06 13:58:55,903 DEBUG   HandlerThread:52708 [handler.py:handle_request():141] handle_request: stop_status
2024-03-06 13:58:55,904 DEBUG   SenderThread:52708 [sender.py:send_request():249] send_request: stop_status
2024-03-06 13:59:12,195 DEBUG   HandlerThread:52708 [handler.py:handle_request():141] handle_request: stop_status
2024-03-06 13:59:12,197 DEBUG   SenderThread:52708 [sender.py:send_request():249] send_request: stop_status
2024-03-06 13:59:14,519 DEBUG   SenderThread:52708 [sender.py:send():235] send: stats
2024-03-06 13:59:28,560 DEBUG   HandlerThread:52708 [handler.py:handle_request():141] handle_request: stop_status
2024-03-06 13:59:28,561 DEBUG   SenderThread:52708 [sender.py:send_request():249] send_request: stop_status
2024-03-06 13:59:45,001 DEBUG   HandlerThread:52708 [handler.py:handle_request():141] handle_request: stop_status
2024-03-06 13:59:45,002 DEBUG   SenderThread:52708 [sender.py:send_request():249] send_request: stop_status
2024-03-06 13:59:47,487 DEBUG   SenderThread:52708 [sender.py:send():235] send: stats
2024-03-06 13:59:58,424 ERROR   Thread-22 :52708 [internal_api.py:upload_file():1640] upload_file exception https://storage.googleapis.com/wandb-production.appspot.com/shahwaiz/UNet-DAS/fxayqnmn/wandb-metadata.json?Expires=1709790899&GoogleAccessId=gorilla-files-url-signer-man%40wandb-production.iam.gserviceaccount.com&Signature=mQQwc7RkYe4oDv%2FP0AwJNS9yfztXTIC4FJ6DarVoqRt4oFn0fd459isQGZeCDXAOQ%2F75SC51exHTkIuWfZ9XNs9eHxM51%2BTOXfHEwXhMfocf0q2x5Y0slBhydQbYuoQiMyfnLfe6ybor1bieRvKiEUpI6KDP0N02YledMJKd4cVb3BI1wHLmdafV7rDToWO3CpTG%2BaWoMIozrhfDInuqVhSOZZK73FGTeffR6ineDqqTlDTL%2BbBycevPjz4QoAiyHDC9o6tc7LMKgtZciplVvBPxFmq6Jz2NA%2BiydISOrvOiLOReDvs%2BX2sg%2BDGiCJ1uOtublCiqn1RlXWNbEHGaQA%3D%3D: ('Connection aborted.', ConnectionResetError(10054, '远程主机强迫关闭了一个现有的连接。', None, 10054, None))
2024-03-06 13:59:58,424 ERROR   Thread-22 :52708 [internal_api.py:upload_file():1642] upload_file request headers: {'User-Agent': 'python-requests/2.31.0', 'Accept-Encoding': 'gzip, deflate', 'Accept': '*/*', 'Connection': 'keep-alive', 'Content-Length': '766'}
2024-03-06 13:59:58,424 ERROR   Thread-22 :52708 [internal_api.py:upload_file():1644] upload_file response body: 
2024-03-06 14:00:01,261 DEBUG   HandlerThread:52708 [handler.py:handle_request():141] handle_request: stop_status
2024-03-06 14:00:01,262 DEBUG   SenderThread:52708 [sender.py:send_request():249] send_request: stop_status
2024-03-06 14:00:18,790 DEBUG   HandlerThread:52708 [handler.py:handle_request():141] handle_request: stop_status
2024-03-06 14:00:18,791 DEBUG   SenderThread:52708 [sender.py:send_request():249] send_request: stop_status
2024-03-06 14:00:20,511 DEBUG   SenderThread:52708 [sender.py:send():235] send: stats
2024-03-06 14:00:35,097 DEBUG   HandlerThread:52708 [handler.py:handle_request():141] handle_request: stop_status
2024-03-06 14:00:35,098 DEBUG   SenderThread:52708 [sender.py:send_request():249] send_request: stop_status
2024-03-06 14:00:51,430 DEBUG   HandlerThread:52708 [handler.py:handle_request():141] handle_request: stop_status
2024-03-06 14:00:51,431 DEBUG   SenderThread:52708 [sender.py:send_request():249] send_request: stop_status
2024-03-06 14:00:54,040 DEBUG   SenderThread:52708 [sender.py:send():235] send: stats
2024-03-06 14:01:09,047 DEBUG   HandlerThread:52708 [handler.py:handle_request():141] handle_request: stop_status
2024-03-06 14:01:09,048 DEBUG   SenderThread:52708 [sender.py:send_request():249] send_request: stop_status
2024-03-06 14:01:25,414 DEBUG   HandlerThread:52708 [handler.py:handle_request():141] handle_request: stop_status
2024-03-06 14:01:25,414 DEBUG   SenderThread:52708 [sender.py:send_request():249] send_request: stop_status
2024-03-06 14:01:27,120 DEBUG   SenderThread:52708 [sender.py:send():235] send: stats
2024-03-06 14:01:42,129 DEBUG   HandlerThread:52708 [handler.py:handle_request():141] handle_request: stop_status
2024-03-06 14:01:42,130 DEBUG   SenderThread:52708 [sender.py:send_request():249] send_request: stop_status
2024-03-06 14:01:58,486 DEBUG   HandlerThread:52708 [handler.py:handle_request():141] handle_request: stop_status
2024-03-06 14:01:58,487 DEBUG   SenderThread:52708 [sender.py:send_request():249] send_request: stop_status
2024-03-06 14:02:00,392 WARNING MainThread:52708 [internal.py:wandb_internal():153] Internal process interrupt: 1
2024-03-06 14:02:00,940 DEBUG   SenderThread:52708 [sender.py:send():235] send: stats
2024-03-06 14:02:05,249 DEBUG   SenderThread:52708 [sender.py:send():235] send: config
2024-03-06 14:02:06,466 INFO    Thread-16 :52708 [dir_watcher.py:_on_file_modified():269] file/dir modified: .\wandb\run-20240306_135436-fxayqnmn\files\output.log
2024-03-06 14:02:15,945 DEBUG   HandlerThread:52708 [handler.py:handle_request():141] handle_request: stop_status
2024-03-06 14:02:15,946 DEBUG   SenderThread:52708 [sender.py:send_request():249] send_request: stop_status
