2024-03-06 13:17:59,397 INFO    MainThread:47368 [internal.py:wandb_internal():90] W&B internal server running at pid: 47368, started at: 2024-03-06 13:17:59.397339
2024-03-06 13:17:59,399 INFO    WriterThread:47368 [datastore.py:open_for_write():75] open: .\wandb\run-20240306_131758-25jringl\run-25jringl.wandb
2024-03-06 13:17:59,402 DEBUG   SenderThread:47368 [sender.py:send():235] send: header
2024-03-06 13:17:59,402 DEBUG   SenderThread:47368 [sender.py:send():235] send: run
2024-03-06 13:17:59,404 INFO    SenderThread:47368 [sender.py:_maybe_setup_resume():492] checking resume status for None/UNet-DAS/25jringl
2024-03-06 13:18:03,910 ERROR   SenderThread:47368 [retry.py:__call__():126] Retry attempt failed:
urllib3.exceptions.SSLError: TLS/SSL connection has been closed (EOF) (_ssl.c:1131)

The above exception was the direct cause of the following exception:

urllib3.exceptions.ProxyError: ('Unable to connect to proxy', SSLError(SSLZeroReturnError(6, 'TLS/SSL connection has been closed (EOF) (_ssl.c:1131)')))

The above exception was the direct cause of the following exception:

Traceback (most recent call last):
  File "E:\Anaconda\envs\unet\lib\site-packages\requests\adapters.py", line 486, in send
    resp = conn.urlopen(
  File "E:\Anaconda\envs\unet\lib\site-packages\urllib3\connectionpool.py", line 847, in urlopen
    retries = retries.increment(
  File "E:\Anaconda\envs\unet\lib\site-packages\urllib3\util\retry.py", line 515, in increment
    raise MaxRetryError(_pool, url, reason) from reason  # type: ignore[arg-type]
urllib3.exceptions.MaxRetryError: HTTPSConnectionPool(host='api.wandb.ai', port=443): Max retries exceeded with url: /graphql (Caused by ProxyError('Unable to connect to proxy', SSLError(SSLZeroReturnError(6, 'TLS/SSL connection has been closed (EOF) (_ssl.c:1131)'))))

During handling of the above exception, another exception occurred:

Traceback (most recent call last):
  File "C:\Users\19086\AppData\Roaming\Python\Python38\site-packages\wandb\sdk\lib\retry.py", line 102, in __call__
    result = self._call_fn(*args, **kwargs)
  File "C:\Users\19086\AppData\Roaming\Python\Python38\site-packages\wandb\sdk\internal\internal_api.py", line 140, in execute
    return self.client.execute(*args, **kwargs)
  File "C:\Users\19086\AppData\Roaming\Python\Python38\site-packages\wandb\vendor\gql-0.2.0\wandb_gql\client.py", line 52, in execute
    result = self._get_result(document, *args, **kwargs)
  File "C:\Users\19086\AppData\Roaming\Python\Python38\site-packages\wandb\vendor\gql-0.2.0\wandb_gql\client.py", line 60, in _get_result
    return self.transport.execute(document, *args, **kwargs)
  File "C:\Users\19086\AppData\Roaming\Python\Python38\site-packages\wandb\vendor\gql-0.2.0\wandb_gql\transport\requests.py", line 38, in execute
    request = requests.post(self.url, **post_args)
  File "E:\Anaconda\envs\unet\lib\site-packages\requests\api.py", line 115, in post
    return request("post", url, data=data, json=json, **kwargs)
  File "E:\Anaconda\envs\unet\lib\site-packages\requests\api.py", line 59, in request
    return session.request(method=method, url=url, **kwargs)
  File "E:\Anaconda\envs\unet\lib\site-packages\requests\sessions.py", line 589, in request
    resp = self.send(prep, **send_kwargs)
  File "E:\Anaconda\envs\unet\lib\site-packages\requests\sessions.py", line 703, in send
    r = adapter.send(request, **kwargs)
  File "E:\Anaconda\envs\unet\lib\site-packages\requests\adapters.py", line 513, in send
    raise ProxyError(e, request=request)
requests.exceptions.ProxyError: HTTPSConnectionPool(host='api.wandb.ai', port=443): Max retries exceeded with url: /graphql (Caused by ProxyError('Unable to connect to proxy', SSLError(SSLZeroReturnError(6, 'TLS/SSL connection has been closed (EOF) (_ssl.c:1131)'))))
2024-03-06 13:18:20,621 DEBUG   HandlerThread:47368 [handler.py:handle_request():141] handle_request: check_version
2024-03-06 13:18:20,630 INFO    SenderThread:47368 [dir_watcher.py:__init__():205] watching files in: .\wandb\run-20240306_131758-25jringl\files
2024-03-06 13:18:20,630 INFO    SenderThread:47368 [sender.py:_start_run_threads():812] run started: 25jringl with start time 1709702278
2024-03-06 13:18:20,630 DEBUG   SenderThread:47368 [sender.py:send():235] send: summary
2024-03-06 13:18:20,631 INFO    SenderThread:47368 [sender.py:_save_file():949] saving file wandb-summary.json with policy end
2024-03-06 13:18:20,631 DEBUG   SenderThread:47368 [sender.py:send_request():249] send_request: check_version
2024-03-06 13:18:21,472 DEBUG   HandlerThread:47368 [handler.py:handle_request():141] handle_request: run_start
2024-03-06 13:18:21,499 DEBUG   HandlerThread:47368 [meta.py:__init__():35] meta init
2024-03-06 13:18:21,499 DEBUG   HandlerThread:47368 [meta.py:__init__():49] meta init done
2024-03-06 13:18:21,499 DEBUG   HandlerThread:47368 [meta.py:probe():209] probe
2024-03-06 13:18:21,507 DEBUG   HandlerThread:47368 [meta.py:_setup_git():199] setup git
2024-03-06 13:18:21,632 INFO    Thread-11 :47368 [dir_watcher.py:_on_file_created():256] file/dir created: .\wandb\run-20240306_131758-25jringl\files\wandb-summary.json
2024-03-06 13:18:21,649 DEBUG   HandlerThread:47368 [meta.py:_setup_git():206] setup git done
2024-03-06 13:18:21,649 DEBUG   HandlerThread:47368 [meta.py:_save_pip():53] save pip
2024-03-06 13:18:21,650 DEBUG   HandlerThread:47368 [meta.py:_save_pip():67] save pip done
2024-03-06 13:18:21,650 DEBUG   HandlerThread:47368 [meta.py:_save_conda():74] save conda
2024-03-06 13:18:22,638 INFO    Thread-11 :47368 [dir_watcher.py:_on_file_created():256] file/dir created: .\wandb\run-20240306_131758-25jringl\files\conda-environment.yaml
2024-03-06 13:18:22,638 INFO    Thread-11 :47368 [dir_watcher.py:_on_file_created():256] file/dir created: .\wandb\run-20240306_131758-25jringl\files\requirements.txt
2024-03-06 13:18:23,995 WARNING MainThread:47368 [internal.py:wandb_internal():153] Internal process interrupt: 1
2024-03-06 13:18:24,090 DEBUG   HandlerThread:47368 [meta.py:_save_conda():84] save conda done
2024-03-06 13:18:24,090 DEBUG   HandlerThread:47368 [meta.py:probe():247] probe done
2024-03-06 13:18:24,146 DEBUG   SenderThread:47368 [sender.py:send():235] send: files
2024-03-06 13:18:24,146 INFO    SenderThread:47368 [sender.py:_save_file():949] saving file wandb-metadata.json with policy now
2024-03-06 13:18:24,666 INFO    Thread-11 :47368 [dir_watcher.py:_on_file_created():256] file/dir created: .\wandb\run-20240306_131758-25jringl\files\wandb-metadata.json
2024-03-06 13:18:26,175 ERROR   Thread-17 :47368 [internal_api.py:upload_file():1640] upload_file exception https://storage.googleapis.com/wandb-production.appspot.com/shahwaiz/UNet-DAS/25jringl/wandb-metadata.json?Expires=1709788705&GoogleAccessId=gorilla-files-url-signer-man%40wandb-production.iam.gserviceaccount.com&Signature=iZRZqQIfptULp0Wn30rS0ykXbk9iwBCnTIY6r5u4IyLY66PPbSKddo2bZ0GChlxPTZLtP699UIbnt6yZGbs0YrzX3lhdUUEF0tI8BLIcbsuz5aP4Ob7EscgBk7PWGNzQJOSdINtmaGXT%2FbU3R7mvdCSmZ5jeoKOvvkDXXq%2B2Au7M9Quiaz2KZiyPsN462efLH8w4Zmvhs0zqJpUcxpPoDBG%2B%2Fh0NG3bXzMYh8MXME%2FA8sqQGbMWBIcdUe0M0NnKvNbJOx12xFvDIwWNlccFcrEPx%2FqtkvHHtp5zaXLUOHORu4UylE0eV5XO7Owa1WDLq1qFrLGwwfJ0zANFXelAlQA%3D%3D: ('Connection aborted.', ConnectionResetError(10054, '远程主机强迫关闭了一个现有的连接。', None, 10054, None))
2024-03-06 13:18:26,175 ERROR   Thread-17 :47368 [internal_api.py:upload_file():1642] upload_file request headers: {'User-Agent': 'python-requests/2.31.0', 'Accept-Encoding': 'gzip, deflate', 'Accept': '*/*', 'Connection': 'keep-alive', 'Content-Length': '889'}
2024-03-06 13:18:26,175 ERROR   Thread-17 :47368 [internal_api.py:upload_file():1644] upload_file response body: 
2024-03-06 13:18:28,004 ERROR   Thread-17 :47368 [internal_api.py:upload_file():1640] upload_file exception https://storage.googleapis.com/wandb-production.appspot.com/shahwaiz/UNet-DAS/25jringl/wandb-metadata.json?Expires=1709788705&GoogleAccessId=gorilla-files-url-signer-man%40wandb-production.iam.gserviceaccount.com&Signature=iZRZqQIfptULp0Wn30rS0ykXbk9iwBCnTIY6r5u4IyLY66PPbSKddo2bZ0GChlxPTZLtP699UIbnt6yZGbs0YrzX3lhdUUEF0tI8BLIcbsuz5aP4Ob7EscgBk7PWGNzQJOSdINtmaGXT%2FbU3R7mvdCSmZ5jeoKOvvkDXXq%2B2Au7M9Quiaz2KZiyPsN462efLH8w4Zmvhs0zqJpUcxpPoDBG%2B%2Fh0NG3bXzMYh8MXME%2FA8sqQGbMWBIcdUe0M0NnKvNbJOx12xFvDIwWNlccFcrEPx%2FqtkvHHtp5zaXLUOHORu4UylE0eV5XO7Owa1WDLq1qFrLGwwfJ0zANFXelAlQA%3D%3D: ('Connection aborted.', ConnectionResetError(10054, '远程主机强迫关闭了一个现有的连接。', None, 10054, None))
2024-03-06 13:18:28,005 ERROR   Thread-17 :47368 [internal_api.py:upload_file():1642] upload_file request headers: {'User-Agent': 'python-requests/2.31.0', 'Accept-Encoding': 'gzip, deflate', 'Accept': '*/*', 'Connection': 'keep-alive', 'Content-Length': '889'}
2024-03-06 13:18:28,005 ERROR   Thread-17 :47368 [internal_api.py:upload_file():1644] upload_file response body: 
2024-03-06 13:18:30,871 ERROR   Thread-17 :47368 [internal_api.py:upload_file():1640] upload_file exception https://storage.googleapis.com/wandb-production.appspot.com/shahwaiz/UNet-DAS/25jringl/wandb-metadata.json?Expires=1709788705&GoogleAccessId=gorilla-files-url-signer-man%40wandb-production.iam.gserviceaccount.com&Signature=iZRZqQIfptULp0Wn30rS0ykXbk9iwBCnTIY6r5u4IyLY66PPbSKddo2bZ0GChlxPTZLtP699UIbnt6yZGbs0YrzX3lhdUUEF0tI8BLIcbsuz5aP4Ob7EscgBk7PWGNzQJOSdINtmaGXT%2FbU3R7mvdCSmZ5jeoKOvvkDXXq%2B2Au7M9Quiaz2KZiyPsN462efLH8w4Zmvhs0zqJpUcxpPoDBG%2B%2Fh0NG3bXzMYh8MXME%2FA8sqQGbMWBIcdUe0M0NnKvNbJOx12xFvDIwWNlccFcrEPx%2FqtkvHHtp5zaXLUOHORu4UylE0eV5XO7Owa1WDLq1qFrLGwwfJ0zANFXelAlQA%3D%3D: ('Connection aborted.', ConnectionResetError(10054, '远程主机强迫关闭了一个现有的连接。', None, 10054, None))
2024-03-06 13:18:30,872 ERROR   Thread-17 :47368 [internal_api.py:upload_file():1642] upload_file request headers: {'User-Agent': 'python-requests/2.31.0', 'Accept-Encoding': 'gzip, deflate', 'Accept': '*/*', 'Connection': 'keep-alive', 'Content-Length': '889'}
2024-03-06 13:18:30,872 ERROR   Thread-17 :47368 [internal_api.py:upload_file():1644] upload_file response body: 
2024-03-06 13:18:30,872 ERROR   Thread-17 :47368 [retry.py:__call__():126] Retry attempt failed:
Traceback (most recent call last):
  File "E:\Anaconda\envs\unet\lib\site-packages\urllib3\connectionpool.py", line 793, in urlopen
    response = self._make_request(
  File "E:\Anaconda\envs\unet\lib\site-packages\urllib3\connectionpool.py", line 491, in _make_request
    raise new_e
  File "E:\Anaconda\envs\unet\lib\site-packages\urllib3\connectionpool.py", line 467, in _make_request
    self._validate_conn(conn)
  File "E:\Anaconda\envs\unet\lib\site-packages\urllib3\connectionpool.py", line 1099, in _validate_conn
    conn.connect()
  File "E:\Anaconda\envs\unet\lib\site-packages\urllib3\connection.py", line 653, in connect
    sock_and_verified = _ssl_wrap_socket_and_match_hostname(
  File "E:\Anaconda\envs\unet\lib\site-packages\urllib3\connection.py", line 806, in _ssl_wrap_socket_and_match_hostname
    ssl_sock = ssl_wrap_socket(
  File "E:\Anaconda\envs\unet\lib\site-packages\urllib3\util\ssl_.py", line 465, in ssl_wrap_socket
    ssl_sock = _ssl_wrap_socket_impl(sock, context, tls_in_tls, server_hostname)
  File "E:\Anaconda\envs\unet\lib\site-packages\urllib3\util\ssl_.py", line 509, in _ssl_wrap_socket_impl
    return ssl_context.wrap_socket(sock, server_hostname=server_hostname)
  File "E:\Anaconda\envs\unet\lib\ssl.py", line 500, in wrap_socket
    return self.sslsocket_class._create(
  File "E:\Anaconda\envs\unet\lib\ssl.py", line 1073, in _create
    self.do_handshake()
  File "E:\Anaconda\envs\unet\lib\ssl.py", line 1342, in do_handshake
    self._sslobj.do_handshake()
ConnectionResetError: [WinError 10054] 远程主机强迫关闭了一个现有的连接。

During handling of the above exception, another exception occurred:

Traceback (most recent call last):
  File "E:\Anaconda\envs\unet\lib\site-packages\requests\adapters.py", line 486, in send
    resp = conn.urlopen(
  File "E:\Anaconda\envs\unet\lib\site-packages\urllib3\connectionpool.py", line 847, in urlopen
    retries = retries.increment(
  File "E:\Anaconda\envs\unet\lib\site-packages\urllib3\util\retry.py", line 470, in increment
    raise reraise(type(error), error, _stacktrace)
  File "E:\Anaconda\envs\unet\lib\site-packages\urllib3\util\util.py", line 38, in reraise
    raise value.with_traceback(tb)
  File "E:\Anaconda\envs\unet\lib\site-packages\urllib3\connectionpool.py", line 793, in urlopen
    response = self._make_request(
  File "E:\Anaconda\envs\unet\lib\site-packages\urllib3\connectionpool.py", line 491, in _make_request
    raise new_e
  File "E:\Anaconda\envs\unet\lib\site-packages\urllib3\connectionpool.py", line 467, in _make_request
    self._validate_conn(conn)
  File "E:\Anaconda\envs\unet\lib\site-packages\urllib3\connectionpool.py", line 1099, in _validate_conn
    conn.connect()
  File "E:\Anaconda\envs\unet\lib\site-packages\urllib3\connection.py", line 653, in connect
    sock_and_verified = _ssl_wrap_socket_and_match_hostname(
  File "E:\Anaconda\envs\unet\lib\site-packages\urllib3\connection.py", line 806, in _ssl_wrap_socket_and_match_hostname
    ssl_sock = ssl_wrap_socket(
  File "E:\Anaconda\envs\unet\lib\site-packages\urllib3\util\ssl_.py", line 465, in ssl_wrap_socket
    ssl_sock = _ssl_wrap_socket_impl(sock, context, tls_in_tls, server_hostname)
  File "E:\Anaconda\envs\unet\lib\site-packages\urllib3\util\ssl_.py", line 509, in _ssl_wrap_socket_impl
    return ssl_context.wrap_socket(sock, server_hostname=server_hostname)
  File "E:\Anaconda\envs\unet\lib\ssl.py", line 500, in wrap_socket
    return self.sslsocket_class._create(
  File "E:\Anaconda\envs\unet\lib\ssl.py", line 1073, in _create
    self.do_handshake()
  File "E:\Anaconda\envs\unet\lib\ssl.py", line 1342, in do_handshake
    self._sslobj.do_handshake()
urllib3.exceptions.ProtocolError: ('Connection aborted.', ConnectionResetError(10054, '远程主机强迫关闭了一个现有的连接。', None, 10054, None))

During handling of the above exception, another exception occurred:

Traceback (most recent call last):
  File "C:\Users\19086\AppData\Roaming\Python\Python38\site-packages\wandb\sdk\internal\internal_api.py", line 1637, in upload_file
    response = requests.put(url, data=progress, headers=extra_headers)
  File "E:\Anaconda\envs\unet\lib\site-packages\requests\api.py", line 130, in put
    return request("put", url, data=data, **kwargs)
  File "E:\Anaconda\envs\unet\lib\site-packages\requests\api.py", line 59, in request
    return session.request(method=method, url=url, **kwargs)
  File "E:\Anaconda\envs\unet\lib\site-packages\requests\sessions.py", line 589, in request
    resp = self.send(prep, **send_kwargs)
  File "E:\Anaconda\envs\unet\lib\site-packages\requests\sessions.py", line 703, in send
    r = adapter.send(request, **kwargs)
  File "E:\Anaconda\envs\unet\lib\site-packages\requests\adapters.py", line 501, in send
    raise ConnectionError(err, request=request)
requests.exceptions.ConnectionError: ('Connection aborted.', ConnectionResetError(10054, '远程主机强迫关闭了一个现有的连接。', None, 10054, None))

During handling of the above exception, another exception occurred:

Traceback (most recent call last):
  File "C:\Users\19086\AppData\Roaming\Python\Python38\site-packages\wandb\sdk\lib\retry.py", line 102, in __call__
    result = self._call_fn(*args, **kwargs)
  File "C:\Users\19086\AppData\Roaming\Python\Python38\site-packages\wandb\sdk\internal\internal_api.py", line 1653, in upload_file
    raise e.with_traceback(sys.exc_info()[2])
  File "C:\Users\19086\AppData\Roaming\Python\Python38\site-packages\wandb\sdk\internal\internal_api.py", line 1637, in upload_file
    response = requests.put(url, data=progress, headers=extra_headers)
  File "E:\Anaconda\envs\unet\lib\site-packages\requests\api.py", line 130, in put
    return request("put", url, data=data, **kwargs)
  File "E:\Anaconda\envs\unet\lib\site-packages\requests\api.py", line 59, in request
    return session.request(method=method, url=url, **kwargs)
  File "E:\Anaconda\envs\unet\lib\site-packages\requests\sessions.py", line 589, in request
    resp = self.send(prep, **send_kwargs)
  File "E:\Anaconda\envs\unet\lib\site-packages\requests\sessions.py", line 703, in send
    r = adapter.send(request, **kwargs)
  File "E:\Anaconda\envs\unet\lib\site-packages\requests\adapters.py", line 501, in send
    raise ConnectionError(err, request=request)
wandb.sdk.lib.retry.TransientError: None
2024-03-06 13:18:36,206 INFO    Thread-17 :47368 [upload_job.py:push():132] Uploaded file C:\Users\19086\AppData\Local\Temp\tmpm53q5lgcwandb\1ew5l7z5-wandb-metadata.json
2024-03-06 13:18:46,867 WARNING MainThread:47368 [internal.py:wandb_internal():153] Internal process interrupt: 2
2024-03-06 13:18:46,867 ERROR   MainThread:47368 [internal.py:wandb_internal():156] Internal process interrupted.
2024-03-06 13:18:47,351 INFO    WriterThread:47368 [datastore.py:close():279] close: .\wandb\run-20240306_131758-25jringl\run-25jringl.wandb
2024-03-06 13:18:47,351 INFO    SenderThread:47368 [sender.py:finish():1111] shutting down sender
2024-03-06 13:18:47,351 INFO    HandlerThread:47368 [handler.py:finish():806] shutting down handler
2024-03-06 13:18:47,351 INFO    SenderThread:47368 [dir_watcher.py:finish():336] shutting down directory watcher
2024-03-06 13:18:47,871 INFO    SenderThread:47368 [dir_watcher.py:finish():366] scan: .\wandb\run-20240306_131758-25jringl\files
2024-03-06 13:18:47,871 INFO    SenderThread:47368 [dir_watcher.py:finish():380] scan save: .\wandb\run-20240306_131758-25jringl\files\conda-environment.yaml conda-environment.yaml
2024-03-06 13:18:47,872 INFO    SenderThread:47368 [dir_watcher.py:finish():380] scan save: .\wandb\run-20240306_131758-25jringl\files\config.yaml config.yaml
2024-03-06 13:18:47,872 INFO    SenderThread:47368 [dir_watcher.py:finish():380] scan save: .\wandb\run-20240306_131758-25jringl\files\requirements.txt requirements.txt
2024-03-06 13:18:47,875 INFO    SenderThread:47368 [dir_watcher.py:finish():380] scan save: .\wandb\run-20240306_131758-25jringl\files\wandb-metadata.json wandb-metadata.json
2024-03-06 13:18:47,875 INFO    SenderThread:47368 [dir_watcher.py:finish():380] scan save: .\wandb\run-20240306_131758-25jringl\files\wandb-summary.json wandb-summary.json
2024-03-06 13:18:47,881 INFO    SenderThread:47368 [file_pusher.py:finish():145] shutting down file pusher
2024-03-06 13:18:47,881 INFO    SenderThread:47368 [file_pusher.py:join():150] waiting for file pusher
2024-03-06 13:18:49,771 ERROR   Thread-19 :47368 [internal_api.py:upload_file():1640] upload_file exception https://storage.googleapis.com/wandb-production.appspot.com/shahwaiz/UNet-DAS/25jringl/requirements.txt?Expires=1709788729&GoogleAccessId=gorilla-files-url-signer-man%40wandb-production.iam.gserviceaccount.com&Signature=LGc12jPys%2BB1cfaKr6LGRuNmEJdq4ZYjZsnOi9KD75FbyHnsrFi9sMKKUl30ByuyaD7GPIpvUNyWzx%2BcYy3ydKZW%2BJpwz3VCsRPcd%2FVxdAImqoYWglsbdKgLpmhu8n%2BfnK2AuoMLBO4TAVRWMOx0BcNN2l4GOTH1ZiZdti7fPgP%2Bxf0KjnOC7qIgyizk67%2Bj5AKEASJqRd%2FrNC2MyUN6NQIzagZlNvn0Wn6QLlULp3tnQVXX2%2BsVEoE9UZXHib22dYH3mp5glBgFiiTHPaCSpCOGSQuO294ApDRBEffBevLL4L%2BmSHraU1WEX%2FsNMdPRbG1XWtsMMPV9ot6NUgyebA%3D%3D: ('Connection aborted.', ConnectionResetError(10054, '远程主机强迫关闭了一个现有的连接。', None, 10054, None))
2024-03-06 13:18:49,771 ERROR   Thread-19 :47368 [internal_api.py:upload_file():1642] upload_file request headers: {'User-Agent': 'python-requests/2.31.0', 'Accept-Encoding': 'gzip, deflate', 'Accept': '*/*', 'Connection': 'keep-alive', 'Content-Length': '1252'}
2024-03-06 13:18:49,771 ERROR   Thread-19 :47368 [internal_api.py:upload_file():1644] upload_file response body: 
2024-03-06 13:18:49,845 ERROR   Thread-18 :47368 [internal_api.py:upload_file():1640] upload_file exception https://storage.googleapis.com/wandb-production.appspot.com/shahwaiz/UNet-DAS/25jringl/config.yaml?Expires=1709788729&GoogleAccessId=gorilla-files-url-signer-man%40wandb-production.iam.gserviceaccount.com&Signature=RRe2UdEQLZi2CudnBaMLKpw7SSdxjhCRHk0hZKK%2FjJNRIlXI9C5aG%2BxvCVkaZKHBpFgQTM8vvI5fHj7LBivCe4StqgVC3jX6syOtMnD8pHNuDYc%2BrO%2FoXaaMfltNS%2BefX071EX%2Bz%2B%2BaqEtjcZM1%2BaX%2BTp8zTm%2B9CCsErwREzXVSh9INZ0d2QVHHy0OOq8NRpb%2FjH1G6XCmC%2Fr3KgkA1l%2FbCI1ItHC5JSYPYdjcRsjbYZwA%2FaiiEiZDvX7IehX6KTa1nv1Q4rctCcbc7u0UXcq7isQwpQLN1eG0PT1mjiM5YhiL4KgzoLbUyRBF2o3dzbeA4KE2clrOjbue9Rex7L6g%3D%3D: ('Connection aborted.', ConnectionResetError(10054, '远程主机强迫关闭了一个现有的连接。', None, 10054, None))
2024-03-06 13:18:49,845 ERROR   Thread-18 :47368 [internal_api.py:upload_file():1642] upload_file request headers: {'User-Agent': 'python-requests/2.31.0', 'Accept-Encoding': 'gzip, deflate', 'Accept': '*/*', 'Connection': 'keep-alive', 'Content-Length': '348'}
2024-03-06 13:18:49,845 ERROR   Thread-18 :47368 [internal_api.py:upload_file():1644] upload_file response body: 
2024-03-06 13:18:51,334 ERROR   Thread-20 :47368 [internal_api.py:upload_file():1640] upload_file exception https://storage.googleapis.com/wandb-production.appspot.com/shahwaiz/UNet-DAS/25jringl/wandb-summary.json?Expires=1709788729&GoogleAccessId=gorilla-files-url-signer-man%40wandb-production.iam.gserviceaccount.com&Signature=vcUDcBJkkoXFGME1Mthfeq3h16FrDbg0BtDGyVLbHB3ZD4WGzjWbZ4%2Bbt%2FSf0ottieLJbr2Nl8dWTDUtGFi%2F%2Bu3pSmFcqg0JIjHEt4TzJr7beQr5ffAT79fx8uBJCoj2RBCscMh1TdRvNGslh8p5YT55u%2BRqlVApiObpnzlWAwBIvs38r6zGZTLbj5CVQAgGRz69w%2Fv8jM9yPnBjnEKx4fPm8CeTE0D%2FGDzK1Cwc5QkfF5qo0dWXnHc2CaLvpCZzJgZslUcS3Fj5%2BR3BEITkv%2F5EGR%2FCrnCt4hZ3nTy%2F25Yzljm4omHj06RiHpIFXigoEa%2BWKbUTzfdfEgcZdUmCfw%3D%3D: ('Connection aborted.', ConnectionResetError(10054, '远程主机强迫关闭了一个现有的连接。', None, 10054, None))
2024-03-06 13:18:51,334 ERROR   Thread-20 :47368 [internal_api.py:upload_file():1642] upload_file request headers: {'User-Agent': 'python-requests/2.31.0', 'Accept-Encoding': 'gzip, deflate', 'Accept': '*/*', 'Connection': 'keep-alive', 'Content-Length': '2'}
2024-03-06 13:18:51,334 ERROR   Thread-20 :47368 [internal_api.py:upload_file():1644] upload_file response body: 
2024-03-06 13:18:51,334 ERROR   Thread-20 :47368 [retry.py:__call__():126] Retry attempt failed:
Traceback (most recent call last):
  File "E:\Anaconda\envs\unet\lib\site-packages\urllib3\connectionpool.py", line 793, in urlopen
    response = self._make_request(
  File "E:\Anaconda\envs\unet\lib\site-packages\urllib3\connectionpool.py", line 491, in _make_request
    raise new_e
  File "E:\Anaconda\envs\unet\lib\site-packages\urllib3\connectionpool.py", line 467, in _make_request
    self._validate_conn(conn)
  File "E:\Anaconda\envs\unet\lib\site-packages\urllib3\connectionpool.py", line 1099, in _validate_conn
    conn.connect()
  File "E:\Anaconda\envs\unet\lib\site-packages\urllib3\connection.py", line 653, in connect
    sock_and_verified = _ssl_wrap_socket_and_match_hostname(
  File "E:\Anaconda\envs\unet\lib\site-packages\urllib3\connection.py", line 806, in _ssl_wrap_socket_and_match_hostname
    ssl_sock = ssl_wrap_socket(
  File "E:\Anaconda\envs\unet\lib\site-packages\urllib3\util\ssl_.py", line 465, in ssl_wrap_socket
    ssl_sock = _ssl_wrap_socket_impl(sock, context, tls_in_tls, server_hostname)
  File "E:\Anaconda\envs\unet\lib\site-packages\urllib3\util\ssl_.py", line 509, in _ssl_wrap_socket_impl
    return ssl_context.wrap_socket(sock, server_hostname=server_hostname)
  File "E:\Anaconda\envs\unet\lib\ssl.py", line 500, in wrap_socket
    return self.sslsocket_class._create(
  File "E:\Anaconda\envs\unet\lib\ssl.py", line 1073, in _create
    self.do_handshake()
  File "E:\Anaconda\envs\unet\lib\ssl.py", line 1342, in do_handshake
    self._sslobj.do_handshake()
ConnectionResetError: [WinError 10054] 远程主机强迫关闭了一个现有的连接。

During handling of the above exception, another exception occurred:

Traceback (most recent call last):
  File "E:\Anaconda\envs\unet\lib\site-packages\requests\adapters.py", line 486, in send
    resp = conn.urlopen(
  File "E:\Anaconda\envs\unet\lib\site-packages\urllib3\connectionpool.py", line 847, in urlopen
    retries = retries.increment(
  File "E:\Anaconda\envs\unet\lib\site-packages\urllib3\util\retry.py", line 470, in increment
    raise reraise(type(error), error, _stacktrace)
  File "E:\Anaconda\envs\unet\lib\site-packages\urllib3\util\util.py", line 38, in reraise
    raise value.with_traceback(tb)
  File "E:\Anaconda\envs\unet\lib\site-packages\urllib3\connectionpool.py", line 793, in urlopen
    response = self._make_request(
  File "E:\Anaconda\envs\unet\lib\site-packages\urllib3\connectionpool.py", line 491, in _make_request
    raise new_e
  File "E:\Anaconda\envs\unet\lib\site-packages\urllib3\connectionpool.py", line 467, in _make_request
    self._validate_conn(conn)
  File "E:\Anaconda\envs\unet\lib\site-packages\urllib3\connectionpool.py", line 1099, in _validate_conn
    conn.connect()
  File "E:\Anaconda\envs\unet\lib\site-packages\urllib3\connection.py", line 653, in connect
    sock_and_verified = _ssl_wrap_socket_and_match_hostname(
  File "E:\Anaconda\envs\unet\lib\site-packages\urllib3\connection.py", line 806, in _ssl_wrap_socket_and_match_hostname
    ssl_sock = ssl_wrap_socket(
  File "E:\Anaconda\envs\unet\lib\site-packages\urllib3\util\ssl_.py", line 465, in ssl_wrap_socket
    ssl_sock = _ssl_wrap_socket_impl(sock, context, tls_in_tls, server_hostname)
  File "E:\Anaconda\envs\unet\lib\site-packages\urllib3\util\ssl_.py", line 509, in _ssl_wrap_socket_impl
    return ssl_context.wrap_socket(sock, server_hostname=server_hostname)
  File "E:\Anaconda\envs\unet\lib\ssl.py", line 500, in wrap_socket
    return self.sslsocket_class._create(
  File "E:\Anaconda\envs\unet\lib\ssl.py", line 1073, in _create
    self.do_handshake()
  File "E:\Anaconda\envs\unet\lib\ssl.py", line 1342, in do_handshake
    self._sslobj.do_handshake()
urllib3.exceptions.ProtocolError: ('Connection aborted.', ConnectionResetError(10054, '远程主机强迫关闭了一个现有的连接。', None, 10054, None))

During handling of the above exception, another exception occurred:

Traceback (most recent call last):
  File "C:\Users\19086\AppData\Roaming\Python\Python38\site-packages\wandb\sdk\internal\internal_api.py", line 1637, in upload_file
    response = requests.put(url, data=progress, headers=extra_headers)
  File "E:\Anaconda\envs\unet\lib\site-packages\requests\api.py", line 130, in put
    return request("put", url, data=data, **kwargs)
  File "E:\Anaconda\envs\unet\lib\site-packages\requests\api.py", line 59, in request
    return session.request(method=method, url=url, **kwargs)
  File "E:\Anaconda\envs\unet\lib\site-packages\requests\sessions.py", line 589, in request
    resp = self.send(prep, **send_kwargs)
  File "E:\Anaconda\envs\unet\lib\site-packages\requests\sessions.py", line 703, in send
    r = adapter.send(request, **kwargs)
  File "E:\Anaconda\envs\unet\lib\site-packages\requests\adapters.py", line 501, in send
    raise ConnectionError(err, request=request)
requests.exceptions.ConnectionError: ('Connection aborted.', ConnectionResetError(10054, '远程主机强迫关闭了一个现有的连接。', None, 10054, None))

During handling of the above exception, another exception occurred:

Traceback (most recent call last):
  File "C:\Users\19086\AppData\Roaming\Python\Python38\site-packages\wandb\sdk\lib\retry.py", line 102, in __call__
    result = self._call_fn(*args, **kwargs)
  File "C:\Users\19086\AppData\Roaming\Python\Python38\site-packages\wandb\sdk\internal\internal_api.py", line 1653, in upload_file
    raise e.with_traceback(sys.exc_info()[2])
  File "C:\Users\19086\AppData\Roaming\Python\Python38\site-packages\wandb\sdk\internal\internal_api.py", line 1637, in upload_file
    response = requests.put(url, data=progress, headers=extra_headers)
  File "E:\Anaconda\envs\unet\lib\site-packages\requests\api.py", line 130, in put
    return request("put", url, data=data, **kwargs)
  File "E:\Anaconda\envs\unet\lib\site-packages\requests\api.py", line 59, in request
    return session.request(method=method, url=url, **kwargs)
  File "E:\Anaconda\envs\unet\lib\site-packages\requests\sessions.py", line 589, in request
    resp = self.send(prep, **send_kwargs)
  File "E:\Anaconda\envs\unet\lib\site-packages\requests\sessions.py", line 703, in send
    r = adapter.send(request, **kwargs)
  File "E:\Anaconda\envs\unet\lib\site-packages\requests\adapters.py", line 501, in send
    raise ConnectionError(err, request=request)
wandb.sdk.lib.retry.TransientError: None
2024-03-06 13:18:51,503 ERROR   Thread-19 :47368 [internal_api.py:upload_file():1640] upload_file exception https://storage.googleapis.com/wandb-production.appspot.com/shahwaiz/UNet-DAS/25jringl/requirements.txt?Expires=1709788729&GoogleAccessId=gorilla-files-url-signer-man%40wandb-production.iam.gserviceaccount.com&Signature=LGc12jPys%2BB1cfaKr6LGRuNmEJdq4ZYjZsnOi9KD75FbyHnsrFi9sMKKUl30ByuyaD7GPIpvUNyWzx%2BcYy3ydKZW%2BJpwz3VCsRPcd%2FVxdAImqoYWglsbdKgLpmhu8n%2BfnK2AuoMLBO4TAVRWMOx0BcNN2l4GOTH1ZiZdti7fPgP%2Bxf0KjnOC7qIgyizk67%2Bj5AKEASJqRd%2FrNC2MyUN6NQIzagZlNvn0Wn6QLlULp3tnQVXX2%2BsVEoE9UZXHib22dYH3mp5glBgFiiTHPaCSpCOGSQuO294ApDRBEffBevLL4L%2BmSHraU1WEX%2FsNMdPRbG1XWtsMMPV9ot6NUgyebA%3D%3D: ('Connection aborted.', ConnectionResetError(10054, '远程主机强迫关闭了一个现有的连接。', None, 10054, None))
2024-03-06 13:18:51,503 ERROR   Thread-19 :47368 [internal_api.py:upload_file():1642] upload_file request headers: {'User-Agent': 'python-requests/2.31.0', 'Accept-Encoding': 'gzip, deflate', 'Accept': '*/*', 'Connection': 'keep-alive', 'Content-Length': '1252'}
2024-03-06 13:18:51,503 ERROR   Thread-19 :47368 [internal_api.py:upload_file():1644] upload_file response body: 
2024-03-06 13:18:51,504 ERROR   Thread-19 :47368 [retry.py:__call__():126] Retry attempt failed:
Traceback (most recent call last):
  File "E:\Anaconda\envs\unet\lib\site-packages\urllib3\connectionpool.py", line 793, in urlopen
    response = self._make_request(
  File "E:\Anaconda\envs\unet\lib\site-packages\urllib3\connectionpool.py", line 491, in _make_request
    raise new_e
  File "E:\Anaconda\envs\unet\lib\site-packages\urllib3\connectionpool.py", line 467, in _make_request
    self._validate_conn(conn)
  File "E:\Anaconda\envs\unet\lib\site-packages\urllib3\connectionpool.py", line 1099, in _validate_conn
    conn.connect()
  File "E:\Anaconda\envs\unet\lib\site-packages\urllib3\connection.py", line 653, in connect
    sock_and_verified = _ssl_wrap_socket_and_match_hostname(
  File "E:\Anaconda\envs\unet\lib\site-packages\urllib3\connection.py", line 806, in _ssl_wrap_socket_and_match_hostname
    ssl_sock = ssl_wrap_socket(
  File "E:\Anaconda\envs\unet\lib\site-packages\urllib3\util\ssl_.py", line 465, in ssl_wrap_socket
    ssl_sock = _ssl_wrap_socket_impl(sock, context, tls_in_tls, server_hostname)
  File "E:\Anaconda\envs\unet\lib\site-packages\urllib3\util\ssl_.py", line 509, in _ssl_wrap_socket_impl
    return ssl_context.wrap_socket(sock, server_hostname=server_hostname)
  File "E:\Anaconda\envs\unet\lib\ssl.py", line 500, in wrap_socket
    return self.sslsocket_class._create(
  File "E:\Anaconda\envs\unet\lib\ssl.py", line 1073, in _create
    self.do_handshake()
  File "E:\Anaconda\envs\unet\lib\ssl.py", line 1342, in do_handshake
    self._sslobj.do_handshake()
ConnectionResetError: [WinError 10054] 远程主机强迫关闭了一个现有的连接。

During handling of the above exception, another exception occurred:

Traceback (most recent call last):
  File "E:\Anaconda\envs\unet\lib\site-packages\requests\adapters.py", line 486, in send
    resp = conn.urlopen(
  File "E:\Anaconda\envs\unet\lib\site-packages\urllib3\connectionpool.py", line 847, in urlopen
    retries = retries.increment(
  File "E:\Anaconda\envs\unet\lib\site-packages\urllib3\util\retry.py", line 470, in increment
    raise reraise(type(error), error, _stacktrace)
  File "E:\Anaconda\envs\unet\lib\site-packages\urllib3\util\util.py", line 38, in reraise
    raise value.with_traceback(tb)
  File "E:\Anaconda\envs\unet\lib\site-packages\urllib3\connectionpool.py", line 793, in urlopen
    response = self._make_request(
  File "E:\Anaconda\envs\unet\lib\site-packages\urllib3\connectionpool.py", line 491, in _make_request
    raise new_e
  File "E:\Anaconda\envs\unet\lib\site-packages\urllib3\connectionpool.py", line 467, in _make_request
    self._validate_conn(conn)
  File "E:\Anaconda\envs\unet\lib\site-packages\urllib3\connectionpool.py", line 1099, in _validate_conn
    conn.connect()
  File "E:\Anaconda\envs\unet\lib\site-packages\urllib3\connection.py", line 653, in connect
    sock_and_verified = _ssl_wrap_socket_and_match_hostname(
  File "E:\Anaconda\envs\unet\lib\site-packages\urllib3\connection.py", line 806, in _ssl_wrap_socket_and_match_hostname
    ssl_sock = ssl_wrap_socket(
  File "E:\Anaconda\envs\unet\lib\site-packages\urllib3\util\ssl_.py", line 465, in ssl_wrap_socket
    ssl_sock = _ssl_wrap_socket_impl(sock, context, tls_in_tls, server_hostname)
  File "E:\Anaconda\envs\unet\lib\site-packages\urllib3\util\ssl_.py", line 509, in _ssl_wrap_socket_impl
    return ssl_context.wrap_socket(sock, server_hostname=server_hostname)
  File "E:\Anaconda\envs\unet\lib\ssl.py", line 500, in wrap_socket
    return self.sslsocket_class._create(
  File "E:\Anaconda\envs\unet\lib\ssl.py", line 1073, in _create
    self.do_handshake()
  File "E:\Anaconda\envs\unet\lib\ssl.py", line 1342, in do_handshake
    self._sslobj.do_handshake()
urllib3.exceptions.ProtocolError: ('Connection aborted.', ConnectionResetError(10054, '远程主机强迫关闭了一个现有的连接。', None, 10054, None))

During handling of the above exception, another exception occurred:

Traceback (most recent call last):
  File "C:\Users\19086\AppData\Roaming\Python\Python38\site-packages\wandb\sdk\internal\internal_api.py", line 1637, in upload_file
    response = requests.put(url, data=progress, headers=extra_headers)
  File "E:\Anaconda\envs\unet\lib\site-packages\requests\api.py", line 130, in put
    return request("put", url, data=data, **kwargs)
  File "E:\Anaconda\envs\unet\lib\site-packages\requests\api.py", line 59, in request
    return session.request(method=method, url=url, **kwargs)
  File "E:\Anaconda\envs\unet\lib\site-packages\requests\sessions.py", line 589, in request
    resp = self.send(prep, **send_kwargs)
  File "E:\Anaconda\envs\unet\lib\site-packages\requests\sessions.py", line 703, in send
    r = adapter.send(request, **kwargs)
  File "E:\Anaconda\envs\unet\lib\site-packages\requests\adapters.py", line 501, in send
    raise ConnectionError(err, request=request)
requests.exceptions.ConnectionError: ('Connection aborted.', ConnectionResetError(10054, '远程主机强迫关闭了一个现有的连接。', None, 10054, None))

During handling of the above exception, another exception occurred:

Traceback (most recent call last):
  File "C:\Users\19086\AppData\Roaming\Python\Python38\site-packages\wandb\sdk\lib\retry.py", line 102, in __call__
    result = self._call_fn(*args, **kwargs)
  File "C:\Users\19086\AppData\Roaming\Python\Python38\site-packages\wandb\sdk\internal\internal_api.py", line 1653, in upload_file
    raise e.with_traceback(sys.exc_info()[2])
  File "C:\Users\19086\AppData\Roaming\Python\Python38\site-packages\wandb\sdk\internal\internal_api.py", line 1637, in upload_file
    response = requests.put(url, data=progress, headers=extra_headers)
  File "E:\Anaconda\envs\unet\lib\site-packages\requests\api.py", line 130, in put
    return request("put", url, data=data, **kwargs)
  File "E:\Anaconda\envs\unet\lib\site-packages\requests\api.py", line 59, in request
    return session.request(method=method, url=url, **kwargs)
  File "E:\Anaconda\envs\unet\lib\site-packages\requests\sessions.py", line 589, in request
    resp = self.send(prep, **send_kwargs)
  File "E:\Anaconda\envs\unet\lib\site-packages\requests\sessions.py", line 703, in send
    r = adapter.send(request, **kwargs)
  File "E:\Anaconda\envs\unet\lib\site-packages\requests\adapters.py", line 501, in send
    raise ConnectionError(err, request=request)
wandb.sdk.lib.retry.TransientError: None
2024-03-06 13:18:51,553 ERROR   Thread-18 :47368 [internal_api.py:upload_file():1640] upload_file exception https://storage.googleapis.com/wandb-production.appspot.com/shahwaiz/UNet-DAS/25jringl/config.yaml?Expires=1709788729&GoogleAccessId=gorilla-files-url-signer-man%40wandb-production.iam.gserviceaccount.com&Signature=RRe2UdEQLZi2CudnBaMLKpw7SSdxjhCRHk0hZKK%2FjJNRIlXI9C5aG%2BxvCVkaZKHBpFgQTM8vvI5fHj7LBivCe4StqgVC3jX6syOtMnD8pHNuDYc%2BrO%2FoXaaMfltNS%2BefX071EX%2Bz%2B%2BaqEtjcZM1%2BaX%2BTp8zTm%2B9CCsErwREzXVSh9INZ0d2QVHHy0OOq8NRpb%2FjH1G6XCmC%2Fr3KgkA1l%2FbCI1ItHC5JSYPYdjcRsjbYZwA%2FaiiEiZDvX7IehX6KTa1nv1Q4rctCcbc7u0UXcq7isQwpQLN1eG0PT1mjiM5YhiL4KgzoLbUyRBF2o3dzbeA4KE2clrOjbue9Rex7L6g%3D%3D: ('Connection aborted.', ConnectionResetError(10054, '远程主机强迫关闭了一个现有的连接。', None, 10054, None))
2024-03-06 13:18:51,553 ERROR   Thread-18 :47368 [internal_api.py:upload_file():1642] upload_file request headers: {'User-Agent': 'python-requests/2.31.0', 'Accept-Encoding': 'gzip, deflate', 'Accept': '*/*', 'Connection': 'keep-alive', 'Content-Length': '348'}
2024-03-06 13:18:51,553 ERROR   Thread-18 :47368 [internal_api.py:upload_file():1644] upload_file response body: 
2024-03-06 13:18:51,553 ERROR   Thread-18 :47368 [retry.py:__call__():126] Retry attempt failed:
Traceback (most recent call last):
  File "E:\Anaconda\envs\unet\lib\site-packages\urllib3\connectionpool.py", line 793, in urlopen
    response = self._make_request(
  File "E:\Anaconda\envs\unet\lib\site-packages\urllib3\connectionpool.py", line 491, in _make_request
    raise new_e
  File "E:\Anaconda\envs\unet\lib\site-packages\urllib3\connectionpool.py", line 467, in _make_request
    self._validate_conn(conn)
  File "E:\Anaconda\envs\unet\lib\site-packages\urllib3\connectionpool.py", line 1099, in _validate_conn
    conn.connect()
  File "E:\Anaconda\envs\unet\lib\site-packages\urllib3\connection.py", line 653, in connect
    sock_and_verified = _ssl_wrap_socket_and_match_hostname(
  File "E:\Anaconda\envs\unet\lib\site-packages\urllib3\connection.py", line 806, in _ssl_wrap_socket_and_match_hostname
    ssl_sock = ssl_wrap_socket(
  File "E:\Anaconda\envs\unet\lib\site-packages\urllib3\util\ssl_.py", line 465, in ssl_wrap_socket
    ssl_sock = _ssl_wrap_socket_impl(sock, context, tls_in_tls, server_hostname)
  File "E:\Anaconda\envs\unet\lib\site-packages\urllib3\util\ssl_.py", line 509, in _ssl_wrap_socket_impl
    return ssl_context.wrap_socket(sock, server_hostname=server_hostname)
  File "E:\Anaconda\envs\unet\lib\ssl.py", line 500, in wrap_socket
    return self.sslsocket_class._create(
  File "E:\Anaconda\envs\unet\lib\ssl.py", line 1073, in _create
    self.do_handshake()
  File "E:\Anaconda\envs\unet\lib\ssl.py", line 1342, in do_handshake
    self._sslobj.do_handshake()
ConnectionResetError: [WinError 10054] 远程主机强迫关闭了一个现有的连接。

During handling of the above exception, another exception occurred:

Traceback (most recent call last):
  File "E:\Anaconda\envs\unet\lib\site-packages\requests\adapters.py", line 486, in send
    resp = conn.urlopen(
  File "E:\Anaconda\envs\unet\lib\site-packages\urllib3\connectionpool.py", line 847, in urlopen
    retries = retries.increment(
  File "E:\Anaconda\envs\unet\lib\site-packages\urllib3\util\retry.py", line 470, in increment
    raise reraise(type(error), error, _stacktrace)
  File "E:\Anaconda\envs\unet\lib\site-packages\urllib3\util\util.py", line 38, in reraise
    raise value.with_traceback(tb)
  File "E:\Anaconda\envs\unet\lib\site-packages\urllib3\connectionpool.py", line 793, in urlopen
    response = self._make_request(
  File "E:\Anaconda\envs\unet\lib\site-packages\urllib3\connectionpool.py", line 491, in _make_request
    raise new_e
  File "E:\Anaconda\envs\unet\lib\site-packages\urllib3\connectionpool.py", line 467, in _make_request
    self._validate_conn(conn)
  File "E:\Anaconda\envs\unet\lib\site-packages\urllib3\connectionpool.py", line 1099, in _validate_conn
    conn.connect()
  File "E:\Anaconda\envs\unet\lib\site-packages\urllib3\connection.py", line 653, in connect
    sock_and_verified = _ssl_wrap_socket_and_match_hostname(
  File "E:\Anaconda\envs\unet\lib\site-packages\urllib3\connection.py", line 806, in _ssl_wrap_socket_and_match_hostname
    ssl_sock = ssl_wrap_socket(
  File "E:\Anaconda\envs\unet\lib\site-packages\urllib3\util\ssl_.py", line 465, in ssl_wrap_socket
    ssl_sock = _ssl_wrap_socket_impl(sock, context, tls_in_tls, server_hostname)
  File "E:\Anaconda\envs\unet\lib\site-packages\urllib3\util\ssl_.py", line 509, in _ssl_wrap_socket_impl
    return ssl_context.wrap_socket(sock, server_hostname=server_hostname)
  File "E:\Anaconda\envs\unet\lib\ssl.py", line 500, in wrap_socket
    return self.sslsocket_class._create(
  File "E:\Anaconda\envs\unet\lib\ssl.py", line 1073, in _create
    self.do_handshake()
  File "E:\Anaconda\envs\unet\lib\ssl.py", line 1342, in do_handshake
    self._sslobj.do_handshake()
urllib3.exceptions.ProtocolError: ('Connection aborted.', ConnectionResetError(10054, '远程主机强迫关闭了一个现有的连接。', None, 10054, None))

During handling of the above exception, another exception occurred:

Traceback (most recent call last):
  File "C:\Users\19086\AppData\Roaming\Python\Python38\site-packages\wandb\sdk\internal\internal_api.py", line 1637, in upload_file
    response = requests.put(url, data=progress, headers=extra_headers)
  File "E:\Anaconda\envs\unet\lib\site-packages\requests\api.py", line 130, in put
    return request("put", url, data=data, **kwargs)
  File "E:\Anaconda\envs\unet\lib\site-packages\requests\api.py", line 59, in request
    return session.request(method=method, url=url, **kwargs)
  File "E:\Anaconda\envs\unet\lib\site-packages\requests\sessions.py", line 589, in request
    resp = self.send(prep, **send_kwargs)
  File "E:\Anaconda\envs\unet\lib\site-packages\requests\sessions.py", line 703, in send
    r = adapter.send(request, **kwargs)
  File "E:\Anaconda\envs\unet\lib\site-packages\requests\adapters.py", line 501, in send
    raise ConnectionError(err, request=request)
requests.exceptions.ConnectionError: ('Connection aborted.', ConnectionResetError(10054, '远程主机强迫关闭了一个现有的连接。', None, 10054, None))

During handling of the above exception, another exception occurred:

Traceback (most recent call last):
  File "C:\Users\19086\AppData\Roaming\Python\Python38\site-packages\wandb\sdk\lib\retry.py", line 102, in __call__
    result = self._call_fn(*args, **kwargs)
  File "C:\Users\19086\AppData\Roaming\Python\Python38\site-packages\wandb\sdk\internal\internal_api.py", line 1653, in upload_file
    raise e.with_traceback(sys.exc_info()[2])
  File "C:\Users\19086\AppData\Roaming\Python\Python38\site-packages\wandb\sdk\internal\internal_api.py", line 1637, in upload_file
    response = requests.put(url, data=progress, headers=extra_headers)
  File "E:\Anaconda\envs\unet\lib\site-packages\requests\api.py", line 130, in put
    return request("put", url, data=data, **kwargs)
  File "E:\Anaconda\envs\unet\lib\site-packages\requests\api.py", line 59, in request
    return session.request(method=method, url=url, **kwargs)
  File "E:\Anaconda\envs\unet\lib\site-packages\requests\sessions.py", line 589, in request
    resp = self.send(prep, **send_kwargs)
  File "E:\Anaconda\envs\unet\lib\site-packages\requests\sessions.py", line 703, in send
    r = adapter.send(request, **kwargs)
  File "E:\Anaconda\envs\unet\lib\site-packages\requests\adapters.py", line 501, in send
    raise ConnectionError(err, request=request)
wandb.sdk.lib.retry.TransientError: None
2024-03-06 13:18:52,976 ERROR   Thread-20 :47368 [internal_api.py:upload_file():1640] upload_file exception https://storage.googleapis.com/wandb-production.appspot.com/shahwaiz/UNet-DAS/25jringl/wandb-summary.json?Expires=1709788729&GoogleAccessId=gorilla-files-url-signer-man%40wandb-production.iam.gserviceaccount.com&Signature=vcUDcBJkkoXFGME1Mthfeq3h16FrDbg0BtDGyVLbHB3ZD4WGzjWbZ4%2Bbt%2FSf0ottieLJbr2Nl8dWTDUtGFi%2F%2Bu3pSmFcqg0JIjHEt4TzJr7beQr5ffAT79fx8uBJCoj2RBCscMh1TdRvNGslh8p5YT55u%2BRqlVApiObpnzlWAwBIvs38r6zGZTLbj5CVQAgGRz69w%2Fv8jM9yPnBjnEKx4fPm8CeTE0D%2FGDzK1Cwc5QkfF5qo0dWXnHc2CaLvpCZzJgZslUcS3Fj5%2BR3BEITkv%2F5EGR%2FCrnCt4hZ3nTy%2F25Yzljm4omHj06RiHpIFXigoEa%2BWKbUTzfdfEgcZdUmCfw%3D%3D: ('Connection aborted.', ConnectionResetError(10054, '远程主机强迫关闭了一个现有的连接。', None, 10054, None))
2024-03-06 13:18:52,976 ERROR   Thread-20 :47368 [internal_api.py:upload_file():1642] upload_file request headers: {'User-Agent': 'python-requests/2.31.0', 'Accept-Encoding': 'gzip, deflate', 'Accept': '*/*', 'Connection': 'keep-alive', 'Content-Length': '2'}
2024-03-06 13:18:52,976 ERROR   Thread-20 :47368 [internal_api.py:upload_file():1644] upload_file response body: 
2024-03-06 13:18:54,311 ERROR   Thread-19 :47368 [internal_api.py:upload_file():1640] upload_file exception https://storage.googleapis.com/wandb-production.appspot.com/shahwaiz/UNet-DAS/25jringl/requirements.txt?Expires=1709788729&GoogleAccessId=gorilla-files-url-signer-man%40wandb-production.iam.gserviceaccount.com&Signature=LGc12jPys%2BB1cfaKr6LGRuNmEJdq4ZYjZsnOi9KD75FbyHnsrFi9sMKKUl30ByuyaD7GPIpvUNyWzx%2BcYy3ydKZW%2BJpwz3VCsRPcd%2FVxdAImqoYWglsbdKgLpmhu8n%2BfnK2AuoMLBO4TAVRWMOx0BcNN2l4GOTH1ZiZdti7fPgP%2Bxf0KjnOC7qIgyizk67%2Bj5AKEASJqRd%2FrNC2MyUN6NQIzagZlNvn0Wn6QLlULp3tnQVXX2%2BsVEoE9UZXHib22dYH3mp5glBgFiiTHPaCSpCOGSQuO294ApDRBEffBevLL4L%2BmSHraU1WEX%2FsNMdPRbG1XWtsMMPV9ot6NUgyebA%3D%3D: ('Connection aborted.', ConnectionResetError(10054, '远程主机强迫关闭了一个现有的连接。', None, 10054, None))
2024-03-06 13:18:54,311 ERROR   Thread-19 :47368 [internal_api.py:upload_file():1642] upload_file request headers: {'User-Agent': 'python-requests/2.31.0', 'Accept-Encoding': 'gzip, deflate', 'Accept': '*/*', 'Connection': 'keep-alive', 'Content-Length': '1252'}
2024-03-06 13:18:54,311 ERROR   Thread-19 :47368 [internal_api.py:upload_file():1644] upload_file response body: 
2024-03-06 13:18:54,870 INFO    Thread-18 :47368 [upload_job.py:push():132] Uploaded file .\wandb\run-20240306_131758-25jringl\files\config.yaml
2024-03-06 13:18:56,077 ERROR   Thread-20 :47368 [internal_api.py:upload_file():1640] upload_file exception https://storage.googleapis.com/wandb-production.appspot.com/shahwaiz/UNet-DAS/25jringl/wandb-summary.json?Expires=1709788729&GoogleAccessId=gorilla-files-url-signer-man%40wandb-production.iam.gserviceaccount.com&Signature=vcUDcBJkkoXFGME1Mthfeq3h16FrDbg0BtDGyVLbHB3ZD4WGzjWbZ4%2Bbt%2FSf0ottieLJbr2Nl8dWTDUtGFi%2F%2Bu3pSmFcqg0JIjHEt4TzJr7beQr5ffAT79fx8uBJCoj2RBCscMh1TdRvNGslh8p5YT55u%2BRqlVApiObpnzlWAwBIvs38r6zGZTLbj5CVQAgGRz69w%2Fv8jM9yPnBjnEKx4fPm8CeTE0D%2FGDzK1Cwc5QkfF5qo0dWXnHc2CaLvpCZzJgZslUcS3Fj5%2BR3BEITkv%2F5EGR%2FCrnCt4hZ3nTy%2F25Yzljm4omHj06RiHpIFXigoEa%2BWKbUTzfdfEgcZdUmCfw%3D%3D: ('Connection aborted.', ConnectionResetError(10054, '远程主机强迫关闭了一个现有的连接。', None, 10054, None))
2024-03-06 13:18:56,077 ERROR   Thread-20 :47368 [internal_api.py:upload_file():1642] upload_file request headers: {'User-Agent': 'python-requests/2.31.0', 'Accept-Encoding': 'gzip, deflate', 'Accept': '*/*', 'Connection': 'keep-alive', 'Content-Length': '2'}
2024-03-06 13:18:56,077 ERROR   Thread-20 :47368 [internal_api.py:upload_file():1644] upload_file response body: 
2024-03-06 13:18:59,157 ERROR   Thread-19 :47368 [internal_api.py:upload_file():1640] upload_file exception https://storage.googleapis.com/wandb-production.appspot.com/shahwaiz/UNet-DAS/25jringl/requirements.txt?Expires=1709788729&GoogleAccessId=gorilla-files-url-signer-man%40wandb-production.iam.gserviceaccount.com&Signature=LGc12jPys%2BB1cfaKr6LGRuNmEJdq4ZYjZsnOi9KD75FbyHnsrFi9sMKKUl30ByuyaD7GPIpvUNyWzx%2BcYy3ydKZW%2BJpwz3VCsRPcd%2FVxdAImqoYWglsbdKgLpmhu8n%2BfnK2AuoMLBO4TAVRWMOx0BcNN2l4GOTH1ZiZdti7fPgP%2Bxf0KjnOC7qIgyizk67%2Bj5AKEASJqRd%2FrNC2MyUN6NQIzagZlNvn0Wn6QLlULp3tnQVXX2%2BsVEoE9UZXHib22dYH3mp5glBgFiiTHPaCSpCOGSQuO294ApDRBEffBevLL4L%2BmSHraU1WEX%2FsNMdPRbG1XWtsMMPV9ot6NUgyebA%3D%3D: ('Connection aborted.', ConnectionResetError(10054, '远程主机强迫关闭了一个现有的连接。', None, 10054, None))
2024-03-06 13:18:59,158 ERROR   Thread-19 :47368 [internal_api.py:upload_file():1642] upload_file request headers: {'User-Agent': 'python-requests/2.31.0', 'Accept-Encoding': 'gzip, deflate', 'Accept': '*/*', 'Connection': 'keep-alive', 'Content-Length': '1252'}
2024-03-06 13:18:59,158 ERROR   Thread-19 :47368 [internal_api.py:upload_file():1644] upload_file response body: 
2024-03-06 13:19:01,366 ERROR   Thread-20 :47368 [internal_api.py:upload_file():1640] upload_file exception https://storage.googleapis.com/wandb-production.appspot.com/shahwaiz/UNet-DAS/25jringl/wandb-summary.json?Expires=1709788729&GoogleAccessId=gorilla-files-url-signer-man%40wandb-production.iam.gserviceaccount.com&Signature=vcUDcBJkkoXFGME1Mthfeq3h16FrDbg0BtDGyVLbHB3ZD4WGzjWbZ4%2Bbt%2FSf0ottieLJbr2Nl8dWTDUtGFi%2F%2Bu3pSmFcqg0JIjHEt4TzJr7beQr5ffAT79fx8uBJCoj2RBCscMh1TdRvNGslh8p5YT55u%2BRqlVApiObpnzlWAwBIvs38r6zGZTLbj5CVQAgGRz69w%2Fv8jM9yPnBjnEKx4fPm8CeTE0D%2FGDzK1Cwc5QkfF5qo0dWXnHc2CaLvpCZzJgZslUcS3Fj5%2BR3BEITkv%2F5EGR%2FCrnCt4hZ3nTy%2F25Yzljm4omHj06RiHpIFXigoEa%2BWKbUTzfdfEgcZdUmCfw%3D%3D: ('Connection aborted.', ConnectionResetError(10054, '远程主机强迫关闭了一个现有的连接。', None, 10054, None))
2024-03-06 13:19:01,366 ERROR   Thread-20 :47368 [internal_api.py:upload_file():1642] upload_file request headers: {'User-Agent': 'python-requests/2.31.0', 'Accept-Encoding': 'gzip, deflate', 'Accept': '*/*', 'Connection': 'keep-alive', 'Content-Length': '2'}
2024-03-06 13:19:01,366 ERROR   Thread-20 :47368 [internal_api.py:upload_file():1644] upload_file response body: 
