2024-03-06 16:14:08,393 INFO    MainThread:46316 [internal.py:wandb_internal():90] W&B internal server running at pid: 46316, started at: 2024-03-06 16:14:08.392733
2024-03-06 16:14:08,396 INFO    WriterThread:46316 [datastore.py:open_for_write():75] open: .\wandb\run-20240306_161405-2wcp307e\run-2wcp307e.wandb
2024-03-06 16:14:08,404 DEBUG   SenderThread:46316 [sender.py:send():235] send: header
2024-03-06 16:14:08,404 DEBUG   SenderThread:46316 [sender.py:send():235] send: run
2024-03-06 16:14:08,408 INFO    SenderThread:46316 [sender.py:_maybe_setup_resume():492] checking resume status for None/UNet-DAS/2wcp307e
2024-03-06 16:14:11,169 DEBUG   HandlerThread:46316 [handler.py:handle_request():141] handle_request: check_version
2024-03-06 16:14:11,180 INFO    SenderThread:46316 [dir_watcher.py:__init__():205] watching files in: .\wandb\run-20240306_161405-2wcp307e\files
2024-03-06 16:14:11,180 INFO    SenderThread:46316 [sender.py:_start_run_threads():812] run started: 2wcp307e with start time 1709712847
2024-03-06 16:14:11,180 DEBUG   SenderThread:46316 [sender.py:send():235] send: summary
2024-03-06 16:14:11,181 INFO    SenderThread:46316 [sender.py:_save_file():949] saving file wandb-summary.json with policy end
2024-03-06 16:14:11,182 DEBUG   SenderThread:46316 [sender.py:send_request():249] send_request: check_version
2024-03-06 16:14:11,966 DEBUG   HandlerThread:46316 [handler.py:handle_request():141] handle_request: run_start
2024-03-06 16:14:12,003 DEBUG   HandlerThread:46316 [meta.py:__init__():35] meta init
2024-03-06 16:14:12,004 DEBUG   HandlerThread:46316 [meta.py:__init__():49] meta init done
2024-03-06 16:14:12,004 DEBUG   HandlerThread:46316 [meta.py:probe():209] probe
2024-03-06 16:14:12,051 DEBUG   HandlerThread:46316 [meta.py:_setup_git():199] setup git
2024-03-06 16:14:12,190 INFO    Thread-16 :46316 [dir_watcher.py:_on_file_created():256] file/dir created: .\wandb\run-20240306_161405-2wcp307e\files\wandb-summary.json
2024-03-06 16:14:12,200 DEBUG   HandlerThread:46316 [meta.py:_setup_git():206] setup git done
2024-03-06 16:14:12,200 DEBUG   HandlerThread:46316 [meta.py:_save_pip():53] save pip
2024-03-06 16:14:12,202 DEBUG   HandlerThread:46316 [meta.py:_save_pip():67] save pip done
2024-03-06 16:14:12,202 DEBUG   HandlerThread:46316 [meta.py:_save_conda():74] save conda
2024-03-06 16:14:13,195 INFO    Thread-16 :46316 [dir_watcher.py:_on_file_created():256] file/dir created: .\wandb\run-20240306_161405-2wcp307e\files\conda-environment.yaml
2024-03-06 16:14:13,196 INFO    Thread-16 :46316 [dir_watcher.py:_on_file_created():256] file/dir created: .\wandb\run-20240306_161405-2wcp307e\files\requirements.txt
2024-03-06 16:14:15,977 DEBUG   HandlerThread:46316 [meta.py:_save_conda():84] save conda done
2024-03-06 16:14:15,977 DEBUG   HandlerThread:46316 [meta.py:probe():247] probe done
2024-03-06 16:14:16,055 DEBUG   SenderThread:46316 [sender.py:send():235] send: files
2024-03-06 16:14:16,055 DEBUG   HandlerThread:46316 [handler.py:handle_request():141] handle_request: stop_status
2024-03-06 16:14:16,055 INFO    SenderThread:46316 [sender.py:_save_file():949] saving file wandb-metadata.json with policy now
2024-03-06 16:14:16,057 DEBUG   SenderThread:46316 [sender.py:send_request():249] send_request: stop_status
2024-03-06 16:14:16,219 INFO    Thread-16 :46316 [dir_watcher.py:_on_file_modified():269] file/dir modified: .\wandb\run-20240306_161405-2wcp307e\files\conda-environment.yaml
2024-03-06 16:14:16,220 INFO    Thread-16 :46316 [dir_watcher.py:_on_file_created():256] file/dir created: .\wandb\run-20240306_161405-2wcp307e\files\wandb-metadata.json
2024-03-06 16:14:16,220 INFO    Thread-16 :46316 [dir_watcher.py:_on_file_created():256] file/dir created: .\wandb\run-20240306_161405-2wcp307e\files\output.log
2024-03-06 16:14:17,329 DEBUG   SenderThread:46316 [sender.py:send():235] send: telemetry
2024-03-06 16:14:17,329 DEBUG   SenderThread:46316 [sender.py:send():235] send: metric
2024-03-06 16:14:17,329 DEBUG   SenderThread:46316 [sender.py:send():235] send: telemetry
2024-03-06 16:14:17,329 DEBUG   SenderThread:46316 [sender.py:send():235] send: metric
2024-03-06 16:14:17,329 WARNING SenderThread:46316 [sender.py:send_metric():905] Seen metric with glob (shouldn't happen)
2024-03-06 16:14:17,329 DEBUG   SenderThread:46316 [sender.py:send():235] send: config
2024-03-06 16:14:18,060 ERROR   Thread-22 :46316 [internal_api.py:upload_file():1640] upload_file exception https://storage.googleapis.com/wandb-production.appspot.com/shahwaiz/UNet-DAS/2wcp307e/wandb-metadata.json?Expires=1709799257&GoogleAccessId=gorilla-files-url-signer-man%40wandb-production.iam.gserviceaccount.com&Signature=mDDnfGhnmrAiSxnBQX0Lx8X4Cj6HlVvmXaNEQ7JYjCVeTczPCCwyAtzpWjF30E09oo4OPVgTyZhLe1%2FqUGBvcgm2elgYPeVviMZCcSLx6L0AjrrGbYle7L1hH3zUY80w9%2BJJ3ePYzGwkPC1Qco9PbMCc%2Fk8CiGpUKDHsD6U5c%2F58ZNPKTCDNaox2lr%2FH%2BWmGIvkJBULG8z2a7bZaxJVIYpVZB8GfhSbEdcCyW6z%2FC%2Fs93fzY9E4FPUmQ0NhwKZAQwCAEglJQKydDXw%2B3F4a7YGyYvtgBoGgl58hf22Wt7EZDLIvvsl0oe1bWl%2BAgxuqvMl0%2F%2F6uH%2FL1clZhwTDlSVg%3D%3D: ('Connection aborted.', ConnectionResetError(10054, '远程主机强迫关闭了一个现有的连接。', None, 10054, None))
2024-03-06 16:14:18,061 ERROR   Thread-22 :46316 [internal_api.py:upload_file():1642] upload_file request headers: {'User-Agent': 'python-requests/2.31.0', 'Accept-Encoding': 'gzip, deflate', 'Accept': '*/*', 'Connection': 'keep-alive', 'Content-Length': '766'}
2024-03-06 16:14:18,061 ERROR   Thread-22 :46316 [internal_api.py:upload_file():1644] upload_file response body: 
2024-03-06 16:14:18,230 INFO    Thread-16 :46316 [dir_watcher.py:_on_file_modified():269] file/dir modified: .\wandb\run-20240306_161405-2wcp307e\files\output.log
2024-03-06 16:14:19,666 ERROR   Thread-22 :46316 [internal_api.py:upload_file():1640] upload_file exception https://storage.googleapis.com/wandb-production.appspot.com/shahwaiz/UNet-DAS/2wcp307e/wandb-metadata.json?Expires=1709799257&GoogleAccessId=gorilla-files-url-signer-man%40wandb-production.iam.gserviceaccount.com&Signature=mDDnfGhnmrAiSxnBQX0Lx8X4Cj6HlVvmXaNEQ7JYjCVeTczPCCwyAtzpWjF30E09oo4OPVgTyZhLe1%2FqUGBvcgm2elgYPeVviMZCcSLx6L0AjrrGbYle7L1hH3zUY80w9%2BJJ3ePYzGwkPC1Qco9PbMCc%2Fk8CiGpUKDHsD6U5c%2F58ZNPKTCDNaox2lr%2FH%2BWmGIvkJBULG8z2a7bZaxJVIYpVZB8GfhSbEdcCyW6z%2FC%2Fs93fzY9E4FPUmQ0NhwKZAQwCAEglJQKydDXw%2B3F4a7YGyYvtgBoGgl58hf22Wt7EZDLIvvsl0oe1bWl%2BAgxuqvMl0%2F%2F6uH%2FL1clZhwTDlSVg%3D%3D: ('Connection aborted.', ConnectionResetError(10054, '远程主机强迫关闭了一个现有的连接。', None, 10054, None))
2024-03-06 16:14:19,666 ERROR   Thread-22 :46316 [internal_api.py:upload_file():1642] upload_file request headers: {'User-Agent': 'python-requests/2.31.0', 'Accept-Encoding': 'gzip, deflate', 'Accept': '*/*', 'Connection': 'keep-alive', 'Content-Length': '766'}
2024-03-06 16:14:19,666 ERROR   Thread-22 :46316 [internal_api.py:upload_file():1644] upload_file response body: 
2024-03-06 16:14:22,265 ERROR   Thread-22 :46316 [internal_api.py:upload_file():1640] upload_file exception https://storage.googleapis.com/wandb-production.appspot.com/shahwaiz/UNet-DAS/2wcp307e/wandb-metadata.json?Expires=1709799257&GoogleAccessId=gorilla-files-url-signer-man%40wandb-production.iam.gserviceaccount.com&Signature=mDDnfGhnmrAiSxnBQX0Lx8X4Cj6HlVvmXaNEQ7JYjCVeTczPCCwyAtzpWjF30E09oo4OPVgTyZhLe1%2FqUGBvcgm2elgYPeVviMZCcSLx6L0AjrrGbYle7L1hH3zUY80w9%2BJJ3ePYzGwkPC1Qco9PbMCc%2Fk8CiGpUKDHsD6U5c%2F58ZNPKTCDNaox2lr%2FH%2BWmGIvkJBULG8z2a7bZaxJVIYpVZB8GfhSbEdcCyW6z%2FC%2Fs93fzY9E4FPUmQ0NhwKZAQwCAEglJQKydDXw%2B3F4a7YGyYvtgBoGgl58hf22Wt7EZDLIvvsl0oe1bWl%2BAgxuqvMl0%2F%2F6uH%2FL1clZhwTDlSVg%3D%3D: ('Connection aborted.', ConnectionResetError(10054, '远程主机强迫关闭了一个现有的连接。', None, 10054, None))
2024-03-06 16:14:22,265 ERROR   Thread-22 :46316 [internal_api.py:upload_file():1642] upload_file request headers: {'User-Agent': 'python-requests/2.31.0', 'Accept-Encoding': 'gzip, deflate', 'Accept': '*/*', 'Connection': 'keep-alive', 'Content-Length': '766'}
2024-03-06 16:14:22,265 ERROR   Thread-22 :46316 [internal_api.py:upload_file():1644] upload_file response body: 
2024-03-06 16:14:22,266 ERROR   Thread-22 :46316 [retry.py:__call__():126] Retry attempt failed:
Traceback (most recent call last):
  File "E:\Anaconda\envs\unet\lib\site-packages\urllib3\connectionpool.py", line 793, in urlopen
    response = self._make_request(
  File "E:\Anaconda\envs\unet\lib\site-packages\urllib3\connectionpool.py", line 491, in _make_request
    raise new_e
  File "E:\Anaconda\envs\unet\lib\site-packages\urllib3\connectionpool.py", line 467, in _make_request
    self._validate_conn(conn)
  File "E:\Anaconda\envs\unet\lib\site-packages\urllib3\connectionpool.py", line 1099, in _validate_conn
    conn.connect()
  File "E:\Anaconda\envs\unet\lib\site-packages\urllib3\connection.py", line 653, in connect
    sock_and_verified = _ssl_wrap_socket_and_match_hostname(
  File "E:\Anaconda\envs\unet\lib\site-packages\urllib3\connection.py", line 806, in _ssl_wrap_socket_and_match_hostname
    ssl_sock = ssl_wrap_socket(
  File "E:\Anaconda\envs\unet\lib\site-packages\urllib3\util\ssl_.py", line 465, in ssl_wrap_socket
    ssl_sock = _ssl_wrap_socket_impl(sock, context, tls_in_tls, server_hostname)
  File "E:\Anaconda\envs\unet\lib\site-packages\urllib3\util\ssl_.py", line 509, in _ssl_wrap_socket_impl
    return ssl_context.wrap_socket(sock, server_hostname=server_hostname)
  File "E:\Anaconda\envs\unet\lib\ssl.py", line 500, in wrap_socket
    return self.sslsocket_class._create(
  File "E:\Anaconda\envs\unet\lib\ssl.py", line 1073, in _create
    self.do_handshake()
  File "E:\Anaconda\envs\unet\lib\ssl.py", line 1342, in do_handshake
    self._sslobj.do_handshake()
ConnectionResetError: [WinError 10054] 远程主机强迫关闭了一个现有的连接。

During handling of the above exception, another exception occurred:

Traceback (most recent call last):
  File "E:\Anaconda\envs\unet\lib\site-packages\requests\adapters.py", line 486, in send
    resp = conn.urlopen(
  File "E:\Anaconda\envs\unet\lib\site-packages\urllib3\connectionpool.py", line 847, in urlopen
    retries = retries.increment(
  File "E:\Anaconda\envs\unet\lib\site-packages\urllib3\util\retry.py", line 470, in increment
    raise reraise(type(error), error, _stacktrace)
  File "E:\Anaconda\envs\unet\lib\site-packages\urllib3\util\util.py", line 38, in reraise
    raise value.with_traceback(tb)
  File "E:\Anaconda\envs\unet\lib\site-packages\urllib3\connectionpool.py", line 793, in urlopen
    response = self._make_request(
  File "E:\Anaconda\envs\unet\lib\site-packages\urllib3\connectionpool.py", line 491, in _make_request
    raise new_e
  File "E:\Anaconda\envs\unet\lib\site-packages\urllib3\connectionpool.py", line 467, in _make_request
    self._validate_conn(conn)
  File "E:\Anaconda\envs\unet\lib\site-packages\urllib3\connectionpool.py", line 1099, in _validate_conn
    conn.connect()
  File "E:\Anaconda\envs\unet\lib\site-packages\urllib3\connection.py", line 653, in connect
    sock_and_verified = _ssl_wrap_socket_and_match_hostname(
  File "E:\Anaconda\envs\unet\lib\site-packages\urllib3\connection.py", line 806, in _ssl_wrap_socket_and_match_hostname
    ssl_sock = ssl_wrap_socket(
  File "E:\Anaconda\envs\unet\lib\site-packages\urllib3\util\ssl_.py", line 465, in ssl_wrap_socket
    ssl_sock = _ssl_wrap_socket_impl(sock, context, tls_in_tls, server_hostname)
  File "E:\Anaconda\envs\unet\lib\site-packages\urllib3\util\ssl_.py", line 509, in _ssl_wrap_socket_impl
    return ssl_context.wrap_socket(sock, server_hostname=server_hostname)
  File "E:\Anaconda\envs\unet\lib\ssl.py", line 500, in wrap_socket
    return self.sslsocket_class._create(
  File "E:\Anaconda\envs\unet\lib\ssl.py", line 1073, in _create
    self.do_handshake()
  File "E:\Anaconda\envs\unet\lib\ssl.py", line 1342, in do_handshake
    self._sslobj.do_handshake()
urllib3.exceptions.ProtocolError: ('Connection aborted.', ConnectionResetError(10054, '远程主机强迫关闭了一个现有的连接。', None, 10054, None))

During handling of the above exception, another exception occurred:

Traceback (most recent call last):
  File "C:\Users\19086\AppData\Roaming\Python\Python38\site-packages\wandb\sdk\internal\internal_api.py", line 1637, in upload_file
    response = requests.put(url, data=progress, headers=extra_headers)
  File "E:\Anaconda\envs\unet\lib\site-packages\requests\api.py", line 130, in put
    return request("put", url, data=data, **kwargs)
  File "E:\Anaconda\envs\unet\lib\site-packages\requests\api.py", line 59, in request
    return session.request(method=method, url=url, **kwargs)
  File "E:\Anaconda\envs\unet\lib\site-packages\requests\sessions.py", line 589, in request
    resp = self.send(prep, **send_kwargs)
  File "E:\Anaconda\envs\unet\lib\site-packages\requests\sessions.py", line 703, in send
    r = adapter.send(request, **kwargs)
  File "E:\Anaconda\envs\unet\lib\site-packages\requests\adapters.py", line 501, in send
    raise ConnectionError(err, request=request)
requests.exceptions.ConnectionError: ('Connection aborted.', ConnectionResetError(10054, '远程主机强迫关闭了一个现有的连接。', None, 10054, None))

During handling of the above exception, another exception occurred:

Traceback (most recent call last):
  File "C:\Users\19086\AppData\Roaming\Python\Python38\site-packages\wandb\sdk\lib\retry.py", line 102, in __call__
    result = self._call_fn(*args, **kwargs)
  File "C:\Users\19086\AppData\Roaming\Python\Python38\site-packages\wandb\sdk\internal\internal_api.py", line 1653, in upload_file
    raise e.with_traceback(sys.exc_info()[2])
  File "C:\Users\19086\AppData\Roaming\Python\Python38\site-packages\wandb\sdk\internal\internal_api.py", line 1637, in upload_file
    response = requests.put(url, data=progress, headers=extra_headers)
  File "E:\Anaconda\envs\unet\lib\site-packages\requests\api.py", line 130, in put
    return request("put", url, data=data, **kwargs)
  File "E:\Anaconda\envs\unet\lib\site-packages\requests\api.py", line 59, in request
    return session.request(method=method, url=url, **kwargs)
  File "E:\Anaconda\envs\unet\lib\site-packages\requests\sessions.py", line 589, in request
    resp = self.send(prep, **send_kwargs)
  File "E:\Anaconda\envs\unet\lib\site-packages\requests\sessions.py", line 703, in send
    r = adapter.send(request, **kwargs)
  File "E:\Anaconda\envs\unet\lib\site-packages\requests\adapters.py", line 501, in send
    raise ConnectionError(err, request=request)
wandb.sdk.lib.retry.TransientError: None
2024-03-06 16:14:27,077 ERROR   Thread-22 :46316 [internal_api.py:upload_file():1640] upload_file exception https://storage.googleapis.com/wandb-production.appspot.com/shahwaiz/UNet-DAS/2wcp307e/wandb-metadata.json?Expires=1709799257&GoogleAccessId=gorilla-files-url-signer-man%40wandb-production.iam.gserviceaccount.com&Signature=mDDnfGhnmrAiSxnBQX0Lx8X4Cj6HlVvmXaNEQ7JYjCVeTczPCCwyAtzpWjF30E09oo4OPVgTyZhLe1%2FqUGBvcgm2elgYPeVviMZCcSLx6L0AjrrGbYle7L1hH3zUY80w9%2BJJ3ePYzGwkPC1Qco9PbMCc%2Fk8CiGpUKDHsD6U5c%2F58ZNPKTCDNaox2lr%2FH%2BWmGIvkJBULG8z2a7bZaxJVIYpVZB8GfhSbEdcCyW6z%2FC%2Fs93fzY9E4FPUmQ0NhwKZAQwCAEglJQKydDXw%2B3F4a7YGyYvtgBoGgl58hf22Wt7EZDLIvvsl0oe1bWl%2BAgxuqvMl0%2F%2F6uH%2FL1clZhwTDlSVg%3D%3D: ('Connection aborted.', ConnectionResetError(10054, '远程主机强迫关闭了一个现有的连接。', None, 10054, None))
2024-03-06 16:14:27,077 ERROR   Thread-22 :46316 [internal_api.py:upload_file():1642] upload_file request headers: {'User-Agent': 'python-requests/2.31.0', 'Accept-Encoding': 'gzip, deflate', 'Accept': '*/*', 'Connection': 'keep-alive', 'Content-Length': '766'}
2024-03-06 16:14:27,077 ERROR   Thread-22 :46316 [internal_api.py:upload_file():1644] upload_file response body: 
2024-03-06 16:14:32,338 DEBUG   HandlerThread:46316 [handler.py:handle_request():141] handle_request: stop_status
2024-03-06 16:14:32,339 DEBUG   SenderThread:46316 [sender.py:send_request():249] send_request: stop_status
2024-03-06 16:14:34,370 INFO    Thread-16 :46316 [dir_watcher.py:_on_file_modified():269] file/dir modified: .\wandb\run-20240306_161405-2wcp307e\files\output.log
2024-03-06 16:14:37,051 ERROR   Thread-22 :46316 [internal_api.py:upload_file():1640] upload_file exception https://storage.googleapis.com/wandb-production.appspot.com/shahwaiz/UNet-DAS/2wcp307e/wandb-metadata.json?Expires=1709799257&GoogleAccessId=gorilla-files-url-signer-man%40wandb-production.iam.gserviceaccount.com&Signature=mDDnfGhnmrAiSxnBQX0Lx8X4Cj6HlVvmXaNEQ7JYjCVeTczPCCwyAtzpWjF30E09oo4OPVgTyZhLe1%2FqUGBvcgm2elgYPeVviMZCcSLx6L0AjrrGbYle7L1hH3zUY80w9%2BJJ3ePYzGwkPC1Qco9PbMCc%2Fk8CiGpUKDHsD6U5c%2F58ZNPKTCDNaox2lr%2FH%2BWmGIvkJBULG8z2a7bZaxJVIYpVZB8GfhSbEdcCyW6z%2FC%2Fs93fzY9E4FPUmQ0NhwKZAQwCAEglJQKydDXw%2B3F4a7YGyYvtgBoGgl58hf22Wt7EZDLIvvsl0oe1bWl%2BAgxuqvMl0%2F%2F6uH%2FL1clZhwTDlSVg%3D%3D: ('Connection aborted.', ConnectionResetError(10054, '远程主机强迫关闭了一个现有的连接。', None, 10054, None))
2024-03-06 16:14:37,051 ERROR   Thread-22 :46316 [internal_api.py:upload_file():1642] upload_file request headers: {'User-Agent': 'python-requests/2.31.0', 'Accept-Encoding': 'gzip, deflate', 'Accept': '*/*', 'Connection': 'keep-alive', 'Content-Length': '766'}
2024-03-06 16:14:37,051 ERROR   Thread-22 :46316 [internal_api.py:upload_file():1644] upload_file response body: 
2024-03-06 16:14:41,448 INFO    Thread-16 :46316 [dir_watcher.py:_on_file_modified():269] file/dir modified: .\wandb\run-20240306_161405-2wcp307e\files\config.yaml
2024-03-06 16:14:42,999 DEBUG   SenderThread:46316 [sender.py:send():235] send: stats
2024-03-06 16:14:49,056 DEBUG   HandlerThread:46316 [handler.py:handle_request():141] handle_request: stop_status
2024-03-06 16:14:49,057 DEBUG   SenderThread:46316 [sender.py:send_request():249] send_request: stop_status
2024-03-06 16:14:56,946 ERROR   Thread-22 :46316 [internal_api.py:upload_file():1640] upload_file exception https://storage.googleapis.com/wandb-production.appspot.com/shahwaiz/UNet-DAS/2wcp307e/wandb-metadata.json?Expires=1709799257&GoogleAccessId=gorilla-files-url-signer-man%40wandb-production.iam.gserviceaccount.com&Signature=mDDnfGhnmrAiSxnBQX0Lx8X4Cj6HlVvmXaNEQ7JYjCVeTczPCCwyAtzpWjF30E09oo4OPVgTyZhLe1%2FqUGBvcgm2elgYPeVviMZCcSLx6L0AjrrGbYle7L1hH3zUY80w9%2BJJ3ePYzGwkPC1Qco9PbMCc%2Fk8CiGpUKDHsD6U5c%2F58ZNPKTCDNaox2lr%2FH%2BWmGIvkJBULG8z2a7bZaxJVIYpVZB8GfhSbEdcCyW6z%2FC%2Fs93fzY9E4FPUmQ0NhwKZAQwCAEglJQKydDXw%2B3F4a7YGyYvtgBoGgl58hf22Wt7EZDLIvvsl0oe1bWl%2BAgxuqvMl0%2F%2F6uH%2FL1clZhwTDlSVg%3D%3D: ('Connection aborted.', ConnectionResetError(10054, '远程主机强迫关闭了一个现有的连接。', None, 10054, None))
2024-03-06 16:14:56,946 ERROR   Thread-22 :46316 [internal_api.py:upload_file():1642] upload_file request headers: {'User-Agent': 'python-requests/2.31.0', 'Accept-Encoding': 'gzip, deflate', 'Accept': '*/*', 'Connection': 'keep-alive', 'Content-Length': '766'}
2024-03-06 16:14:56,947 ERROR   Thread-22 :46316 [internal_api.py:upload_file():1644] upload_file response body: 
2024-03-06 16:15:06,309 DEBUG   HandlerThread:46316 [handler.py:handle_request():141] handle_request: stop_status
2024-03-06 16:15:06,309 DEBUG   SenderThread:46316 [sender.py:send_request():249] send_request: stop_status
2024-03-06 16:15:16,038 DEBUG   SenderThread:46316 [sender.py:send():235] send: stats
2024-03-06 16:15:22,680 DEBUG   HandlerThread:46316 [handler.py:handle_request():141] handle_request: stop_status
2024-03-06 16:15:22,681 DEBUG   SenderThread:46316 [sender.py:send_request():249] send_request: stop_status
2024-03-06 16:15:30,827 ERROR   Thread-22 :46316 [internal_api.py:upload_file():1640] upload_file exception https://storage.googleapis.com/wandb-production.appspot.com/shahwaiz/UNet-DAS/2wcp307e/wandb-metadata.json?Expires=1709799257&GoogleAccessId=gorilla-files-url-signer-man%40wandb-production.iam.gserviceaccount.com&Signature=mDDnfGhnmrAiSxnBQX0Lx8X4Cj6HlVvmXaNEQ7JYjCVeTczPCCwyAtzpWjF30E09oo4OPVgTyZhLe1%2FqUGBvcgm2elgYPeVviMZCcSLx6L0AjrrGbYle7L1hH3zUY80w9%2BJJ3ePYzGwkPC1Qco9PbMCc%2Fk8CiGpUKDHsD6U5c%2F58ZNPKTCDNaox2lr%2FH%2BWmGIvkJBULG8z2a7bZaxJVIYpVZB8GfhSbEdcCyW6z%2FC%2Fs93fzY9E4FPUmQ0NhwKZAQwCAEglJQKydDXw%2B3F4a7YGyYvtgBoGgl58hf22Wt7EZDLIvvsl0oe1bWl%2BAgxuqvMl0%2F%2F6uH%2FL1clZhwTDlSVg%3D%3D: ('Connection aborted.', ConnectionResetError(10054, '远程主机强迫关闭了一个现有的连接。', None, 10054, None))
2024-03-06 16:15:30,827 ERROR   Thread-22 :46316 [internal_api.py:upload_file():1642] upload_file request headers: {'User-Agent': 'python-requests/2.31.0', 'Accept-Encoding': 'gzip, deflate', 'Accept': '*/*', 'Connection': 'keep-alive', 'Content-Length': '766'}
2024-03-06 16:15:30,828 ERROR   Thread-22 :46316 [internal_api.py:upload_file():1644] upload_file response body: 
2024-03-06 16:15:38,944 DEBUG   HandlerThread:46316 [handler.py:handle_request():141] handle_request: stop_status
2024-03-06 16:15:38,945 DEBUG   SenderThread:46316 [sender.py:send_request():249] send_request: stop_status
2024-03-06 16:15:49,077 DEBUG   SenderThread:46316 [sender.py:send():235] send: stats
2024-03-06 16:15:55,372 DEBUG   HandlerThread:46316 [handler.py:handle_request():141] handle_request: stop_status
2024-03-06 16:15:55,373 DEBUG   SenderThread:46316 [sender.py:send_request():249] send_request: stop_status
2024-03-06 16:16:11,676 DEBUG   HandlerThread:46316 [handler.py:handle_request():141] handle_request: stop_status
2024-03-06 16:16:11,677 DEBUG   SenderThread:46316 [sender.py:send_request():249] send_request: stop_status
2024-03-06 16:16:22,128 DEBUG   SenderThread:46316 [sender.py:send():235] send: stats
2024-03-06 16:16:28,076 DEBUG   HandlerThread:46316 [handler.py:handle_request():141] handle_request: stop_status
2024-03-06 16:16:28,076 DEBUG   SenderThread:46316 [sender.py:send_request():249] send_request: stop_status
2024-03-06 16:16:44,564 DEBUG   HandlerThread:46316 [handler.py:handle_request():141] handle_request: stop_status
2024-03-06 16:16:44,564 DEBUG   SenderThread:46316 [sender.py:send_request():249] send_request: stop_status
2024-03-06 16:16:45,394 ERROR   Thread-22 :46316 [internal_api.py:upload_file():1640] upload_file exception https://storage.googleapis.com/wandb-production.appspot.com/shahwaiz/UNet-DAS/2wcp307e/wandb-metadata.json?Expires=1709799257&GoogleAccessId=gorilla-files-url-signer-man%40wandb-production.iam.gserviceaccount.com&Signature=mDDnfGhnmrAiSxnBQX0Lx8X4Cj6HlVvmXaNEQ7JYjCVeTczPCCwyAtzpWjF30E09oo4OPVgTyZhLe1%2FqUGBvcgm2elgYPeVviMZCcSLx6L0AjrrGbYle7L1hH3zUY80w9%2BJJ3ePYzGwkPC1Qco9PbMCc%2Fk8CiGpUKDHsD6U5c%2F58ZNPKTCDNaox2lr%2FH%2BWmGIvkJBULG8z2a7bZaxJVIYpVZB8GfhSbEdcCyW6z%2FC%2Fs93fzY9E4FPUmQ0NhwKZAQwCAEglJQKydDXw%2B3F4a7YGyYvtgBoGgl58hf22Wt7EZDLIvvsl0oe1bWl%2BAgxuqvMl0%2F%2F6uH%2FL1clZhwTDlSVg%3D%3D: ('Connection aborted.', ConnectionResetError(10054, '远程主机强迫关闭了一个现有的连接。', None, 10054, None))
2024-03-06 16:16:45,394 ERROR   Thread-22 :46316 [internal_api.py:upload_file():1642] upload_file request headers: {'User-Agent': 'python-requests/2.31.0', 'Accept-Encoding': 'gzip, deflate', 'Accept': '*/*', 'Connection': 'keep-alive', 'Content-Length': '766'}
2024-03-06 16:16:45,394 ERROR   Thread-22 :46316 [internal_api.py:upload_file():1644] upload_file response body: 
2024-03-06 16:16:55,226 DEBUG   SenderThread:46316 [sender.py:send():235] send: stats
2024-03-06 16:17:01,011 DEBUG   HandlerThread:46316 [handler.py:handle_request():141] handle_request: stop_status
2024-03-06 16:17:01,011 DEBUG   SenderThread:46316 [sender.py:send_request():249] send_request: stop_status
2024-03-06 16:17:17,298 DEBUG   HandlerThread:46316 [handler.py:handle_request():141] handle_request: stop_status
2024-03-06 16:17:17,299 DEBUG   SenderThread:46316 [sender.py:send_request():249] send_request: stop_status
2024-03-06 16:17:28,423 DEBUG   SenderThread:46316 [sender.py:send():235] send: stats
2024-03-06 16:17:33,677 DEBUG   HandlerThread:46316 [handler.py:handle_request():141] handle_request: stop_status
2024-03-06 16:17:33,678 DEBUG   SenderThread:46316 [sender.py:send_request():249] send_request: stop_status
2024-03-06 16:17:53,691 DEBUG   HandlerThread:46316 [handler.py:handle_request():141] handle_request: stop_status
2024-03-06 16:17:53,692 DEBUG   SenderThread:46316 [sender.py:send_request():249] send_request: stop_status
2024-03-06 16:18:01,614 DEBUG   SenderThread:46316 [sender.py:send():235] send: stats
2024-03-06 16:18:09,975 DEBUG   HandlerThread:46316 [handler.py:handle_request():141] handle_request: stop_status
2024-03-06 16:18:09,976 DEBUG   SenderThread:46316 [sender.py:send_request():249] send_request: stop_status
2024-03-06 16:18:26,327 DEBUG   HandlerThread:46316 [handler.py:handle_request():141] handle_request: stop_status
2024-03-06 16:18:26,328 DEBUG   SenderThread:46316 [sender.py:send_request():249] send_request: stop_status
2024-03-06 16:18:34,766 DEBUG   SenderThread:46316 [sender.py:send():235] send: stats
2024-03-06 16:18:43,532 DEBUG   HandlerThread:46316 [handler.py:handle_request():141] handle_request: stop_status
2024-03-06 16:18:43,533 DEBUG   SenderThread:46316 [sender.py:send_request():249] send_request: stop_status
2024-03-06 16:18:54,438 ERROR   Thread-22 :46316 [internal_api.py:upload_file():1640] upload_file exception https://storage.googleapis.com/wandb-production.appspot.com/shahwaiz/UNet-DAS/2wcp307e/wandb-metadata.json?Expires=1709799257&GoogleAccessId=gorilla-files-url-signer-man%40wandb-production.iam.gserviceaccount.com&Signature=mDDnfGhnmrAiSxnBQX0Lx8X4Cj6HlVvmXaNEQ7JYjCVeTczPCCwyAtzpWjF30E09oo4OPVgTyZhLe1%2FqUGBvcgm2elgYPeVviMZCcSLx6L0AjrrGbYle7L1hH3zUY80w9%2BJJ3ePYzGwkPC1Qco9PbMCc%2Fk8CiGpUKDHsD6U5c%2F58ZNPKTCDNaox2lr%2FH%2BWmGIvkJBULG8z2a7bZaxJVIYpVZB8GfhSbEdcCyW6z%2FC%2Fs93fzY9E4FPUmQ0NhwKZAQwCAEglJQKydDXw%2B3F4a7YGyYvtgBoGgl58hf22Wt7EZDLIvvsl0oe1bWl%2BAgxuqvMl0%2F%2F6uH%2FL1clZhwTDlSVg%3D%3D: ('Connection aborted.', ConnectionResetError(10054, '远程主机强迫关闭了一个现有的连接。', None, 10054, None))
2024-03-06 16:18:54,438 ERROR   Thread-22 :46316 [internal_api.py:upload_file():1642] upload_file request headers: {'User-Agent': 'python-requests/2.31.0', 'Accept-Encoding': 'gzip, deflate', 'Accept': '*/*', 'Connection': 'keep-alive', 'Content-Length': '766'}
2024-03-06 16:18:54,438 ERROR   Thread-22 :46316 [internal_api.py:upload_file():1644] upload_file response body: 
2024-03-06 16:18:59,938 DEBUG   HandlerThread:46316 [handler.py:handle_request():141] handle_request: stop_status
2024-03-06 16:18:59,938 DEBUG   SenderThread:46316 [sender.py:send_request():249] send_request: stop_status
2024-03-06 16:19:07,913 DEBUG   SenderThread:46316 [sender.py:send():235] send: stats
2024-03-06 16:19:16,277 DEBUG   HandlerThread:46316 [handler.py:handle_request():141] handle_request: stop_status
2024-03-06 16:19:16,278 DEBUG   SenderThread:46316 [sender.py:send_request():249] send_request: stop_status
2024-03-06 16:19:32,611 DEBUG   HandlerThread:46316 [handler.py:handle_request():141] handle_request: stop_status
2024-03-06 16:19:32,612 DEBUG   SenderThread:46316 [sender.py:send_request():249] send_request: stop_status
2024-03-06 16:19:41,069 DEBUG   SenderThread:46316 [sender.py:send():235] send: stats
2024-03-06 16:19:48,981 DEBUG   HandlerThread:46316 [handler.py:handle_request():141] handle_request: stop_status
2024-03-06 16:19:48,982 DEBUG   SenderThread:46316 [sender.py:send_request():249] send_request: stop_status
2024-03-06 16:20:08,502 DEBUG   HandlerThread:46316 [handler.py:handle_request():141] handle_request: stop_status
2024-03-06 16:20:08,503 DEBUG   SenderThread:46316 [sender.py:send_request():249] send_request: stop_status
2024-03-06 16:20:14,247 DEBUG   SenderThread:46316 [sender.py:send():235] send: stats
2024-03-06 16:20:24,922 DEBUG   HandlerThread:46316 [handler.py:handle_request():141] handle_request: stop_status
2024-03-06 16:20:24,923 DEBUG   SenderThread:46316 [sender.py:send_request():249] send_request: stop_status
2024-03-06 16:20:41,965 DEBUG   HandlerThread:46316 [handler.py:handle_request():141] handle_request: stop_status
2024-03-06 16:20:41,966 DEBUG   SenderThread:46316 [sender.py:send_request():249] send_request: stop_status
2024-03-06 16:20:47,310 DEBUG   SenderThread:46316 [sender.py:send():235] send: stats
2024-03-06 16:20:58,235 DEBUG   HandlerThread:46316 [handler.py:handle_request():141] handle_request: stop_status
2024-03-06 16:20:58,236 DEBUG   SenderThread:46316 [sender.py:send_request():249] send_request: stop_status
2024-03-06 16:21:14,574 DEBUG   HandlerThread:46316 [handler.py:handle_request():141] handle_request: stop_status
2024-03-06 16:21:14,575 DEBUG   SenderThread:46316 [sender.py:send_request():249] send_request: stop_status
2024-03-06 16:21:20,460 DEBUG   SenderThread:46316 [sender.py:send():235] send: stats
2024-03-06 16:21:30,895 DEBUG   HandlerThread:46316 [handler.py:handle_request():141] handle_request: stop_status
2024-03-06 16:21:30,896 DEBUG   SenderThread:46316 [sender.py:send_request():249] send_request: stop_status
2024-03-06 16:21:47,229 DEBUG   HandlerThread:46316 [handler.py:handle_request():141] handle_request: stop_status
2024-03-06 16:21:47,230 DEBUG   SenderThread:46316 [sender.py:send_request():249] send_request: stop_status
2024-03-06 16:21:53,560 DEBUG   SenderThread:46316 [sender.py:send():235] send: stats
2024-03-06 16:22:04,285 DEBUG   HandlerThread:46316 [handler.py:handle_request():141] handle_request: stop_status
2024-03-06 16:22:04,286 DEBUG   SenderThread:46316 [sender.py:send_request():249] send_request: stop_status
2024-03-06 16:22:20,643 DEBUG   HandlerThread:46316 [handler.py:handle_request():141] handle_request: stop_status
2024-03-06 16:22:20,644 DEBUG   SenderThread:46316 [sender.py:send_request():249] send_request: stop_status
2024-03-06 16:22:26,600 DEBUG   SenderThread:46316 [sender.py:send():235] send: stats
2024-03-06 16:22:39,394 DEBUG   HandlerThread:46316 [handler.py:handle_request():141] handle_request: stop_status
2024-03-06 16:22:39,395 DEBUG   SenderThread:46316 [sender.py:send_request():249] send_request: stop_status
2024-03-06 16:22:55,570 DEBUG   HandlerThread:46316 [handler.py:handle_request():141] handle_request: stop_status
2024-03-06 16:22:55,571 DEBUG   SenderThread:46316 [sender.py:send_request():249] send_request: stop_status
2024-03-06 16:22:59,709 DEBUG   SenderThread:46316 [sender.py:send():235] send: stats
2024-03-06 16:23:11,865 DEBUG   HandlerThread:46316 [handler.py:handle_request():141] handle_request: stop_status
2024-03-06 16:23:11,866 DEBUG   SenderThread:46316 [sender.py:send_request():249] send_request: stop_status
2024-03-06 16:23:21,053 ERROR   Thread-22 :46316 [internal_api.py:upload_file():1640] upload_file exception https://storage.googleapis.com/wandb-production.appspot.com/shahwaiz/UNet-DAS/2wcp307e/wandb-metadata.json?Expires=1709799257&GoogleAccessId=gorilla-files-url-signer-man%40wandb-production.iam.gserviceaccount.com&Signature=mDDnfGhnmrAiSxnBQX0Lx8X4Cj6HlVvmXaNEQ7JYjCVeTczPCCwyAtzpWjF30E09oo4OPVgTyZhLe1%2FqUGBvcgm2elgYPeVviMZCcSLx6L0AjrrGbYle7L1hH3zUY80w9%2BJJ3ePYzGwkPC1Qco9PbMCc%2Fk8CiGpUKDHsD6U5c%2F58ZNPKTCDNaox2lr%2FH%2BWmGIvkJBULG8z2a7bZaxJVIYpVZB8GfhSbEdcCyW6z%2FC%2Fs93fzY9E4FPUmQ0NhwKZAQwCAEglJQKydDXw%2B3F4a7YGyYvtgBoGgl58hf22Wt7EZDLIvvsl0oe1bWl%2BAgxuqvMl0%2F%2F6uH%2FL1clZhwTDlSVg%3D%3D: ('Connection aborted.', ConnectionResetError(10054, '远程主机强迫关闭了一个现有的连接。', None, 10054, None))
2024-03-06 16:23:21,053 ERROR   Thread-22 :46316 [internal_api.py:upload_file():1642] upload_file request headers: {'User-Agent': 'python-requests/2.31.0', 'Accept-Encoding': 'gzip, deflate', 'Accept': '*/*', 'Connection': 'keep-alive', 'Content-Length': '766'}
2024-03-06 16:23:21,054 ERROR   Thread-22 :46316 [internal_api.py:upload_file():1644] upload_file response body: 
2024-03-06 16:23:28,674 DEBUG   HandlerThread:46316 [handler.py:handle_request():141] handle_request: stop_status
2024-03-06 16:23:28,674 DEBUG   SenderThread:46316 [sender.py:send_request():249] send_request: stop_status
2024-03-06 16:23:32,798 DEBUG   SenderThread:46316 [sender.py:send():235] send: stats
2024-03-06 16:23:44,989 DEBUG   HandlerThread:46316 [handler.py:handle_request():141] handle_request: stop_status
2024-03-06 16:23:44,990 DEBUG   SenderThread:46316 [sender.py:send_request():249] send_request: stop_status
2024-03-06 16:24:01,349 DEBUG   HandlerThread:46316 [handler.py:handle_request():141] handle_request: stop_status
2024-03-06 16:24:01,350 DEBUG   SenderThread:46316 [sender.py:send_request():249] send_request: stop_status
2024-03-06 16:24:05,926 DEBUG   SenderThread:46316 [sender.py:send():235] send: stats
2024-03-06 16:24:17,738 DEBUG   HandlerThread:46316 [handler.py:handle_request():141] handle_request: stop_status
2024-03-06 16:24:17,739 DEBUG   SenderThread:46316 [sender.py:send_request():249] send_request: stop_status
2024-03-06 16:24:34,144 DEBUG   HandlerThread:46316 [handler.py:handle_request():141] handle_request: stop_status
2024-03-06 16:24:34,145 DEBUG   SenderThread:46316 [sender.py:send_request():249] send_request: stop_status
2024-03-06 16:24:39,009 DEBUG   SenderThread:46316 [sender.py:send():235] send: stats
2024-03-06 16:24:50,890 DEBUG   HandlerThread:46316 [handler.py:handle_request():141] handle_request: stop_status
2024-03-06 16:24:50,891 DEBUG   SenderThread:46316 [sender.py:send_request():249] send_request: stop_status
2024-03-06 16:25:08,300 DEBUG   HandlerThread:46316 [handler.py:handle_request():141] handle_request: stop_status
2024-03-06 16:25:08,301 DEBUG   SenderThread:46316 [sender.py:send_request():249] send_request: stop_status
2024-03-06 16:25:12,092 DEBUG   SenderThread:46316 [sender.py:send():235] send: stats
2024-03-06 16:25:25,736 DEBUG   HandlerThread:46316 [handler.py:handle_request():141] handle_request: stop_status
2024-03-06 16:25:25,736 DEBUG   SenderThread:46316 [sender.py:send_request():249] send_request: stop_status
2024-03-06 16:25:43,614 DEBUG   HandlerThread:46316 [handler.py:handle_request():141] handle_request: stop_status
2024-03-06 16:25:43,615 DEBUG   SenderThread:46316 [sender.py:send_request():249] send_request: stop_status
2024-03-06 16:25:45,071 DEBUG   SenderThread:46316 [sender.py:send():235] send: stats
2024-03-06 16:26:00,052 DEBUG   HandlerThread:46316 [handler.py:handle_request():141] handle_request: stop_status
2024-03-06 16:26:00,053 DEBUG   SenderThread:46316 [sender.py:send_request():249] send_request: stop_status
2024-03-06 16:26:16,405 DEBUG   HandlerThread:46316 [handler.py:handle_request():141] handle_request: stop_status
2024-03-06 16:26:16,406 DEBUG   SenderThread:46316 [sender.py:send_request():249] send_request: stop_status
2024-03-06 16:26:18,033 DEBUG   SenderThread:46316 [sender.py:send():235] send: stats
2024-03-06 16:26:32,757 DEBUG   HandlerThread:46316 [handler.py:handle_request():141] handle_request: stop_status
2024-03-06 16:26:32,758 DEBUG   SenderThread:46316 [sender.py:send_request():249] send_request: stop_status
2024-03-06 16:26:49,051 DEBUG   HandlerThread:46316 [handler.py:handle_request():141] handle_request: stop_status
2024-03-06 16:26:49,052 DEBUG   SenderThread:46316 [sender.py:send_request():249] send_request: stop_status
2024-03-06 16:26:50,972 DEBUG   SenderThread:46316 [sender.py:send():235] send: stats
2024-03-06 16:27:05,351 DEBUG   HandlerThread:46316 [handler.py:handle_request():141] handle_request: stop_status
2024-03-06 16:27:05,352 DEBUG   SenderThread:46316 [sender.py:send_request():249] send_request: stop_status
2024-03-06 16:27:14,193 WARNING MainThread:46316 [internal.py:wandb_internal():153] Internal process interrupt: 1
2024-03-06 16:27:15,051 DEBUG   SenderThread:46316 [sender.py:send():235] send: telemetry
2024-03-06 16:27:15,547 DEBUG   SenderThread:46316 [sender.py:send():235] send: exit
2024-03-06 16:27:15,547 INFO    SenderThread:46316 [sender.py:send_exit():371] handling exit code: 0
2024-03-06 16:27:15,548 DEBUG   HandlerThread:46316 [handler.py:handle_request():141] handle_request: poll_exit
2024-03-06 16:27:15,548 INFO    SenderThread:46316 [sender.py:send_exit():373] handling runtime: 783
2024-03-06 16:27:15,549 INFO    SenderThread:46316 [sender.py:_save_file():949] saving file wandb-summary.json with policy end
2024-03-06 16:27:15,549 INFO    SenderThread:46316 [sender.py:send_exit():379] send defer
2024-03-06 16:27:15,549 DEBUG   SenderThread:46316 [sender.py:send_request():249] send_request: poll_exit
2024-03-06 16:27:15,550 DEBUG   HandlerThread:46316 [handler.py:handle_request():141] handle_request: defer
2024-03-06 16:27:15,550 INFO    HandlerThread:46316 [handler.py:handle_request_defer():164] handle defer: 0
2024-03-06 16:27:15,550 DEBUG   SenderThread:46316 [sender.py:send_request():249] send_request: defer
2024-03-06 16:27:15,550 INFO    SenderThread:46316 [sender.py:send_request_defer():388] handle sender defer: 0
2024-03-06 16:27:15,550 INFO    SenderThread:46316 [sender.py:transition_state():392] send defer: 1
2024-03-06 16:27:15,551 DEBUG   HandlerThread:46316 [handler.py:handle_request():141] handle_request: defer
2024-03-06 16:27:15,551 INFO    HandlerThread:46316 [handler.py:handle_request_defer():164] handle defer: 1
2024-03-06 16:27:15,622 DEBUG   SenderThread:46316 [sender.py:send_request():249] send_request: defer
2024-03-06 16:27:15,622 INFO    SenderThread:46316 [sender.py:send_request_defer():388] handle sender defer: 1
2024-03-06 16:27:15,623 INFO    SenderThread:46316 [sender.py:transition_state():392] send defer: 2
2024-03-06 16:27:15,623 DEBUG   SenderThread:46316 [sender.py:send():235] send: stats
2024-03-06 16:27:15,623 DEBUG   HandlerThread:46316 [handler.py:handle_request():141] handle_request: defer
2024-03-06 16:27:15,624 INFO    HandlerThread:46316 [handler.py:handle_request_defer():164] handle defer: 2
2024-03-06 16:27:15,624 DEBUG   SenderThread:46316 [sender.py:send_request():249] send_request: defer
2024-03-06 16:27:15,624 INFO    SenderThread:46316 [sender.py:send_request_defer():388] handle sender defer: 2
2024-03-06 16:27:15,624 INFO    SenderThread:46316 [sender.py:transition_state():392] send defer: 3
2024-03-06 16:27:15,625 DEBUG   HandlerThread:46316 [handler.py:handle_request():141] handle_request: defer
2024-03-06 16:27:15,625 INFO    HandlerThread:46316 [handler.py:handle_request_defer():164] handle defer: 3
2024-03-06 16:27:15,625 DEBUG   SenderThread:46316 [sender.py:send_request():249] send_request: defer
2024-03-06 16:27:15,625 INFO    SenderThread:46316 [sender.py:send_request_defer():388] handle sender defer: 3
2024-03-06 16:27:15,625 INFO    SenderThread:46316 [sender.py:transition_state():392] send defer: 4
2024-03-06 16:27:15,625 DEBUG   HandlerThread:46316 [handler.py:handle_request():141] handle_request: defer
2024-03-06 16:27:15,625 INFO    HandlerThread:46316 [handler.py:handle_request_defer():164] handle defer: 4
2024-03-06 16:27:15,626 DEBUG   SenderThread:46316 [sender.py:send():235] send: summary
2024-03-06 16:27:15,626 INFO    SenderThread:46316 [sender.py:_save_file():949] saving file wandb-summary.json with policy end
2024-03-06 16:27:15,627 DEBUG   SenderThread:46316 [sender.py:send_request():249] send_request: defer
2024-03-06 16:27:15,627 INFO    SenderThread:46316 [sender.py:send_request_defer():388] handle sender defer: 4
2024-03-06 16:27:15,627 INFO    SenderThread:46316 [sender.py:transition_state():392] send defer: 5
2024-03-06 16:27:15,627 DEBUG   HandlerThread:46316 [handler.py:handle_request():141] handle_request: defer
2024-03-06 16:27:15,627 INFO    HandlerThread:46316 [handler.py:handle_request_defer():164] handle defer: 5
2024-03-06 16:27:15,627 DEBUG   SenderThread:46316 [sender.py:send_request():249] send_request: defer
2024-03-06 16:27:15,627 INFO    SenderThread:46316 [sender.py:send_request_defer():388] handle sender defer: 5
2024-03-06 16:27:15,651 DEBUG   HandlerThread:46316 [handler.py:handle_request():141] handle_request: poll_exit
2024-03-06 16:27:16,535 INFO    Thread-16 :46316 [dir_watcher.py:_on_file_modified():269] file/dir modified: .\wandb\run-20240306_161405-2wcp307e\files\output.log
2024-03-06 16:27:16,536 INFO    Thread-16 :46316 [dir_watcher.py:_on_file_modified():269] file/dir modified: .\wandb\run-20240306_161405-2wcp307e\files\wandb-summary.json
2024-03-06 16:27:18,382 ERROR   SenderThread:46316 [internal_api.py:execute():143] 409 response executing GraphQL.
2024-03-06 16:27:18,382 ERROR   SenderThread:46316 [internal_api.py:execute():144] {"errors":[{"message":"run shahwaiz/UNet-DAS/2wcp307e was previously created and deleted; try a new run name","path":["upsertBucket"]}],"data":{"upsertBucket":null}}
2024-03-06 16:27:18,642 INFO    WriterThread:46316 [datastore.py:close():279] close: .\wandb\run-20240306_161405-2wcp307e\run-2wcp307e.wandb
2024-03-06 16:27:18,673 INFO    HandlerThread:46316 [handler.py:finish():806] shutting down handler
2024-03-06 16:27:19,224 ERROR   MainThread:46316 [internal.py:wandb_internal():165] Thread SenderThread:
Traceback (most recent call last):
  File "C:\Users\19086\AppData\Roaming\Python\Python38\site-packages\wandb\apis\normalize.py", line 22, in wrapper
    return func(*args, **kwargs)
  File "C:\Users\19086\AppData\Roaming\Python\Python38\site-packages\wandb\sdk\internal\internal_api.py", line 1319, in upsert_run
    response = self.gql(mutation, variable_values=variable_values, **kwargs)
  File "C:\Users\19086\AppData\Roaming\Python\Python38\site-packages\wandb\sdk\lib\retry.py", line 102, in __call__
    result = self._call_fn(*args, **kwargs)
  File "C:\Users\19086\AppData\Roaming\Python\Python38\site-packages\wandb\sdk\internal\internal_api.py", line 140, in execute
    return self.client.execute(*args, **kwargs)
  File "C:\Users\19086\AppData\Roaming\Python\Python38\site-packages\wandb\vendor\gql-0.2.0\wandb_gql\client.py", line 52, in execute
    result = self._get_result(document, *args, **kwargs)
  File "C:\Users\19086\AppData\Roaming\Python\Python38\site-packages\wandb\vendor\gql-0.2.0\wandb_gql\client.py", line 60, in _get_result
    return self.transport.execute(document, *args, **kwargs)
  File "C:\Users\19086\AppData\Roaming\Python\Python38\site-packages\wandb\vendor\gql-0.2.0\wandb_gql\transport\requests.py", line 39, in execute
    request.raise_for_status()
  File "E:\Anaconda\envs\unet\lib\site-packages\requests\models.py", line 1021, in raise_for_status
    raise HTTPError(http_error_msg, response=self)
requests.exceptions.HTTPError: 409 Client Error: Conflict for url: https://api.wandb.ai/graphql

During handling of the above exception, another exception occurred:

Traceback (most recent call last):
  File "C:\Users\19086\AppData\Roaming\Python\Python38\site-packages\wandb\sdk\internal\internal_util.py", line 51, in run
    self._run()
  File "C:\Users\19086\AppData\Roaming\Python\Python38\site-packages\wandb\sdk\internal\internal_util.py", line 102, in _run
    self._process(record)
  File "C:\Users\19086\AppData\Roaming\Python\Python38\site-packages\wandb\sdk\internal\internal.py", line 310, in _process
    self._sm.send(record)
  File "C:\Users\19086\AppData\Roaming\Python\Python38\site-packages\wandb\sdk\internal\sender.py", line 237, in send
    send_handler(record)
  File "C:\Users\19086\AppData\Roaming\Python\Python38\site-packages\wandb\sdk\internal\sender.py", line 251, in send_request
    send_handler(record)
  File "C:\Users\19086\AppData\Roaming\Python\Python38\site-packages\wandb\sdk\internal\sender.py", line 411, in send_request_defer
    self.debounce()
  File "C:\Users\19086\AppData\Roaming\Python\Python38\site-packages\wandb\sdk\internal\sender.py", line 320, in debounce
    self._debounce_config()
  File "C:\Users\19086\AppData\Roaming\Python\Python38\site-packages\wandb\sdk\internal\sender.py", line 326, in _debounce_config
    self._api.upsert_run(
  File "C:\Users\19086\AppData\Roaming\Python\Python38\site-packages\wandb\apis\normalize.py", line 24, in wrapper
    raise CommError(err.response, err)
wandb.errors.CommError: <Response [409]>
2024-03-06 16:27:21,453 INFO    MainThread:46316 [internal.py:handle_exit():80] Internal process exited
